Workbook

Sheet 260205
B2: [26.1H 언팩 소셜 버즈 현황] | X2: -29D | Y2: -1D | Z2: D-day | AA2: +42D | AB2: Start Date | AC2: End Date
X3: 45651 | Y3: 45679 | Z3: 45680 | AA3: 45721 | AB3: 45651 | AC3: 45659
B4: 1. 소셜 버즈 현황 | P4: Data 기준 : 2026/1/28 ~ 2026/2/5 (언팩-29D ~ 언팩-21D) | X4: 46050 | Y4: 46078 | Z4: 46079 | AA4: 46120 | AB4: 46050 | AC4: 46058
C6: [ 2/5 Daily Highlight ]
C7: □ 1일 버즈량 74K (전년 比 5.5배)
C8: ① IG 크리에이터 N-1 제품 카메라 (인물 사진 촬영 모드) 캠페인 (64K, 87%) | V8: https://www.instagram.com/reel/DUVICTfEgK1 | W8: https://www.instagram.com/reel/DUVjVLqjA3G
C9: ② 2차 카메라(줌, 나이토그래피) 티징 기반, 소비자 언급 발생 (1K, 1%) | V9: https://www.instagram.com/reels/DUUEZbVExzw/
C11: [ ~ 2/5 누적 Hightlight]
C12: □ 총 버즈량 285K (전년 比 3.1배), 전일 比 +74K
C13: ① IG 크리에이터, N-1 제품 카메라 (Nightography 중심) 소구 (190K, 67%) | V13: https://www.instagram.com/reel/DTVVCkGjF7j
C14: ② 티징 컨텐츠 기반, Privacy Display 및 카메라 관련 논의 (22K, 8%) | V14: https://x.com/UniverseIce/status/2016322537777725746 | W14: https://x.com/UniverseIce/status/2016342843644883276
C15: ※ Privacy Display (18K, 6%), 카메라 (4K, 2%)
C16: ③ Enhypen 협업, 올림픽 연계 올림픽 카운트다운 및 Victory Selfie 컨텐츠 (12K, 4%) | V16: https://x.com/Olympic/status/2016316039202517387 | W16: x.com/Olympic/status/2017885633239306552
C17: ④ 테크 인플루언서, 언팩 기대 요소를 댓글로 작성하는 이벤트 진행 (8K, 3%) | V17: https://x.com/SaudiAndroid/status/2016546556028014909 | W17: https://x.com/osamahesam1/status/2016560914309263778
C19: □ 제품 內 디스플레이 (24%, x3.5) > 디자인 (13%, x0.7) > AP(11%, x0.8) > Camera (10%, x1.0) 順
C20: ① 디스플레이 (긍 51%, 부 3%) : Privacy Display 적용 영역 선택 및 특정 앱 적용 기능 기대 | V20: https://x.com/sondesix/status/2016520584369471682 | W20: https://x.com/jethronyagti/status/2016577101206368706
C21: ※ Use Scene : SNS/일상 66%, 금융/개인정보 20%, 업무 14% 順
C22: ② 디자인 (긍 22%, 부 10%) : 얇고 가벼운 외관(Ultra 중심) 및 색상 관련 루머 확산 | V22: https://x.com/beebomco/status/2016535725328806170 | W22: https://x.com/kandhesh/status/2016527453418819962
C23: ③ AP/Memory (긍 18%, 부 12%) : SD8 Elite Gen 5 성능 기대, Exynos 2600 적용 모델 성능 우려 일부 有 | V23: https://www.reddit.com/r/PhoneNow/comments/1qpafa0/comment/o2btjvf/ | W23: https://www.reddit.com/r/samsunggalaxy/comments/1qop48c/comment/o23f1j2/
C24: ④ 카메라 (긍 25%, 부 15%) : PR 이후 Nightography/Zoom 에 대한 긍정 기대감 생성 中 (긍정 각 42%, 54%) | V24: https://x.com/CodeCraftBriefs/status/2019115577642742127 | W24: https://x.com/TekTrndz/status/2019048559585439893
C26: □ 발화자 : 로컬 (65%, x7.8) > 소비자 (15%, x1.4) > 미디어 (8%, x1.4), 커뮤니티 (7%, x1.0) > 수원 (4%, x5.9) 順
B30: [버즈량 현황] | X30: [HTR 제외 시]
B31: 구분 | E31: Total 버즈량 | L31: 구분 | X31: 구분 | Z31: Total 버즈량
F32: Family | I32: Buds4 +Pro | J32: AI 단독 언급 | M32: Family | S32: Buds4 +Pro | AA32: Family | AD32: Buds4 +Pro | AE32: AI 단독 언급
G33: Ultra | H33: Base/+ | O33: Ultra | Q33: Base/+ | AB33: Ultra | AC33: Base/+
M34: Pos | N34: Neg | O34: Pos | P34: Neg | Q34: Pos | R34: Neg | S34: Pos | T34: Neg
B35: 26.1H UNPK | E35: 284825 | F35: 63785 | G35: 37993 | H35: 25792 | I35: 4327 | J35: 31521 | L35: 26.1H UNPK | M35: 0.26584793 | N35: 0.13316477 | O35: 0.32492199 | P35: 0.14811423 | Q35: 0.18025456 | R35: 0.11150425 | S35: 0.23754513 | T35: 0.15090253 | X35: 26.1H UNPK | Z35: 284825 | AA35: 63785 | AB35: 37993 | AC35: 25792 | AD35: 4327 | AE35: 31521
B36: (전년 比) | E36: 3.077958 | F36: 1.2433723 | G36: 1.4431192 | H36: 1.2768949 | I36: 0.51450654 | J36: 0.71224241 | L36: (전년 比) | M36: 0.064422772 | N36: 0.036015091 | O36: 0.11915477 | P36: 0.058278636 | Q36: 0.012284254 | R36: -0.013644894 | S36: -0.013004324 | T36: -0.0071701695 | X36: (전년 比) | Z36: 3.077958 | AA36: 1.2433723 | AB36: 1.4431192 | AC36: 1.2768949 | AD36: 0.51450654 | AE36: 0.71224241
B37: 25.1H UNPK | E37: 92537 | F37: 51300 | G37: 26327 | H37: 20199 | I37: 8410 | J37: 44256 | L37: 25.1H UNPK | M37: 0.20142516 | N37: 0.097149679 | O37: 0.20576722 | P37: 0.089835595 | Q37: 0.1679703 | R37: 0.12514914 | S37: 0.25054945 | T37: 0.1580727 | X37: 25.1H UNPK | Z37: 92537 | AA37: 51300 | AB37: 26327 | AC37: 20199 | AD37: 8410 | AE37: 44256
B38: ※ 제품 버즈 : Ultra 언급 버즈는 Ultra로 우선 반영, Base/+는 Ultra 언급 제외 후 집계 | L38: ※ Sentiment는 TV/News/Radio/Print 및 HTR 제외하고 추출
B39: ※ Buds4+Pro의 전작 기준은 Buds3+Pro, '24.2H 언팩 당시 공개 기준 ('25.1H 언팩 총 합계에 미 포함)
B40: ※ Brand 언급 버즈량 : 14K (#ExplorGalaxy)
B42: 2. 발화자별 버즈 현황
C44: ① 수원 (13K)
C45: - 밀라노 올림픽 참석 Icon 인플루언서(Enhypen) 컨텐츠 팬 계정 내 확산 (12K) | V45: https://x.com/Olympic/status/2016316039202517387
C46: ② 로컬 (185K)
C47: - IG Creator 發 브랜드 커뮤니케이션(#ExploreGalaxy) 확산 中 (141K) | V47: https://www.instagram.com/p/DTVVCkGjF7j/
C48: - SESAR 테크 인플루언서 發 UNPK 해시태그 및 기대 제품 댓글 작성 소비자 참여 이벤트 버즈 발생 (4K) | V48: https://x.com/SaudiAndroid/status/2016546556028014909
C49: - 그 외 테크 인플루언서 發 Privercy Display, 유출된 언팩 초대장 및 제품 이미지 중심으로 제품 루머 생성 (4K) | V49: https://x.com/UniverseIce/status/2016342843644883276
C50: ③ 소비자 (43K)
...

Sheet 260204
B2: [26.1H 언팩 소셜 버즈 현황] | X2: -29D | Y2: -1D | Z2: D-day | AA2: +42D | AB2: Start Date | AC2: End Date
X3: 45651 | Y3: 45679 | Z3: 45680 | AA3: 45721 | AB3: 45651 | AC3: 45658
B4: 1. 소셜 버즈 현황 | P4: Data 기준 : 2026/1/28 ~ 2026/2/4 (언팩-29D ~ 언팩-22D) | X4: 46050 | Y4: 46078 | Z4: 46079 | AA4: 46120 | AB4: 46050 | AC4: 46057
C6: [ Miracle 소셜 당일 (2/4) 버즈 Highlight ]
C7: □ 버즈량 39K, 전년 동기간 比 3.6배
C8: ① 2차 티징 컨텐츠 (Camera Zoom, Nightography) 3K (8%) (1차 티징 1일차 8K 대비 0.4배 수준) | V8: https://www.instagram.com/reels/DUUEZbVExzw/
C9: ② SEUK FB 發 7일간 브랜드 활용 및 디스플레이 소구 이벤트 5K (14%) | V9: https://www.facebook.com/701689855332829/posts/1361889662646175
C10: ③ SIEL Creator 發 #ExploreGalaxy 활용 소비자 참여 이벤트 20K (51%) | V10: https://www.instagram.com/reel/DUVICTfEgK1
C12: [ Miracle 소셜 누적 버즈 Highlight ]
C13: □ 총 버즈량 210K, 전년 比 2.7배
C14: ① IG 크레에이터 發 N-1 제품 카메라 소구 활동 (120K, 53%) (SIEL Creator 신규 Posting) | V14: https://www.instagram.com/reel/DTVVCkGjF7j
C15: ② 티징 컨텐츠 2차 공개, 1차 Privacy Display (17K, 8%) / 2차 Camera Zoom, Nightography (3K, 1%) | V15: https://x.com/UniverseIce/status/2016322537777725746 | W15: https://x.com/UniverseIce/status/2016342843644883276
C16: ③ Enhypen 협업, 올림픽 연계 올림픽 카운트다운 및 Victory Selfie 컨텐츠 (14K, 7%) | V16: https://x.com/Olympic/status/2016316039202517387
C17: ④ 테크 인플루언서, 언팩 기대 요소를 댓글로 작성하는 이벤트 진행 (7K, 4%) | V17: https://x.com/SaudiAndroid/status/2016546556028014909 | W17: https://x.com/osamahesam1/status/2016560914309263778
C19: □ 디스플레이 (25%) > 디자인 (13%) > AP/Memory (11%) 順 제품 관심 생성 중
C20: ① 디스플레이 (긍 51%, 부 3%) : Privacy Display 기능 中 부분 적용 가능 루머에 혁신적인 기능이라는 긍정 반응 多 | V20: https://x.com/sondesix/status/2016520584369471682 | W20: https://x.com/jethronyagti/status/2016577101206368706
C21: (※ Use Scene : SNS/일상 67%, 금융/개인정보 20%, 업무 13% 順)
C22: ② 디자인 (긍 22%, 부 9%) : 역대 M3 중 가장 얇고 가벼운 외관 기대 | V22: https://x.com/beebomco/status/2016535725328806170 | W22: https://x.com/kandhesh/status/2016527453418819962
C23: ③ AP/Memory (긍 19%, 부 12%) : SD8 Elite Gen 5 성능 기대, Exynos 2600 적용 모델 성능 우려 일부 有 | V23: https://www.reddit.com/r/PhoneNow/comments/1qpafa0/comment/o2btjvf/ | W23: https://www.reddit.com/r/samsunggalaxy/comments/1qop48c/comment/o23f1j2/
C25: □ 발화자 : 로컬 57% > 소비자 19% > 미디어 10% > 수원 5% 順
C26: - Creator 및 테크 인플루언서 활동으로 제품 루머 및 언팩 기대감 지속 확산 중 | V26: https://www.instagram.com/reel/DTVVCkGjF7j | W26: https://x.com/SaudiAndroid/status/2016546556028014909 | X26: https://x.com/UniverseIce/status/2016342843644883276
B30: [버즈량 현황] | X30: [HTR 제외 시]
B31: 구분 | E31: Total 버즈량 | L31: 구분 | X31: 구분 | Z31: Total 버즈량
F32: Family | I32: Buds4 +Pro | J32: AI 단독 언급 | M32: Family | S32: Buds4 +Pro | AA32: Family | AD32: Buds4 +Pro | AE32: AI 단독 언급
G33: Ultra | H33: Base/+ | O33: Ultra | Q33: Base/+ | AB33: Ultra | AC33: Base/+
M34: Pos | N34: Neg | O34: Pos | P34: Neg | Q34: Pos | R34: Neg | S34: Pos | T34: Neg
B35: 26.1H UNPK | E35: 210400 | F35: 58759 | G35: 34856 | H35: 23903 | I35: 3965 | J35: 27018 | L35: 26.1H UNPK | M35: 0.26660331 | N35: 0.12965163 | O35: 0.32941997 | P35: 0.14528378 | Q35: 0.17669607 | R35: 0.10727788 | S35: 0.24023669 | T35: 0.14477318 | X35: 26.1H UNPK | Z35: 210400 | AA35: 58759 | AB35: 34856 | AC35: 23903 | AD35: 3965 | AE35: 27018
B36: (전년 比) | E36: 2.6621117 | F36: 1.3081684 | G36: 1.4705932 | H36: 1.4342374 | I36: 0.53997004 | J36: 0.67887834 | L36: (전년 比) | M36: 0.069659482 | N36: 0.035051969 | O36: 0.13217193 | P36: 0.055561105 | Q36: 0.0061258897 | R36: -0.014673337 | S36: -0.015600274 | T36: -0.010747204 | X36: (전년 比) | Z36: 2.6621117 | AA36: 1.3081684 | AB36: 1.4705932 | AC36: 1.4342374 | AD36: 0.53997004 | AE36: 0.67887834
B37: 25.1H UNPK | E37: 79035 | F37: 44917 | G37: 23702 | H37: 16666 | I37: 7343 | J37: 39798 | L37: 25.1H UNPK | M37: 0.19694383 | N37: 0.094599659 | O37: 0.19724803 | P37: 0.089722675 | Q37: 0.17057018 | R37: 0.12195122 | S37: 0.25583696 | T37: 0.15552038 | X37: 25.1H UNPK | Z37: 79035 | AA37: 44917 | AB37: 23702 | AC37: 16666 | AD37: 7343 | AE37: 39798
B38: ※ 제품 버즈 : Ultra 언급 버즈는 Ultra로 우선 반영, Base/+는 Ultra 언급 제외 후 집계 | L38: ※ Sentiment는 TV/News/Radio/Print 및 HTR 제외하고 추출
B39: ※ Buds4+Pro의 전작 기준은 Buds3+Pro, '24.2H 언팩 당시 공개 기준 ('25.1H 언팩 총 합계에 미 포함)
B40: ※ Brand 언급 버즈량 : 14K (#ExplorGalaxy)
B42: 2. 발화자별 버즈 현황
C44: ① 수원 (11K)
C45: - 밀라노 올림픽 참석 Icon 인플루언서(Enhypen) 컨텐츠 팬 계정 내 확산 (10K) | V45: https://x.com/Olympic/status/2016316039202517387
C46: ② 로컬 (120K)
C47: - IG Creator 發 브랜드 커뮤니케이션(#ExploreGalaxy) 확산 中 (67K + 소비자 4K) | V47: https://www.instagram.com/p/DTVVCkGjF7j/
C48: - SESAR 테크 인플루언서 發 UNPK 해시태그 및 기대 제품 댓글 작성 소비자 참여 이벤트 버즈 발생 (4K) | V48: https://x.com/SaudiAndroid/status/2016546556028014909
C49: - 그 외 테크 인플루언서 發 Privercy Display, 유출된 언팩 초대장 및 제품 이미지 중심으로 제품 루머 생성 (3K) | V49: https://x.com/UniverseIce/status/2016342843644883276
C50: ③ 소비자 (40K)
...

Sheet 260203
B2: ="[26.1H 언팩 소셜 버즈 현황]" -> [26.1H 언팩 소셜 버즈 현황] | X2: -29D | Y2: -1D | Z2: D-day | AA2: +42D | AB2: Start Date | AC2: End Date
X3: 45651 | Y3: 45679 | Z3: 45680 | AA3: 45721 | AB3: =AB4-399 -> 45651 | AC3: =AC4-399 -> 45657
B4: ="1. 소셜 버즈 현황" -> 1. 소셜 버즈 현황 | P4: ="Data 기준 : "&YEAR(AB4)&"/"&MONTH(AB4)&"/"&DAY(AB4)&" ~ "&YEAR(AC4)&"/"&MONTH(AC4)&"/"&DAY(AC4)&" (언팩-29D ~ 언팩"&_xlfn.DAYS(AC4,Z4)&"D)" -> Data 기준 : 2026/1/28 ~ 2026/2/3 (언팩-29D ~ 언팩-23D) | X4: 46050 | Y4: 46078 | Z4: 46079 | AA4: 46120 | AB4: 46050 | AC4: 46056
C6: □ 총 버즈량 168K, 전년 比 2.5배
C7: ① IG 크리에이터 發 N-1 제품 카메라 소구 활동 (86K, 51%) | V7: https://www.instagram.com/reel/DTVVCkGjF7j
C8: ② 티징 컨텐츠 기반, Privacy Display 소셜 內 관심 확산후 소강 中 (17K, 10%) | V8: https://x.com/UniverseIce/status/2016322537777725746 | W8: https://x.com/UniverseIce/status/2016342843644883276
C9: ③ Enhypen 협업, 올림픽 연계 올림픽 카운트다운 및 Victory Selfie 컨텐츠 (7K, 5%) | V9: https://x.com/Olympic/status/2016316039202517387
C10: ④ 테크 인플루언서, 언팩 기대 요소를 댓글로 작성하는 이벤트 진행 (7K, 4%) | V10: https://x.com/SaudiAndroid/status/2016546556028014909 | W10: https://x.com/osamahesam1/status/2016560914309263778
C12: □ 디스플레이 (27%) > 디자인 (12%) > AP/Memory (11%) 順 제품 관심 생성 중
C13: ① 디스플레이 (긍 51%, 부 3%) : Privacy Display 기능 中 부분 적용 가능 루머에 혁신적인 기능이라는 긍정 반응 多 | V13: https://x.com/sondesix/status/2016520584369471682 | W13: https://x.com/jethronyagti/status/2016577101206368706
C14: (※ Use Scene : SNS/일상 67%, 금융/개인정보 20%, 업무 13% 順)
C15: ② 디자인 (긍 23%, 부 9%) : 역대 M3 중 가장 얇고 가벼운 외관 기대 | V15: https://x.com/beebomco/status/2016535725328806170 | W15: https://x.com/kandhesh/status/2016527453418819962
C16: ③ AP/Memory (긍 18%, 부 11%) : SD8 Elite Gen 5 성능 기대, Exynos 2600 적용 모델 성능 우려 일부 有 | V16: https://www.reddit.com/r/PhoneNow/comments/1qpafa0/comment/o2btjvf/ | W16: https://www.reddit.com/r/samsunggalaxy/comments/1qop48c/comment/o23f1j2/
C18: □ 발화자 : 로컬 55% > 소비자 20% > 미디어 11% > 수원 4% 順
C19: - 테크 인플루언서 중심 제품 루머 및 언팩 기대감 지속 확산 중 | V19: https://x.com/SaudiAndroid/status/2016546556028014909 | W19: https://x.com/UniverseIce/status/2016342843644883276
B23: [버즈량 현황] | X23: [HTR 제외 시]
B24: 구분 | E24: Total 버즈량 | L24: 구분 | X24: 구분 | Z24: Total 버즈량
F25: Family | I25: Buds4 +Pro | J25: AI 단독 언급 | M25: Family | S25: Buds4 +Pro | AA25: Family | AD25: Buds4 +Pro | AE25: AI 단독 언급
G26: Ultra | H26: Base/+ | O26: Ultra | Q26: Base/+ | AB26: Ultra | AC26: Base/+
M27: Pos | N27: Neg | O27: Pos | P27: Neg | Q27: Pos | R27: Neg | S27: Pos | T27: Neg
B28: 26.1H UNPK | E28: 168148 | F28: 52959 | G28: 31514 | H28: 21445 | I28: 2908 | J28: 18960 | L28: 26.1H UNPK | M28: 0.26853494 | N28: 0.12647511 | O28: 0.33354694 | P28: 0.14486543 | Q28: 0.17479933 | R28: 0.099959577 | S28: 0.22533632 | T28: 0.11995516 | X28: 26.1H UNPK | Z28: 168148 | AA28: 52959 | AB28: 31514 | AC28: 21445 | AD28: 2908 | AE28: 18960
B29: (전년 比) | E29: 2.4689161 | F29: 1.3204757 | G29: 1.472961 | H29: 1.4858311 | I29: 0.43867853 | J29: 0.52894406 | L29: (전년 比) | M29: 0.075716651 | N29: 0.032255509 | O29: 0.14073975 | P29: 0.05633857 | Q29: 0.007909378 | R29: -0.026164825 | S29: -0.023018219 | T29: -0.041738568 | X29: (전년 比) | Z29: 2.4689161 | AA29: 1.3204757 | AB29: 1.472961 | AC29: 1.4858311 | AD29: 0.43867853 | AE29: 0.52894406
B30: 25.1H UNPK | E30: 68106 | F30: 40106 | G30: 21395 | H30: 14433 | I30: 6629 | J30: 35845 | L30: 25.1H UNPK | M30: 0.19281829 | N30: 0.0942196 | O30: 0.19280719 | P30: 0.088526858 | Q30: 0.16688995 | R30: 0.1261244 | S30: 0.24835454 | T30: 0.16169373 | X30: 25.1H UNPK | Z30: 68106 | AA30: 40106 | AB30: 21395 | AC30: 14433 | AD30: 6629 | AE30: 35845
B31: ※ 제품 버즈 : Ultra 언급 버즈는 Ultra로 우선 반영, Base/+는 Ultra 언급 제외 후 집계 | L31: ※ Sentiment는 TV/News/Radio/Print 및 HTR 제외하고 추출
B32: ※ Buds4+Pro의 전작 기준은 Buds3+Pro, '24.2H 언팩 당시 공개 기준 ('25.1H 언팩 총 합계에 미 포함)
B33: ※ Brand 언급 버즈량 : 14K (#ExplorGalaxy)
B35: ="2. 발화자별 버즈 현황" -> 2. 발화자별 버즈 현황
C37: ① 수원 (7K)
C38: - 밀라노 올림픽 참석 Icon 인플루언서(Enhypen) 컨텐츠 팬 계정 내 확산 (7K) | V38: https://x.com/Olympic/status/2016316039202517387
C39: ② 로컬 (93K)
C40: - IG Creator 發 브랜드 커뮤니케이션(#ExploreGalaxy) 확산 中 (67K + 소비자 4K) | V40: https://www.instagram.com/p/DTVVCkGjF7j/
C41: - SESAR 테크 인플루언서 發 UNPK 해시태그 및 기대 제품 댓글 작성 소비자 참여 이벤트 버즈 발생 (4K) | V41: https://x.com/SaudiAndroid/status/2016546556028014909
C42: - 그 외 테크 인플루언서 發 Privercy Display, 유출된 언팩 초대장 및 제품 이미지 중심으로 제품 루머 생성 (3K) | V42: https://x.com/UniverseIce/status/2016342843644883276
C43: ③ 소비자 (34K)
C44: - Privacy Display 기능 PR 공개로 혁신성에 대한 긍정 버즈 확산 中 (12K) | V44: https://x.com/rrreggegg/status/2016407184419258802
B47: 발화자 | E47: 버즈량 | H47: 비중
F48: 전년 比 | G48: 전작 평균 | I48: 전년 比 | J48: 전작 평균
B49: Total | E49: 168148 | F49: 2.4689161 | G49: 101784 | H49: - | I49: - | J49: -
C50: 수원 | E50: 7408 | F50: 6.4811899 | G50: 3233 | H50: 0.044056426 | I50: 0.027273764 | J50: 0.031763498
D51: HTR | E51: 0 | F51: - | H51: 0 | I51: 0
...

Sheet 260202
B2: [26.1H 언팩 소셜 버즈 현황] | X2: -29D | Y2: -1D | Z2: D-day | AA2: +42D | AB2: Start Date | AC2: End Date
X3: 45651 | Y3: 45679 | Z3: 45680 | AA3: 45721 | AB3: 45651 | AC3: 45656
B4: 1. 소셜 버즈 현황 | P4: Data 기준 : 2026/1/28 ~ 2026/2/2 (언팩-29D ~ 언팩-24D) | X4: 46050 | Y4: 46078 | Z4: 46079 | AA4: 46120 | AB4: 46050 | AC4: 46055
C6: □ 총 버즈량 150K, 전년 比 2.6배
C7: ① IG 크레에이터 發 N-1 제품 카메라 소구 활동 (78K, 50%) | V7: https://www.instagram.com/reel/DTVVCkGjF7j
C8: ② 티징 컨텐츠 기반, Privacy Display 소셜 內 관심 확산후 소강 中 (16K, 11%) | V8: https://x.com/UniverseIce/status/2016322537777725746 | W8: https://x.com/UniverseIce/status/2016342843644883276
C9: ③ Enhypen 협업, 올림픽 연계 올림픽 카운트다운 및 Victory Selfie 컨텐츠 (7K, 5%) | V9: https://x.com/Olympic/status/2016316039202517387
C10: ④ 테크 인플루언서, 언팩 기대 요소를 댓글로 작성하는 이벤트 진행 (7K, 4%) | V10: https://x.com/SaudiAndroid/status/2016546556028014909 | W10: https://x.com/osamahesam1/status/2016560914309263778
C12: □ 디스플레이 (30%) > 디자인 (12%) > AP/Memory (10%) 順 제품 관심 생성 중
C13: ① 디스플레이 (긍 52%, 부 3%) : Privacy Display 기능 中 부분 적용 가능 루머에 혁신적인 기능이라는 긍정 반응 多 | V13: https://x.com/sondesix/status/2016520584369471682 | W13: https://x.com/jethronyagti/status/2016577101206368706
C14: (※ Use Scene : SNS/일상 68%, 금융/개인정보 20%, 업무 12% 順)
C15: ② 디자인 (긍 22%, 부 8%) : 역대 M3 중 가장 얇고 가벼운 외관 기대 | V15: https://x.com/beebomco/status/2016535725328806170 | W15: https://x.com/kandhesh/status/2016527453418819962
C16: ③ AP/Memory (긍 18%, 부 11%) : SD8 Elite Gen 5 성능 기대, Exynos 2600 적용 모델 성능 우려 일부 有 | V16: https://www.reddit.com/r/PhoneNow/comments/1qpafa0/comment/o2btjvf/ | W16: https://www.reddit.com/r/samsunggalaxy/comments/1qop48c/comment/o23f1j2/
C18: □ 발화자 : 로컬 57% > 소비자 21% > 미디어 10% > 수원 5% 順
C19: - 테크 인플루언서 중심 제품 루머 및 언팩 기대감 지속 확산 중 | V19: https://x.com/SaudiAndroid/status/2016546556028014909 | W19: https://x.com/UniverseIce/status/2016342843644883276
B23: [버즈량 현황] | X23: [HTR 제외 시]
B24: 구분 | E24: Total 버즈량 | L24: 구분 | X24: 구분 | Z24: Total 버즈량
F25: Family | I25: Buds4 +Pro | J25: AI 단독 언급 | M25: Family | S25: Buds4 +Pro | AA25: Family | AD25: Buds4 +Pro | AE25: AI 단독 언급
G26: Ultra | H26: Base/+ | O26: Ultra | Q26: Base/+ | AB26: Ultra | AC26: Base/+
M27: Pos | N27: Neg | O27: Pos | P27: Neg | Q27: Pos | R27: Neg | S27: Pos | T27: Neg
B28: 26.1H UNPK | E28: 150401 | F28: 47087 | G28: 27933 | H28: 19154 | I28: 2625 | J28: 15674 | L28: 26.1H UNPK | M28: 0.2722196 | N28: 0.11881915 | O28: 0.34349449 | P28: 0.14255244 | Q28: 0.16965085 | R28: 0.084665558 | S28: 0.22752294 | T28: 0.11192661 | X28: 26.1H UNPK | Z28: 150401 | AA28: 47087 | AB28: 27933 | AC28: 19154 | AD28: 2625 | AE28: 15674
B29: (전년 比) | E29: 2.5813267 | F29: 1.3884646 | G29: 1.5431744 | H29: 1.5890161 | I29: 0.43431502 | J29: 0.51121983 | L29: (전년 比) | M29: 0.089013494 | N29: 0.026579964 | O29: 0.15448807 | P29: 0.054985242 | Q29: 0.0072984436 | R29: -0.046805831 | S29: -0.026753296 | T29: -0.064483913 | X29: (전년 比) | Z29: 2.5813267 | AA29: 1.3884646 | AB29: 1.5431744 | AC29: 1.5890161 | AD29: 0.43431502 | AE29: 0.51121983
B30: 25.1H UNPK | E30: 58265 | F30: 33913 | G30: 18101 | H30: 12054 | I30: 6044 | J30: 30660 | L30: 25.1H UNPK | M30: 0.18320611 | N30: 0.092239186 | O30: 0.18900642 | P30: 0.087567193 | Q30: 0.16235241 | R30: 0.13147139 | S30: 0.25427623 | T30: 0.17641052 | X30: 25.1H UNPK | Z30: 58265 | AA30: 33913 | AB30: 18101 | AC30: 12054 | AD30: 6044 | AE30: 30660
B31: ※ 제품 버즈 : Ultra 언급 버즈는 Ultra로 우선 반영, Base/+는 Ultra 언급 제외 후 집계 | L31: ※ Sentiment는 TV/News/Radio/Print 및 HTR 제외하고 추출
B32: ※ Buds4+Pro의 전작 기준은 Buds3+Pro, '24.2H 언팩 당시 공개 기준 ('25.1H 언팩 총 합계에 미 포함)
B33: ※ Brand 언급 버즈량 : 14K (#ExplorGalaxy)
B35: 2. 발화자별 버즈 현황
C37: ① 수원 (7K)
C38: - 밀라노 올림픽 참석 Icon 인플루언서(Enhypen) 컨텐츠 팬 계정 내 확산 (7K) | V38: https://x.com/Olympic/status/2016316039202517387
C39: ② 로컬 (85K)
C40: - IG Creator 發 브랜드 커뮤니케이션(#ExploreGalaxy) 확산 中 (67K + 소비자 4K) | V40: https://www.instagram.com/p/DTVVCkGjF7j/
C41: - SESAR 테크 인플루언서 發 UNPK 해시태그 및 기대 제품 댓글 작성 소비자 참여 이벤트 버즈 발생 (4K) | V41: https://x.com/SaudiAndroid/status/2016546556028014909
C42: - 그 외 테크 인플루언서 發 Privercy Display 중심으로 제품 루머 생성 (3K) | V42: https://x.com/UniverseIce/status/2016342843644883276
C43: ③ 소비자 (31K)
C44: - Privacy Display 기능 PR 공개로 혁신성에 대한 긍정 버즈 확산 中 (12K) | V44: https://x.com/rrreggegg/status/2016407184419258802
B47: 발화자 | E47: 버즈량 | H47: 비중
F48: 전년 比 | G48: 전작 평균 | I48: 전년 比 | J48: 전작 평균
B49: Total | E49: 150401 | F49: 2.5813267 | G49: 88896 | H49: - | I49: - | J49: -
C50: 수원 | E50: 7239 | F50: 7.8090615 | G50: 3014.75 | H50: 0.048131329 | I50: 0.032221263 | J50: 0.033913224
D51: HTR | E51: 0 | F51: - | H51: 0 | I51: 0
...

Sheet 260201
B2: [26.1H 언팩 소셜 버즈 현황] | X2: -29D | Y2: -1D | Z2: D-day | AA2: +42D | AB2: Start Date | AC2: End Date
X3: 45651 | Y3: 45679 | Z3: 45680 | AA3: 45721 | AB3: 45651 | AC3: 45655
B4: 1. 소셜 버즈 현황 | P4: Data 기준 : 2026/1/28 ~ 2026/2/1 (언팩-29D ~ 언팩-25D) | X4: 46050 | Y4: 46078 | Z4: 46079 | AA4: 46120 | AB4: 46050 | AC4: 46054
C6: □ 총 버즈량 135K, 전년 比 2.8배
C7: ① IG 크레에이터 發 N-1 제품 카메라 소구 활동 (71K, 52%) | V7: https://www.instagram.com/reel/DTVVCkGjF7j
C8: ② 티징 컨텐츠 기반, Privacy Display 소셜 內 관심 확산후 소강 中 (16K, 11%) | V8: https://x.com/UniverseIce/status/2016322537777725746 | W8: https://x.com/UniverseIce/status/2016342843644883276
C9: ③ Enhypen 협업, 올림픽 연계 올림픽 카운트다운 및 Victory Selfie 컨텐츠 (7K, 5%) | V9: https://x.com/Olympic/status/2016316039202517387
C10: ④ 테크 인플루언서, 언팩 기대 요소를 댓글로 작성하는 이벤트 진행 (6K, 5%) | V10: https://x.com/SaudiAndroid/status/2016546556028014909 | W10: https://x.com/osamahesam1/status/2016560914309263778
C12: □ 디스플레이 (32%) > 디자인 (11%) > AP/Memory (10%) 順 제품 관심 생성 중
C13: ① 디스플레이 (긍 53%, 부 3%) : Privacy Display 기능 中 부분 적용 가능 루머에 혁신적인 기능이라는 긍정 반응 多 | V13: https://x.com/sondesix/status/2016520584369471682 | W13: https://x.com/jethronyagti/status/2016577101206368706
C14: (※ Use Scene : SNS/일상 26%, 금융/개인정보 8%, 업무 4% 順)
C15: ② 디자인 (긍 20%, 부 8%) : 얇고 가벼운 외관 및 색상 관련 루머 확산 | V15: https://x.com/beebomco/status/2016535725328806170 | W15: https://x.com/kandhesh/status/2016527453418819962
C16: ③ AP/Memory (긍 17%, 부 11%) : SD8 Elite Gen 5 성능 기대, Exynos 2600 적용 모델 성능 우려 일부 有 | V16: https://www.reddit.com/r/PhoneNow/comments/1qpafa0/comment/o2btjvf/ | W16: https://www.reddit.com/r/samsunggalaxy/comments/1qop48c/comment/o23f1j2/
C18: □ 발화자 : 로컬 57% > 소비자 21% > 미디어 10% > 수원 5% 順
C19: - 테크 인플루언서 중심 제품 루머 및 언팩 기대감 지속 확산 중 | V19: https://x.com/SaudiAndroid/status/2016546556028014909 | W19: https://x.com/UniverseIce/status/2016342843644883276
B23: [버즈량 현황] | X23: [HTR 제외 시]
B24: 구분 | E24: Total 버즈량 | L24: 구분 | X24: 구분 | Z24: Total 버즈량
F25: Family | I25: Buds4 +Pro | J25: AI 단독 언급 | M25: Family | S25: Buds4 +Pro | AA25: Family | AD25: Buds4 +Pro | AE25: AI 단독 언급
G26: Ultra | H26: Base/+ | O26: Ultra | Q26: Base/+ | AB26: Ultra | AC26: Base/+
M27: Pos | N27: Neg | O27: Pos | P27: Neg | Q27: Pos | R27: Neg | S27: Pos | T27: Neg
B28: 26.1H UNPK | E28: 135372 | F28: 41838 | G28: 23964 | H28: 17874 | I28: 2381 | J28: 13456 | L28: 26.1H UNPK | M28: 0.27192623 | N28: 0.11305621 | O28: 0.35211268 | P28: 0.13848052 | Q28: 0.16585067 | R28: 0.079423365 | S28: 0.22881921 | T28: 0.10873916 | X28: 26.1H UNPK | Z28: 135372 | AA28: 41838 | AB28: 23964 | AC28: 17874 | AD28: 2381 | AE28: 13456
B29: (전년 比) | E29: 2.7865215 | F29: 1.491604 | G29: 1.6534879 | H29: 1.733993 | I29: 0.42877724 | J29: 0.52447771 | L29: (전년 比) | M29: 0.086417718 | N29: 0.020270772 | O29: 0.15621619 | P29: 0.050739514 | Q29: 0.012167578 | R29: -0.055181829 | S29: -0.013985005 | T29: -0.073933967 | X29: (전년 比) | Z29: 2.7865215 | AA29: 1.491604 | AB29: 1.6534879 | AC29: 1.733993 | AD29: 0.42877724 | AE29: 0.52447771
B30: 25.1H UNPK | E30: 48581 | F30: 28049 | G30: 14493 | H30: 10308 | I30: 5553 | J30: 25656 | L30: 25.1H UNPK | M30: 0.18550851 | N30: 0.092785434 | O30: 0.19589648 | P30: 0.087741004 | Q30: 0.15368309 | R30: 0.13460519 | S30: 0.24280422 | T30: 0.18267313 | X30: 25.1H UNPK | Z30: 48581 | AA30: 28049 | AB30: 14493 | AC30: 10308 | AD30: 5553 | AE30: 25656
B31: ※ 제품 버즈 : Ultra 언급 버즈는 Ultra로 우선 반영, Base/+는 Ultra 언급 제외 후 집계 | L31: ※ Sentiment는 TV/News/Radio/Print 및 HTR 제외하고 추출
B32: ※ Buds4+Pro의 전작 기준은 Buds3+Pro, '24.2H 언팩 당시 공개 기준 ('25.1H 언팩 총 합계에 미 포함)
B33: ※ Brand 언급 버즈량 : 14K (#ExplorGalaxy)
B35: 2. 발화자별 버즈 현황
C37: ① 수원 (7K)
C38: - 밀라노 올림픽 참석 Icon 인플루언서(Enhypen) 컨텐츠 팬 계정 내 확산 (7K) | V38: https://x.com/Olympic/status/2016316039202517387
C39: ② 로컬 (78K)
C40: - IG Creator 發 브랜드 커뮤니케이션(#ExploreGalaxy) 확산 中 (67K + 소비자 4K) | V40: https://www.instagram.com/p/DTVVCkGjF7j/
C41: - SESAR 테크 인플루언서 發 UNPK 해시태그 및 기대 제품 댓글 작성 소비자 참여 이벤트 버즈 발생 (4K) | V41: https://x.com/SaudiAndroid/status/2016546556028014909
C42: - 그 외 테크 인플루언서 發 Privercy Display 중심으로 제품 루머 생성 (2K) | V42: https://x.com/UniverseIce/status/2016342843644883276
C43: ③ 소비자 (28K)
C44: - Privacy Display 기능 PR 공개로 혁신성에 대한 긍정 버즈 확산 中 (12K) | V44: https://x.com/rrreggegg/status/2016407184419258802
B47: 발화자 | E47: 버즈량 | H47: 비중
F48: 전년 比 | G48: 전작 평균 | I48: 전년 比 | J48: 전작 평균
B49: Total | E49: 135372 | F49: 2.7865215 | G49: 78046 | H49: - | I49: - | J49: -
C50: 수원 | E50: 7115 | F50: 10.55638 | G50: 2781.25 | H50: 0.052558875 | I50: 0.038685138 | J50: 0.035636035
D51: HTR | E51: 0 | F51: - | H51: 0 | I51: 0
...

Sheet 260129
B2: ="[26.1H 언팩 소셜 버즈 현황]" -> [26.1H 언팩 소셜 버즈 현황] | X2: -29D | Y2: -1D | Z2: D-day | AA2: +42D | AB2: Start Date | AC2: End Date
X3: 45651 | Y3: 45679 | Z3: 45680 | AA3: 45721 | AB3: =AB4-399 -> 45651 | AC3: =AC4-399 -> 45652
B4: ="1. 소셜 버즈 현황" -> 1. 소셜 버즈 현황 | P4: ="Data 기준 : "&YEAR(AB4)&"/"&MONTH(AB4)&"/"&DAY(AB4)&" ~ "&YEAR(AC4)&"/"&MONTH(AC4)&"/"&DAY(AC4)&" (언팩-29D ~ 언팩"&_xlfn.DAYS(AC4,Z4)&"D)" -> Data 기준 : 2026/1/28 ~ 2026/1/29 (언팩-29D ~ 언팩-28D) | X4: 46050 | Y4: 46078 | Z4: 46079 | AA4: 46120 | AB4: 46050 | AC4: 46051
C6: □ 총 버즈량 67K, 전년 比 3.4배
C7: ① 공개된 티징 컨텐츠 기반, Privacy Display 소셜 內 관심 지속 확산 中 (14K, 20%) | V7: https://x.com/UniverseIce/status/2016322537777725746
C8: ② IG 크레에이터 發 N-1 제품 카메라 소구 활동 (28K, 42%) | V8: https://www.instagram.com/reel/DTVVCkGjF7j/c/18088663010034647
C9: ③ Enhypen 협업, 올림픽 연계한 카메라 소구 컨텐츠 중심 팬덤 관심 발생 (6K, 9%) | V9: https://x.com/Olympic/status/2016316039202517387
C10: ④ Tech 인플루언서, 언팩 기대 요소를 댓글로 작성하는 이벤트 진행 (4K, 6%) | V10: https://x.com/SaudiAndroid/status/2016546556028014909 | W10: https://x.com/osamahesam1/status/2016560914309263778
C12: □ 디스플레이 (44%) > 디자인 (9%) > AP/Memory (7%) 順 제품 관심 생성 중
C13: ① 디스플레이 (긍 56%, 부 2%) : Privacy Display 기능 中 부분 적용 가능 루머에 혁신적인 기능이라는 긍정 반응 多 | V13: https://x.com/sondesix/status/2016520584369471682 | W13: https://x.com/jethronyagti/status/2016577101206368706
C14: (※ 아직 초기이나 Use Scene은 SNS/일상 71%, 금융/개인정보 7%, 업무 보안 4% 順)
C15: ② 디자인 (긍 21%, 부 6%) : 총 6 종 발매 색상 예상 루머 확산 中 | V15: https://x.com/beebomco/status/2016535725328806170 | W15: https://x.com/kandhesh/status/2016527453418819962
C16: ③ AP/Memory (긍 19%, 부 12%) : SD8 Elite Gen 5 탑재 기대와 일부 모델 당사 Exynos 탑재 우려 혼재 | V16: https://www.reddit.com/r/PhoneNow/comments/1qpafa0/comment/o2btjvf/ | W16: https://www.reddit.com/r/samsunggalaxy/comments/1qop48c/comment/o23f1j2/
C18: □ 발화자 : 로컬 47% > 소비자 27% > 미디어 10% 順
C19: - 티징 컨텐츠를 테크 인플루언서가 공유하고, 이에 소비자들의 댓글로 확산 中
C20: - SESAR를 시작으로 로컬 테크 인플루언서 언팩 홍보 활동 게시 | V20: https://x.com/SaudiAndroid/status/2016546556028014909 | W20: https://x.com/osamahesam1/status/2016560914309263778
B24: [버즈량 현황] | X24: [HTR 제외 시]
B25: 구분 | E25: Total 버즈량 | L25: 구분 | X25: 구분 | Z25: Total 버즈량
F26: Family | I26: Buds4 +Pro | J26: AI 단독 언급 | M26: Family | S26: Buds4 +Pro | AA26: Family | AD26: Buds4 +Pro | AE26: AI 단독 언급
G27: Ultra | H27: Base/+ | O27: Ultra | Q27: Base/+ | AB27: Ultra | AC27: Base/+
M28: Pos | N28: Neg | O28: Pos | P28: Neg | Q28: Pos | R28: Neg | S28: Pos | T28: Neg
B29: 26.1H UNPK | E29: 66920 | F29: 24806 | G29: 13062 | H29: 11744 | I29: 827 | J29: 7937 | L29: 26.1H UNPK | M29: 0.28736014 | N29: 0.095059738 | O29: 0.41028675 | P29: 0.13509331 | Q29: 0.15375482 | R29: 0.051548432 | S29: 0.18403909 | T29: 0.091205212 | X29: 26.1H UNPK | Z29: =E29-SUMIFS(Total!T:T,Total!G:G,">=" & $AB$4,Total!G:G,"<=" & $AC$4) -> 66920 | AA29: =SUMIFS(Total!BQ:BQ,Total!G:G,">=" & $AB$4,Total!G:G,"<=" & $AC$4) -> 24806 | AB29: =SUMIFS(Total!BT:BT,Total!G:G,">=" & $AB$4,Total!G:G,"<=" & $AC$4) -> 13062 | AC29: =SUMIFS(Total!BW:BW,Total!G:G,">=" & $AB$4,Total!G:G,"<=" & $AC$4) -> 11744 | AD29: =SUMIFS(Total!BZ:BZ,Total!G:G,">=" & $AB$4,Total!G:G,"<=" & $AC$4) -> 827 | AE29: =J29-SUMIFS(#REF!,#REF!,">=" & $AB$4,#REF!,"<=" & $AC$4,#REF!,"AI",#REF!,"AI",#REF!,"Y") -> #REF!
B30: (전년 比) | E30: 3.3682303 | F30: 2.7840629 | G30: 3.1573604 | H30: 3.3602289 | I30: 0.33907339 | J30: 0.76760155 | L30: (전년 比) | M30: 0.12563075 | N30: 0.0037867199 | O30: 0.2491224 | P30: 0.052381204 | Q30: -0.017121848 | R30: -0.078466427 | S30: -0.0054126817 | T30: -0.051057106 | X30: (전년 比) | Z30: =Z29/Z31 -> 3.3682303 | AA30: =AA29/AA31 -> 2.7840629 | AB30: =AB29/AB31 -> 3.1573604 | AC30: =AC29/AC31 -> 3.3602289 | AD30: =AD29/AD31 -> 0.33907339 | AE30: =AE29/AE31 -> #REF!
B31: 25.1H UNPK | E31: 19868 | F31: 8910 | G31: 4137 | H31: 3495 | I31: 2439 | J31: 10340 | L31: 25.1H UNPK | M31: 0.16172938 | N31: 0.091273018 | O31: 0.16116436 | P31: 0.082712105 | Q31: 0.17087667 | R31: 0.13001486 | S31: 0.18945177 | T31: 0.14226232 | X31: 25.1H UNPK | Z31: =E31-SUMIFS(Total!S:S,Total!F:F,">=" & $AB$3,Total!F:F,"<=" & $AC$3) -> 19868 | AA31: =SUMIFS(Total!BP:BP,Total!F:F,">=" & $AB$3,Total!F:F,"<=" & $AC$3) -> 8910 | AB31: =SUMIFS(Total!BS:BS,Total!F:F,">=" & $AB$3,Total!F:F,"<=" & $AC$3) -> 4137 | AC31: =SUMIFS(Total!BV:BV,Total!F:F,">=" & $AB$3,Total!F:F,"<=" & $AC$3) -> 3495 | AD31: =SUMIFS(Total!BY:BY,Total!C:C,">=" & $AB$3-197,Total!C:C,"<=" & $AC$3-197) -> 2439 | AE31: =J31-SUMIFS(#REF!,#REF!,">=" & $AB$3,#REF!,"<=" & $AC$3,#REF!,"AI") -> #REF!
B32: ※ 제품 버즈 : Ultra 언급 버즈는 Ultra로 우선 반영, Base/+는 Ultra 언급 제외 후 집계 | L32: ※ Sentiment는 TV/News/Radio/Print 및 HTR 제외하고 추출
B33: ※ Buds4+Pro의 전작 기준은 Buds3+Pro, '24.2H 언팩 당시 공개 기준 ('25.1H 언팩 총 합계에 미 포함)
B34: ※ Brand 언급 버즈량 : 14K (#ExplorGalaxy)
B36: ="2. 발화자별 버즈 현황" -> 2. 발화자별 버즈 현황
C38: ① 수원 (6K)
C39: - 밀라노 올림픽 참석 Icon 인플루언서(Enhypen) 컨텐츠 팬 계정 내 확산 (6K) | V39: https://x.com/Olympic/status/2016316039202517387
C40: ② 로컬 (31K)
C41: - IG Creator 發 브랜드 커뮤니케이션(#ExploreGalaxy) 확산 中 (20K + 소비자 4K) | V41: https://www.instagram.com/p/DTVVCkGjF7j/
C42: - SESAR 테크 인플루언서 發 UNPK 해시태그 및 기대 제품 댓글 작성 소비자 참여 이벤트 버즈 발생 (2K) | V42: https://x.com/SaudiAndroid/status/2016546556028014909
C43: ③ 소비자 (18K)
C44: - Privacy Display 기능 PR 공개로 혁신성에 대한 긍정 버즈 확산 中 (10K) | V44: https://x.com/UniverseIce/status/2016342843644883276
V45: https://x.com/UniverseIce/status/2016342843644883276
B47: 발화자 | E47: 버즈량 | H47: 비중
F48: 전년 比 | G48: 전작 평균 | I48: 전년 比 | J48: 전작 평균
B49: Total | E49: 66920 | F49: 3.3682303 | G49: 35507 | H49: - | I49: - | J49: -
C50: 수원 | E50: 6464 | F50: 28.857143 | G50: 1518.75 | H50: 0.096592947 | I50: 0.085318536 | J50: 0.042772955
...

Sheet 260128
B2: [26.1H 언팩 소셜 버즈 현황] | X2: -29D | Y2: -1D | Z2: D-day | AA2: +42D | AB2: Start Date | AC2: End Date
X3: 45651 | Y3: 45679 | Z3: 45680 | AA3: 45721 | AB3: =AB4-399 -> 45651 | AC3: =AC4-399 -> 45651
B4: 1. 소셜 버즈 현황 | P4: Data 기준 : 2026/1/28 ~ 2026/1/28 (언팩-29D ~ 언팩-29D) | X4: 46050 | Y4: 46078 | Z4: 46079 | AA4: 46120 | AB4: 46050 | AC4: 46050
C5: □ 총 버즈량 35K, 전년比 3.8배 ① 공개된 티징 컨텐츠 기반, Privacy Display 소셜 內 관심 생성 중 (8K, 22%) ② IG 크레에이터 發 N-1 제품 카메라 소구 활동(14K, 40%) ③ Enhypen 협업, 올림픽 연계한 카메라 소구 컨텐츠 중심 팬덤 관심 발생 (5K, 15%) □ 디스플레이 (45%) > 디자인 (7%) > 배터리 (4%) 順 제품 관심 생성 중 ① 디스플레이 (긍 73%, 부 1%) : Privacy Display 기능 中 Noti만 가려지는 기능에 대한 관심 高 (※ 아직 초기이나 Use Scene은 SNS 73%, 업무 보안 2%, 금융 정보 1% 順) ② 디자인 (긍 20%, 부 5%) : 얇고 가벼워진 디자인 기대 ③ 배터리 (긍 9%, 부 10%) : 충전 속도 향상 기대 (Ultra 유선 45W → 60W) 및 용량 동일 우려 혼재 □ 발화자 : 로컬 42%, 소비자 29%, 수원 15% 順 - 티징 컨텐츠를 테크 인플루언서가 공유하고, 이에 소비자들의 댓글로 확산 中 | V5: https://x.com/Olympic/status/2016316039202517387 | W5: https://x.com/UniverseIce/status/2016322537777725746 | X5: https://www.instagram.com/reel/DTVVCkGjF7j/c/18088663010034647
B7: [버즈량 현황] | X7: [HTR 제외 시]
B8: 구분 | E8: Total 버즈량 | L8: 구분 | X8: 구분 | Z8: Total 버즈량
F9: Family | I9: Buds4 +Pro | J9: AI 단독 언급 | M9: Family | S9: Buds4 +Pro | AA9: Family | AD9: Buds4 +Pro | AE9: AI 단독 언급
G10: Ultra | H10: Base/+ | O10: Ultra | Q10: Base/+ | AB10: Ultra | AC10: Base/+
M11: Pos | N11: Neg | O11: Pos | P11: Neg | Q11: Pos | R11: Neg | S11: Pos | T11: Neg
B12: 26.1H UNPK | E12: 35204 | F12: 12123 | G12: 6004 | H12: 6119 | I12: 188 | J12: 4053 | L12: 26.1H UNPK | M12: 0.28894732 | N12: 0.095971453 | O12: 0.46014068 | P12: 0.14028918 | Q12: 0.13053697 | R12: 0.054962936 | S12: 0.26126126 | T12: 0.10810811 | X12: 26.1H UNPK | Z12: =E12-SUMIFS(Total!T:T,Total!G:G,">=" & $AB$4,Total!G:G,"<=" & $AC$4) -> 35204 | AA12: =SUMIFS(Total!BQ:BQ,Total!G:G,">=" & $AB$4,Total!G:G,"<=" & $AC$4) -> 12123 | AB12: =SUMIFS(Total!BT:BT,Total!G:G,">=" & $AB$4,Total!G:G,"<=" & $AC$4) -> 6004 | AC12: =SUMIFS(Total!BW:BW,Total!G:G,">=" & $AB$4,Total!G:G,"<=" & $AC$4) -> 6119 | AD12: =SUMIFS(Total!BZ:BZ,Total!G:G,">=" & $AB$4,Total!G:G,"<=" & $AC$4) -> 188 | AE12: =J12-SUMIFS(#REF!,#REF!,">=" & $AB$4,#REF!,"<=" & $AC$4,#REF!,"AI",#REF!,"AI",#REF!,"Y") -> #REF!
B13: (전년 比) | E13: 3.7821229 | F13: 3.1927838 | G13: 3.4585253 | H13: 3.8949714 | I13: 0.11230585 | J13: 1.0596078 | L13: (전년 比) | M13: 0.1233241 | N13: 0.017997634 | O13: 0.31882567 | P13: 0.10005365 | Q13: -0.085031889 | R13: -0.10870972 | S13: 0.0052371649 | T13: -0.018397916 | X13: (전년 比) | Z13: =Z12/Z14 -> 3.7821229 | AA13: =AA12/AA14 -> 3.1927838 | AB13: =AB12/AB14 -> 3.4585253 | AC13: =AC12/AC14 -> 3.8949714 | AD13: =AD12/AD14 -> 0.11230585 | AE13: =AE12/AE14 -> #REF!
B14: 25.1H UNPK | E14: 9308 | F14: 3797 | G14: 1736 | H14: 1571 | I14: 1674 | J14: 3825 | L14: 25.1H UNPK | M14: 0.16562322 | N14: 0.077973819 | O14: 0.14131501 | P14: 0.040235525 | Q14: 0.21556886 | R14: 0.16367265 | S14: 0.2560241 | T14: 0.12650602 | X14: 25.1H UNPK | Z14: =E14-SUMIFS(Total!S:S,Total!F:F,">=" & $AB$3,Total!F:F,"<=" & $AC$3) -> 9308 | AA14: =SUMIFS(Total!BP:BP,Total!F:F,">=" & $AB$3,Total!F:F,"<=" & $AC$3) -> 3797 | AB14: =SUMIFS(Total!BS:BS,Total!F:F,">=" & $AB$3,Total!F:F,"<=" & $AC$3) -> 1736 | AC14: =SUMIFS(Total!BV:BV,Total!F:F,">=" & $AB$3,Total!F:F,"<=" & $AC$3) -> 1571 | AD14: =SUMIFS(Total!BY:BY,Total!C:C,">=" & $AB$3-197,Total!C:C,"<=" & $AC$3-197) -> 1674 | AE14: =J14-SUMIFS(#REF!,#REF!,">=" & $AB$3,#REF!,"<=" & $AC$3,#REF!,"AI") -> #REF!
B15: ※ 제품 버즈 : Ultra 언급 버즈는 Ultra로 우선 반영, Base/+는 Ultra 언급 제외 후 집계 | L15: ※ Sentiment는 TV/News/Radio/Print 및 HTR 제외하고 추출
B16: ※ Buds4+Pro의 전작 기준은 Buds3+Pro, '24.2H 언팩 당시 공개 기준 ('25.1H 언팩 총 합계에 미 포함)
B17: ※ Brand 언급 버즈량 : 14K (#ExplorGalaxy)
B19: 2. 발화자별 버즈 현황
B20: ① 수원 (5K) - 밀라노 올림픽 및 Icon 인플루언서(Enhypen) 협업 Camera Selfie 소구 컨텐츠 (5K) ② 로컬 (15K) - IG Creator 發 브랜드 커뮤니케이션(#ExploreGalaxy) 확산 中 (13K + 소비자 1K) ③ 소비자 (10K) - Privacy Display 기능 PR 공개로 혁신성에 대한 긍정 버즈 확산 中 (8K) | V20: https://x.com/Olympic/status/2016316039202517387 | W20: https://www.instagram.com/p/DTVVCkGjF7j/ | X20: https://x.com/UniverseIce/status/2016342843644883276
B22: 발화자 | E22: 버즈량 | H22: 비중
F23: 전년 比 | G23: 전작 평균 | I23: 전년 比 | J23: 전작 평균
B24: Total | E24: 35204 | F24: 3.7821229 | G24: 17913 | H24: - | I24: - | J24: -
C25: 수원 | E25: 5334 | F25: 58.615385 | G25: 285 | H25: 0.15151687 | I25: 0.14174034 | J25: 0.015910677
D26: HTR | E26: 0 | F26: - | H26: 0 | I26: 0
D27: Icon 인플루언서 | E27: 5141 | F27: 233.68182 | H27: 0.96381702 | I27: 0.72205878
D28: Contents | E28: 193 | F28: 2.7971014 | H28: 0.036182977 | I28: -0.72205878
C29: 로컬 | E29: 14663 | F29: 2.5474288 | G29: 2676.75 | H29: 0.41651517 | I29: -0.20187761 | J29: 0.14943475
D30: 로컬 인플루언서 | E30: 13820 | F30: 3.0440529 | H30: 0.94250835 | I30: 0.15376617
D31: Partners | E31: 28 | F31: 0.30107527 | H31: 0.0019095683 | I31: -0.014247485
D32: 법인 활동 | E32: 815 | F32: 0.72573464 | H32: 0.055582077 | I32: -0.13951869
C33: 미디어 | E33: 3322 | F33: 4.3311604 | G33: 2305.75 | H33: 0.094364277 | I33: 0.011962042 | J33: 0.12872296
C34: 커뮤니티 | E34: 1565 | F34: 1.4612512 | G34: 2536.25 | H34: 0.044455176 | I34: -0.070607136 | J34: 0.14159107
C35: 소비자 | E35: 10320 | F35: 6.3585952 | G35: 10108.75 | H35: 0.29314851 | I35: 0.11878237 | J35: 0.56434054
B36: ※ HTR, Icon 인플루언서, Contents 비중/로컬 인플루언서, Partners, 법인 활동 비중은 각각 수원/로컬 內 집계
B37: ※ 전작 평균 : S24, FF6, S25, FF7 해당구간 평균
B38: ※ 로컬 인플루언서 : 로컬 Icon 인플루언서, 로컬 Tech 인플루언서, 로컬 Lifestyle 인플루언서의 합
B39: ※ Partners : 로컬 PP, 로컬 Retailer, 로컬 Telco의 합
B40: ※ 법인 활동 : 로컬 HTR, 로컬 Contents의 합
B42: 3. 주요 Miracle CXP (26.1H UNPK Base) | X42: https://space.sprinklr.com/research/insights/listening/dashboard/696592937cb16f4b0d0146d3/tab/2
B43: - Privacy Display를 활용한 공공장소에서의 SNS 및 금융/개인정보 사용에 제약이 없는 점 호평 | X43: □ 주요 Miracle CXP / User Scene 분석 - Privacy Display □ 주요 Miracle CXP / Camera Feature □ 주요 Miracle CXP / AI Feature
B45: 주요 CXP | F45: 버즈량 | G45: 비중 | H45: Sentiment | J45: 내용
H46: Pos | I46: Neg
...

Sheet 법인_260204
G1: -29
B2: ■ 26.1H 언팩 12개 전략 법인 소셜 버즈 현황 | G2: -22
B3: * Data Cut: [Region A] 2026-01-27 ~ 2026-02-03 [Region B] 2026-01-28 ~ 2026-02-04
C5: 누적 | E5: Pre-teaser | G5: Buzz Driver
D6: 전년比 | E6: U-4W | G6: 누적 | H6: 금주 하이라이트
F7: 전년比
B8: SEA | C8: 10025 | D8: 2.5672215 | E8: 10025 | F8: 2.5672215 | G8: - | H8: - 공식 계정 發 동시 다발적 Pre PR 컨텐츠 게재 - Reddit 중심 신제품 관련 소비자 토론 활발 - 초대장 이미지 유출 통한 언팩 일정 확산 | I8: Pre PR (IG) | J8: Rumor(Reddit) | K8: Rumor(Reddit) | L8: Invitation(X)
B9: SEUK | C9: 28970 | D9: 73.903061 | E9: 28970 | F9: 73.903061 | G9: - | H9: - 공식 계정 發 동시 다발적 Privacy Pre PR 컨텐츠 게재 - FB 공식 계정 發 전작 활용 7 Days 소비자 참여 이벤트 (#ExploreGalaxy) | I9: Pre PR(IG) - Privacy | J9: Pre PR(IG) | K9: #ExploreGalaxy(FB) | L9: #ExploreGalaxy(FB2)
B10: SEF | C10: 461 | D10: 1.3323699 | E10: 461 | F10: 1.3323699 | G10: - | H10: - 공식 계정 發 동시 다발적 Privacy Pre PR 컨텐츠 게재 및 뉴스 중심의 신제품 스펙 유출 | I10: Pre PR(IG) | J10: Rumor(News)
B11: SEG | C11: 817 | D11: 2.002451 | E11: 817 | F11: 2.002451 | G11: - | H11: - 공식 계정 發 동시 다발적 Privacy Pre PR 컨텐츠 게재 및 뉴스 중심의 신제품 스펙 유출 | I11: Pre PR(IG) | J11: Rumor(News)
B12: SEIN | C12: 4470 | D12: 2.4439584 | E12: 4470 | F12: 2.4439584 | G12: - | H12: - 공식 계정 發 동시 다발적 Pre PR 컨텐츠 게재 - X 중심의 신제품 스펙 유출 및 소비자 루머 확산 | I12: Pre PR (TT) | J12: Rumor(X) | K12: Rumor(X)
B13: SEAU | C13: 378 | D13: 3.3451327 | E13: 378 | F13: 3.3451327 | G13: - | H13: - 공식 계정 發 동시 다발적 Pre PR 컨텐츠 게재 - 뉴스 중심의 신제품 스펙 유출 - 포럼 내 루머 및 토론 확산 | I13: Pre PR (TT) | J13: Rumor(News) | K13: Rumor(Forum)
B14: TSE | C14: 1205 | D14: 2.2191529 | E14: 1205 | F14: 2.2191529 | G14: - | H14: - 공식 계정 發 동시 다발적 Pre PR 컨텐츠 게재 - X 중심의 신제품 스펙 및 이미지 유출로 인한 기대감 확산 | I14: Pre PR(TT) | J14: Pre PR(IG) | K14: Rumor(X) | L14: Pre PR(IG)
B15: SIEL | C15: 4155 | D15: 1.3173748 | E15: 4155 | F15: 1.3173748 | G15: - | H15: - 공식 계정 發 동시 다발적 Privacy Pre PR 컨텐츠 게재 - 테크 인플루언서 중심 신제품 루머 확산 - X, 뉴스 중심의 신제품 기능 관련 이미지 유출 및 기대감 확산 | I15: Pre PR(IG) | J15: Rumor(YT) | K15: Rumor(X)
B16: SGE | C16: 554 | D16: 2.4954955 | E16: 554 | F16: 2.4954955 | G16: - | H16: - 공식 계정 發 동시 다발적 Privacy Pre PR 컨텐츠 게재 - X, 포럼 중심의 신제품 기능 관련 기대감 확산 | I16: Pre PR(IG) | J16: Rumor(X) | K16: Rumor(Forum)
B17: SEDA | C17: 3914 | D17: 6.7951389 | E17: 3914 | F17: 6.7951389 | G17: - | H17: - 공식 계정 發 동시 다발적 Privacy Pre PR 컨텐츠 게재 - 뉴스 및 X 중심의 신제품 루머/스펙 유출 - Members 내 #FeitoComGalaxy 사진 공유 뱃지 이벤트 - IG 중심 #FeitoComGalaxy 사진/영상 공유 | I17: Pre PR (IG) | J17: Rumor(News) | K17: Rumor(X) | L17: #FeitoComGalaxy(Members) | M17: #FeitoComGalaxy(IG)
B18: Korea | C18: 11664 | D18: 2.2319173 | E18: 11664 | F18: 2.2319173 | G18: - | H18: - 공식 계정 發 동시 다발적 Pre PR 컨텐츠 게재 - X, 포럼 중심의 신제품 스펙 및 이미지 유출로 인한 기대감 및 루머 확산 - 밀라노 올림픽 출전 선수단 소개 컨텐츠 게재 (#withGalaxy) - YT 테크 인플루언서에 의한 루머 및 유출 확산(주연, 테크몽) - PR 컨텐츠 활용 공식계정 IG Event | I18: Pre PR(TT) | J18: Rumor(X) | K18: #withGalaxy(IG) | L18: Rumor(Forum) | M18: YT 테크 인플(주연) | N18: Event(IG)
B19: Japan | C19: 2373 | D19: 1.6664326 | E19: 2373 | F19: 1.6664326 | G19: - | H19: - 공식 계정 發 동시 다발적 Pre PR 컨텐츠 게재 - X 중심의 신제품 스펙 및 이미지 유출로 인한 기대감 및 루머 확산 - 전작 활용 오프라인 부스 방문 포스트 확산 (#GalaxyHarajuku & #GalaxyStudioOsaka) | I19: Pre PR(IG) | J19: Pre PR(TT) | K19: Rumor(X)

Sheet 법인_260203
G1: -29
B2: ■ 26.1H 언팩 12개 전략 법인 소셜 버즈 현황 | G2: -23
B3: * Data Cut: [Region A] 2026-01-27 ~ 2026-02-02 [Region B] 2026-01-28 ~ 2026-02-03
C5: 누적 | E5: Pre-teaser | G5: Buzz Driver
D6: 전년比 | E6: U-4W | G6: 누적 | H6: 금주 하이라이트
F7: 전년比
B8: SEA | C8: 8891 | D8: 2.5431922 | E8: 8891 | F8: 2.5431922 | G8: - | H8: - 공식 계정 發 동시 다발적 Privacy Pre PR 컨텐츠 개재 및 - Reddit 중심 신제품 관련 소비자 토론 활발 - 초대장 이미지 유출 통한 언팩 일정 확산 | I8: Pre PR (IG) | J8: Rumor(Reddit) | K8: Rumor(Reddit) | L8: Invitation(X)
B9: SEUK | C9: 22555 | D9: 68.765244 | E9: 22555 | F9: 68.765244 | G9: - | H9: - 공식 계정 發 동시 다발적 Privacy Pre PR 컨텐츠 개재 - FB 공식 계정 發 전작 활용 7 Days 소비자 참여 이벤트 (#ExploreGalaxy) | I9: Pre PR(IG) - Privacy | J9: Pre PR(IG) | K9: #ExploreGalaxy(FB)
B10: SEF | C10: 368 | D10: 1.2867133 | E10: 368 | F10: 1.2867133 | G10: - | H10: - 공식 계정 發 동시 다발적 Privacy Pre PR 컨텐츠 개재 및 뉴스 중심의 신제품 스펙 유출 | I10: Pre PR(IG) | J10: Rumor(News)
B11: SEG | C11: 724 | D11: 2.0394366 | E11: 724 | F11: 2.0394366 | G11: - | H11: - 공식 계정 發 동시 다발적 Privacy Pre PR 컨텐츠 개재 및 뉴스 중심의 신제품 스펙 유출 | I11: Pre PR(IG) | J11: Rumor(News)
B12: SEIN | C12: 3903 | D12: 2.2176136 | E12: 3903 | F12: 2.2176136 | G12: - | H12: - 공식 계정 發 동시 다발적 Privacy Pre PR 컨텐츠 개재 - X 중심의 신제품 스펙 유출 및 소비자 루머 확산 | I12: Pre PR (TT) | J12: Rumor(X) | K12: Rumor(X)
B13: SEAU | C13: 303 | D13: 3.4827586 | E13: 303 | F13: 3.4827586 | G13: - | H13: - 공식 계정 發 동시 다발적 Privacy Pre PR 컨텐츠 개재 및 뉴스 중심의 신제품 스펙 유출 - 포럼 내 루머 및 토론 확산 | I13: Pre PR (TT) | J13: Rumor(News) | K13: Rumor(Forum)
B14: TSE | C14: 1021 | D14: 0.039468089 | E14: 1021 | F14: 0.039468089 | G14: - | H14: - 공식 계정 發 동시 다발적 Privacy Pre PR 컨텐츠 개재 - X 중심의 신제품 스펙 및 이미지 유출로 인한 기대감 확산 - 공식 계정 發 Camera Pre PR 컨텐츠 개재 | I14: Pre PR(TT) | J14: Pre PR(IG) | K14: Rumor(X) | L14: Pre PR(YT)
B15: SIEL | C15: 3706 | D15: 1.3451906 | E15: 3706 | F15: 1.3451906 | G15: - | H15: - 공식 계정 發 동시 다발적 Privacy Pre PR 컨텐츠 개재 - 테크 인플루언서 중심 신제품 루머 확산 - X 중심의 신제품 기능 관련 이미지 유출 및 기대감 확산 | I15: Pre PR(IG) | J15: Rumor(YT) | K15: Rumor(X)
B16: SGE | C16: 472 | D16: 2.4973545 | E16: 472 | F16: 2.4973545 | G16: - | H16: - 공식 계정 發 동시 다발적 Privacy Pre PR 컨텐츠 개재 - X, 포럼 중심의 신제품 기능 관련 기대감 확산 | I16: Pre PR(IG) | J16: Rumor(X) | K16: Rumor(Forum)
B17: SEDA | C17: 3482 | D17: 6.6961538 | E17: 3482 | F17: 6.6961538 | G17: - | H17: - 공식 계정 發 동시 다발적 Privacy Pre PR 컨텐츠 개재 - 뉴스 및 X 중심의 신제품 루머/스펙 유출 - Members 내 #FeitoComGalaxy 사진 공유 뱃지 이벤트 - IG 중심 #FeitoComGalaxy 사진/영상 공유 | I17: Pre PR (IG) | J17: Rumor(News) | K17: Rumor(X) | L17: #FeitoComGalaxy(Members) | M17: #FeitoComGalaxy(IG)
B18: Korea | C18: 10723 | D18: 2.4627928 | E18: 10723 | F18: 2.4627928 | G18: - | H18: - 공식 계정 發 동시 다발적 Privacy Pre PR 컨텐츠 개재 - X, 포럼 중심의 신제품 스펙 및 이미지 유출로 인한 기대감 및 루머 확산 - 밀라노 올림픽 출전 선수단 소개 컨텐츠 개재 (#withGalaxy) - YT 테크 인플루언서에 의한 루머 및 유출 확산(주연, 테크몽) | I18: Pre PR(TT) | J18: Rumor(X) | K18: #withGalaxy(IG) | L18: Rumor(Forum) | M18: YT 테크 인플(주연)
B19: Japan | C19: 2164 | D19: 1.7052797 | E19: 2164 | F19: 1.7052797 | G19: - | H19: - 공식 계정 發 동시 다발적 Privacy Pre PR 컨텐츠 개재 - X 중심의 신제품 스펙 및 이미지 유출로 인한 기대감 및 루머 확산 - 전작 활용 ILP 방문 포스트 확산 (#GalaxyHarajuku & #GalaxyStudioOsaka) | I19: Pre PR(IG) | J19: Pre PR(TT) | K19: Rumor(X)

Sheet 법인_260202
G1: -29
B2: ■ 26.1H 언팩 12개 전략 법인 소셜 버즈 현황 | G2: -24
B3: * Data Cut: [Region A] 2026-01-27 ~ 2026-02-01 [Region B] 2026-01-28 ~ 2026-02-02
C5: 누적 | E5: Pre-teaser | G5: Buzz Driver
D6: 전년比 | E6: U-4W | G6: 누적 | H6: 금주 하이라이트
F7: 전년比
B8: SEA | C8: 7530 | D8: 2.4353169 | E8: 7530 | F8: 2.4353169 | G8: - | H8: - 공식 계정 發 동시 다발적 Privacy Pre PR 컨텐츠 개재 및 - Reddit 중심 신제품 관련 소비자 토론 활발 - 초대장 이미지 유출 통한 언팩 일정 확산 | I8: Pre PR (IG) | J8: Rumor(Reddit) | K8: Rumor(Reddit) | L8: Invitation(X)
B9: SEUK | C9: 18425 | D9: 69.791667 | E9: 18425 | F9: 69.791667 | G9: - | H9: - 공식 계정 發 동시 다발적 Privacy Pre PR 컨텐츠 개재 - FB 공식 계정 發 전작 활용 7 Days 소비자 참여 이벤트(#ExploreGalaxy) | I9: Pre PR(IG) - Privacy | J9: Pre PR(IG) | K9: #ExploreGalaxy(FB)
B10: SEF | C10: 309 | D10: 1.3918919 | E10: 309 | F10: 1.3918919 | G10: - | H10: - 공식 계정 發 동시 다발적 Privacy Pre PR 컨텐츠 개재 및 뉴스 중심의 신제품 스펙 유출 | I10: Pre PR(IG) | J10: Rumor(News)
B11: SEG | C11: 603 | D11: 2.0721649 | E11: 603 | F11: 2.0721649 | G11: - | H11: - 공식 계정 發 동시 다발적 Privacy Pre PR 컨텐츠 개재 및 뉴스 중심의 신제품 스펙 유출 | I11: Pre PR(IG) | J11: Rumor(News)
B12: SEIN | C12: 3662 | D12: 2.3250794 | E12: 3662 | F12: 2.3250794 | G12: - | H12: - 공식 계정 發 동시 다발적 Privacy Pre PR 컨텐츠 개재 - X 중심의 신제품 스펙 유출 및 소비자 루머 확산 | I12: Pre PR (TT) | J12: Rumor(X) | K12: Rumor(X)
B13: SEAU | C13: 236 | D13: 3.4202899 | E13: 236 | F13: 3.4202899 | G13: - | H13: - 공식 계정 發 동시 다발적 Privacy Pre PR 컨텐츠 개재 및 뉴스 중심의 신제품 스펙 유출 | I13: Pre PR (TT) | J13: Rumor(News)
B14: TSE | C14: 883 | D14: 0.034236749 | E14: 883 | F14: 0.034236749 | G14: - | H14: - 공식 계정 發 동시 다발적 Privacy Pre PR 컨텐츠 개재 - X 중심의 신제품 스펙 및 이미지 유출로 인한 기대감 확산 | I14: Pre PR(TT) | J14: Pre PR(IG) | K14: Rumor(X)
B15: SIEL | C15: 3168 | D15: 1.453211 | E15: 3168 | F15: 1.453211 | G15: - | H15: - 공식 계정 發 동시 다발적 Privacy Pre PR 컨텐츠 개재 - 테크 인플루언서 중심 신제품 루머 확산 - X 중심의 신제품 기능 관련 이미지 유출 및 기대감 확산 | I15: Pre PR(IG) | J15: Rumor(YT) | K15: Rumor(X)
B16: SGE | C16: 435 | D16: 2.71875 | E16: 435 | F16: 2.71875 | G16: - | H16: - 공식 계정 發 동시 다발적 Privacy Pre PR 컨텐츠 개재 - X, 포럼 중심의 신제품 기능 관련 기대감 확산 | I16: Pre PR(IG) | J16: Rumor(X) | K16: Rumor(Forum)
B17: SEDA | C17: 1770 | D17: 4.0877598 | E17: 1770 | F17: 4.0877598 | G17: - | H17: - 공식 계정 發 동시 다발적 Privacy Pre PR 컨텐츠 개재 - 뉴스 및 X 중심의 신제품 루머/스펙 유출 - Members 내 #FeitoComGalaxy 사진 공유 뱃지 이벤트 - IG 중심 #FeitoComGalaxy 사진/영상 공유 | I17: Pre PR (IG) | J17: Rumor(News) | K17: Rumor(X) | L17: #FeitoComGalaxy(Members) | M17: #FeitoComGalaxy(IG)
B18: Korea | C18: 9989 | D18: 2.7114549 | E18: 9989 | F18: 2.7114549 | G18: - | H18: - 공식 계정 發 동시 다발적 Privacy Pre PR 컨텐츠 개재 - X, 포럼 중심의 신제품 스펙 및 이미지 유출로 인한 기대감 및 루머 확산 - 밀라노 올림픽 출전 선수단 소개 컨텐츠 개재 (#withGalaxy) | I18: Pre PR(TT) | J18: Rumor(X) | K18: #withGalaxy(IG)
B19: Japan | C19: 2018 | D19: 1.8754647 | E19: 2018 | F19: 1.8754647 | G19: - | H19: - 공식 계정 發 동시 다발적 Privacy Pre PR 컨텐츠 개재 - X 중심의 신제품 스펙 및 이미지 유출로 인한 기대감 및 루머 확산 | I19: Pre PR(IG) | J19: Pre PR(TT) | K19: Rumor(X)

Sheet 법인_260201
G1: -29
B2: ■ 26.1H 언팩 12개 전략 법인 소셜 버즈 현황 | G2: -25
B3: * Data Cut: [Region A] 2026-01-27 ~ 2026-01-31 [Region B] 2026-01-28 ~ 2026-02-01
C5: 누적 | E5: Pre-teaser | G5: Buzz Driver
D6: 전년比 | E6: U-4W | G6: 누적 | H6: 금주 하이라이트
F7: 전년比
B8: SEA | C8: 6142 | D8: 2.2714497 | E8: 6142 | F8: 2.2714497 | G8: - | H8: - 공식 계정 發 동시 다발적 Privacy Pre PR 컨텐츠 개재 및 - Pre PR로 Reddit 중심 신제품 관련 소비자 토론 활발 - 초대장 이미지 유출 통한 언팩 일정 확산 | I8: Pre PR (IG) | J8: Rumor(Reddit) | K8: Rumor(Reddit) | L8: Invitation(X)
B9: SEUK | C9: 11484 | D9: 51.497758 | E9: 11484 | F9: 51.497758 | G9: - | H9: - 공식 계정 發 동시 다발적 Privacy Pre PR 컨텐츠 개재 - FB 공식 계정 發 7 Days 소비자 참여 이벤트(#ExploreGalaxy) | I9: Pre PR(IG) - Privacy | J9: Pre PR(IG) | K9: IG(#ExploreGalaxy)
B10: SEF | C10: 278 | D10: 1.4479167 | E10: 278 | F10: 1.4479167 | G10: - | H10: - 공식 계정 發 동시 다발적 Privacy Pre PR 컨텐츠 개재 및 뉴스 중심의 신제품 스펙 유출 | I10: Pre PR(IG) | J10: News
B11: SEG | C11: 521 | D11: 2.0674603 | E11: 521 | F11: 2.0674603 | G11: - | H11: - 공식 계정 發 동시 다발적 Privacy Pre PR 컨텐츠 개재 및 뉴스 중심의 신제품 스펙 유출 | I11: Pre PR(IG) | J11: News
B12: SEIN | C12: 3280 | D12: 2.4099927 | E12: 3280 | F12: 2.4099927 | G12: - | H12: - 공식 계정 發 동시 다발적 Privacy Pre PR 컨텐츠 개재 - X 중심의 신제품 스펙 유출 및 소비자 루머 확산 | I12: Pre PR (TT) | J12: Rumor | K12: Rumor
B13: SEAU | C13: 193 | D13: 3.7843137 | E13: 193 | F13: 3.7843137 | G13: - | H13: - 공식 계정 發 동시 다발적 Privacy Pre PR 컨텐츠 개재 및 뉴스 중심의 신제품 스펙 유출 | I13: Pre PR (TT) | J13: News
B14: TSE | C14: 717 | D14: 0.027917299 | E14: 717 | F14: 0.027917299 | G14: - | H14: - 공식 계정 發 동시 다발적 Privacy Pre PR 컨텐츠 개재 - X 중심의 신제품 스펙 및 이미지 유출로 인한 기대감 확산 - #TeamGalaxy 협업 S25Ultra AI 기능 소구 컨텐츠 | I14: Pre PR(TT) | J14: Pre PR(IG) | K14: Rumor | L14: #TeamGalaxy
B15: SIEL | C15: 2886 | D15: 1.5109948 | E15: 2886 | F15: 1.5109948 | G15: - | H15: - 공식 계정 發 동시 다발적 Privacy Pre PR 컨텐츠 개재 - 테크 인플루언서 중심 신제품 루머 확산 - X 중심의 신제품 기능 관련 이미지 유출 및 기대감 확산 | I15: Pre PR(IG) | J15: Rumor | K15: X
B16: SGE | C16: 380 | D16: 2.7941176 | E16: 380 | F16: 2.7941176 | G16: - | H16: - 공식 계정 發 동시 다발적 Privacy Pre PR 컨텐츠 개재 - X, 포럼 중심의 신제품 기능 관련 기대감 확산 | I16: Pre PR(IG) | J16: X | K16: Forum
B17: SEDA | C17: 1517 | D17: 3.9816273 | E17: 1517 | F17: 3.9816273 | G17: - | H17: - 공식 계정 發 동시 다발적 Privacy Pre PR 컨텐츠 개재 - 뉴스 및 X 중심의 신제품 루머/스펙 유출 - Members 내 #FeitoComGalaxy 사진 공유 뱃지 이벤트 - IG 중심 #FeitoComGalaxy 사진 공유 | I17: Pre PR (IG) | J17: Rumor(News) | K17: Rumor(X) | L17: #FeitoComGalaxy(Members) | M17: #FeitoComGalaxy(IG)
B18: Korea | C18: 9347 | D18: 2.8410334 | E18: 9347 | F18: 2.8410334 | G18: - | H18: - 공식 계정 發 동시 다발적 Privacy Pre PR 컨텐츠 개재 - X, 포럼 중심의 신제품 스펙 및 이미지 유출로 인한 기대감 및 루머 확산 | I18: Pre PR(TT) | J18: Rumor
B19: Japan | C19: 1880 | D19: 2 | E19: 1880 | F19: 2 | G19: - | H19: - 공식 계정 發 동시 다발적 Privacy Pre PR 컨텐츠 개재 - X 중심의 신제품 스펙 및 이미지 유출로 인한 기대감 및 루머 확산 | I19: Pre PR(IG) | J19: Pre PR(TT) | K19: Rumor

Sheet 법인_260129
G1: -29
B2: ■ 26.1H 언팩 12개 전략 법인 소셜 버즈 현황 | G2: -28
B3: * Data Cut: [Region A] 2026-01-27 ~ 2026-01-28 [Region B] 2026-01-28 ~ 2026-01-29
C5: 누적 | E5: Pre-teaser | G5: Buzz Driver
D6: 전년比 | E6: U-4W | G6: 누적 | H6: 금주 하이라이트
F7: 전년比
B8: SEA | C8: 2739 | D8: 2.8680628 | E8: 2739 | F8: 2.8680628 | G8: - | H8: - 공식 계정 發 동시 다발적 Privacy Pre PR 컨텐츠 개재 및 - Pre PR로 Reddit 중심 신제품 관련 소비자 토론 활발 | I8: Pre PR (IG) | J8: Rumor(Reddit) | K8: Rumor(Reddit)
B9: SEUK | C9: 3264 | D9: 59.345455 | E9: 3264 | F9: 59.345455 | G9: - | H9: - 공식 계정 發 동시 다발적 Privacy Pre PR 컨텐츠 개재 - FB 공식 계정 發 7 Days 소비자 참여 이벤트(#ExploreGalaxy) | I9: Pre PR(IG) - Privacy | J9: Pre PR(IG) | K9: IG(#ExploreGalaxy)
B10: SEF | C10: 121 | D10: 4.0333333 | E10: 121 | F10: 4.0333333 | G10: - | H10: - 공식 계정 發 동시 다발적 Privacy Pre PR 컨텐츠 개재 및 뉴스 중심의 신제품 스펙 유출 | I10: Pre PR(IG) | J10: News
B11: SEG | C11: 215 | D11: 2.721519 | E11: 215 | F11: 2.721519 | G11: - | H11: - 공식 계정 發 동시 다발적 Privacy Pre PR 컨텐츠 개재 및 뉴스 중심의 신제품 스펙 유출 | I11: Pre PR(IG) | J11: News
B12: SEIN | C12: 2188 | D12: 3.5176849 | E12: 2188 | F12: 3.5176849 | G12: - | H12: - 공식 계정 發 동시 다발적 Privacy Pre PR 컨텐츠 개재 - X 중심의 신제품 유출 및 소비자 루머 확산 | I12: Pre PR (TT) | J12: Rumor
B13: SEAU | C13: 92 | D13: 3.4074074 | E13: 92 | F13: 3.4074074 | G13: - | H13: - 공식 계정 發 동시 다발적 Privacy Pre PR 컨텐츠 개재 및 뉴스 중심의 신제품 스펙 유출 | I13: Pre PR (TT) | J13: News
B14: TSE | C14: 296 | D14: 0.012943852 | E14: 296 | F14: 0.012943852 | G14: - | H14: - 공식 계정 發 동시 다발적 Privacy Pre PR 컨텐츠 개재 - X 중심의 신제품 기능 관련 이미지 유출 및 기대감 확산 - #TeamGalaxy 협업 Galaxy AI 소구 컨텐츠 - 신제품 무선 충전기 관련 루머 확산 | I14: Rumor | J14: #TeamGalaxy | K14: Rumor | L14: Pre PR(TT) | M14: Pre PR(IG)
B15: SIEL | C15: 1463 | D15: 2.3370607 | E15: 1463 | F15: 2.3370607 | G15: - | H15: - 공식 계정 發 동시 다발적 Privacy Pre PR 컨텐츠 개재 - 테크 인플루언서 중심 신제품 루머 확산 - IG 내 Micro 인플루언서 협업 S25FE 컨텐츠 확산 - X 중심의 신제품 기능 관련 이미지 유출 및 기대감 확산 | I15: Pre PR(IG) | J15: Rumor | K15: IG collab | L15: X
B16: SGE | C16: 145 | D16: 3.0208333 | E16: 145 | F16: 3.0208333 | G16: - | H16: - 공식 계정 發 동시 다발적 Privacy Pre PR 컨텐츠 개재 - X, 포럼 중심의 신제품 기능 관련 기대감 확산 | I16: Pre PR(IG) | J16: X | K16: Forum
B17: SEDA | C17: 582 | D17: 6.6896552 | E17: 582 | F17: 6.6896552 | G17: - | H17: - 공식 계정 發 동시 다발적 Privacy Pre PR 컨텐츠 개재 - 뉴스 및 X 중심의 신제품 루머/스펙 유출 - Members 내 #FeitoComGalaxy 사진 공유 뱃지 이벤트 | I17: Pre PR (IG) | J17: Rumor(News) | K17: Rumor(X) | L17: Members(#FeitoComGalaxy)
B18: Korea | C18: 7593 | D18: 8.9119718 | E18: 7593 | F18: 8.9119718 | G18: - | H18: - X 중심의 신제품 기능 관련 이미지/동영상 유출 및 기대감 확산 - 공식 계정 發 동시 다발적 Privacy Pre PR 컨텐츠 개재 - 포럼 중심의 가격 및 출시 일정 관련 루머 확산 - 포럼 중심의 신제품 스펙 유출 | I18: Rumor | J18: Pre PR(TT) | K18: Rumor | L18: Rumor
B19: Japan | C19: 1191 | D19: 2.1654545 | E19: 1191 | F19: 2.1654545 | G19: - | H19: - 공식 계정 發 동시 다발적 Privacy Pre PR 컨텐츠 개재 - X 중심의 신제품 기능 관련 이미지 유출 및 기대감 확산 - X 중심의 신제품 가격 및 스펙 유출 | I19: Rumor | J19: Rumor | K19: Rumor | L19: Rumor | M19: Pre PR(IG) | N19: Pre PR(TT)

Sheet 법인_260128
G1: -29
B2: ■ 26.1H 언팩 12개 전략 법인 소셜 버즈 현황 | G2: -29
B3: * Data Cut: [Region A] 2026-01-27 ~ 2026-01-27 [Region B] 2026-01-28 ~ 2026-01-28
C5: 누적 | E5: Pre-teaser | G5: Buzz Driver
D6: 전년比 | E6: U-4W | G6: 누적 | H6: 금주 하이라이트
F7: 전년比
B8: SEA | C8: 708 | D8: 1.2642857 | E8: 708 | F8: 1.2642857 | G8: - | H8: 공식 계정 發 동시 다발적 Privacy Pre PR 컨텐츠 개재 및 이로 촉발된 Reddit 중심 소비자 토론 | I8: Pre PR (IG) | J8: Reddit
B9: SEUK | C9: 81 | D9: 2.7 | E9: 81 | F9: 2.7 | G9: - | H9: 공식 계정 發 동시 다발적 Privacy Pre PR 컨텐츠 개재 및 뉴스 및 포럼 중심의 신제품 기능 유출 및 기대감 확산 | I9: News
B10: SEF | C10: 31 | D10: 1.6315789 | E10: 31 | F10: 1.6315789 | G10: - | H10: 공식 계정 發 동시 다발적 Privacy Pre PR 컨텐츠 개재 및 뉴스 중심의 신제품 스펙 유출 | I10: News | J10: Pre PR(YT)
B11: SEG | C11: 84 | D11: 1.8666667 | E11: 84 | F11: 1.8666667 | G11: - | H11: 공식 계정 發 동시 다발적 Privacy Pre PR 컨텐츠 개재 및 뉴스 중심의 신제품 스펙 유출 | I11: News
B12: SEIN | C12: 1359 | D12: 4.1944444 | E12: 1359 | F12: 4.1944444 | G12: - | H12: 공식 계정 發 동시 다발적 Privacy Pre PR 컨텐츠 개재 및 뉴스 중심의 신제품 스펙 유출 | I12: Pre PR (TT)
B13: SEAU | C13: 46 | D13: 4.1818182 | E13: 46 | F13: 4.1818182 | G13: - | H13: 공식 계정 發 동시 다발적 Privacy Pre PR 컨텐츠 개재 및 뉴스 중심의 신제품 스펙 유출 | I13: Pre PR (TT)
B14: TSE | C14: 161 | D14: 0.0098888275 | E14: 161 | F14: 0.0098888275 | G14: - | H14: X 중심의 신제품 기능 관련 이미지 유출 및 기대감 확산 #TeamGalaxy 인플루언서 협업 Galaxy AI 소구 컨텐츠 | I14: Rumor | J14: #TeamGalaxy
B15: SIEL | C15: 644 | D15: 1.872093 | E15: 644 | F15: 1.872093 | G15: - | H15: 공식 계정 發 동시 다발적 Privacy Pre PR 컨텐츠 개재 테크 인플루언서 중심 신제품 루머 확산 IG 크레에이터 협업 S25FE 컨텐츠 확산 | I15: Rumor | J15: IG collab | K15: News
B16: SGE | C16: 43 | D16: 2.15 | E16: 43 | F16: 2.15 | G16: - | H16: 공식 계정 發 동시 다발적 Privacy Pre PR 컨텐츠 개재 및 포럼 중심의 신제품 기능 관련 기대감 확산 | I16: Forum
B17: SEDA | C17: 184 | D17: 3.3454545 | E17: 184 | F17: 3.3454545 | G17: - | H17: 공식 계정 發 동시 다발적 Privacy Pre PR 컨텐츠 개재 뉴스 중심의 신제품 스펙 유출 | I17: Pre PR (IG) | J17: News
B18: Korea | C18: 4720 | D18: 13.111111 | E18: 4720 | F18: 13.111111 | G18: - | H18: X 중심의 신제품 기능 관련 이미지/동영상 유출 및 기대감 확산 공식 계정 發 동시 다발적 Privacy Pre PR 컨텐츠 개재 | I18: Rumor | J18: Pre PR(TT)
B19: Japan | C19: 780 | D19: 2.0207254 | E19: 780 | F19: 2.0207254 | G19: - | H19: X 중심의 신제품 기능 관련 이미지 유출 및 기대감 확산 | I19: Rumor

Sheet Line Graph
C3: □ '26.1H 언팩 일별 버즈 Trend
C18: Week 구분 | E18: W-4 | M18: W-3 | T18: W-2 | AA18: W-1
C19: 26.1H UNPK | E19: 46050 | F19: 46051 | G19: 46052 | H19: 46053 | I19: 46054 | J19: 46055 | K19: 46056 | L19: 46057 | M19: 46058 | N19: 46059 | O19: 46060 | P19: 46061 | Q19: 46062 | R19: 46063 | S19: 46064 | T19: 46065 | U19: 46066 | V19: 46067 | W19: 46068 | X19: 46069 | Y19: 46070 | Z19: 46071 | AA19: 46072 | AB19: 46073 | AC19: 46074 | AD19: 46075 | AE19: 46076 | AF19: 46077 | AG19: 46078
D20: Event | E20: Pre-PR | S20: Invi. | V20: HTR | X20: HTR | AA20: HTR | AC20: HTR | AE20: HTR
C21: 25.1H UNPK | E21: 46016 | F21: 46017 | G21: 46018 | H21: 46019 | I21: 46020 | J21: 46021 | K21: 46022 | L21: 46023 | M21: 46024 | N21: 46025 | O21: 46026 | P21: 46027 | Q21: 46028 | R21: 46029 | S21: 46030 | T21: 46031 | U21: 46032 | V21: 46033 | W21: 46034 | X21: 46035 | Y21: 46036 | Z21: 46037 | AA21: 46038 | AB21: 46039 | AC21: 46040 | AD21: 46041 | AE21: 46042 | AF21: 46043 | AG21: 46044
D22: Event | F22: Pre-PR | R22: Invi. | X22: HTR | Z22: HTR | AA22: HTR
C25: 언팩 後 Total Social Buzz Daily Trend
C38: Week 구분 | E38: W+1 | L38: W+2 | S38: W+3 | Z38: W+4 | AG38: W+5
C39: 26.1H UNPK | E39: 46079 | F39: 46080 | G39: 46081 | H39: 46082 | I39: 46083 | J39: 46084 | K39: 46085 | L39: 46086 | M39: 46087 | N39: 46088 | O39: 46089 | P39: 46090 | Q39: 46091 | R39: 46092 | S39: 46093 | T39: 46094 | U39: 46095 | V39: 46096 | W39: 46097 | X39: 46098 | Y39: 46099 | Z39: 46100 | AA39: 46101 | AB39: 46102 | AC39: 46103 | AD39: 46104 | AE39: 46105 | AF39: 46106 | AG39: 46107 | AH39: 46108
C40: Event | E40: UNPK | F40: +24H | G40: +48H | H40: HTR | K40: HTR | N40: HTR | R40: 출시
C41: 25.1H UNPK | E41: 46045 | F41: 46046 | G41: 46047 | H41: 46048 | I41: 46049 | J41: 46050 | K41: 46051 | L41: 46052 | M41: 46053 | N41: 46054 | O41: 46055 | P41: 46056 | Q41: 46057 | R41: 46058 | S41: 46059 | T41: 46060 | U41: 46061 | V41: 46062 | W41: 46063 | X41: 46064 | Y41: 46065 | Z41: 46066 | AA41: 46067 | AB41: 46068 | AC41: 46069 | AD41: 46070 | AE41: 46071 | AF41: 46072 | AG41: 46073 | AH41: 46074
C42: Event | E42: UNPK | F42: +24H | G42: +48H | I42: HTR | L42: HTR | T42: 출시 | W42: HTR | Z42: HTR

Sheet Daily Feature Trend
B2: Rank | C2: Ultra | D2: -1D | L2: Rank | M2: Ultra | N2: -2D | V2: Rank | W2: Ultra | X2: -3D | AF2: Rank | AG2: Ultra | AH2: -4D
D3: 버즈량 (%) | G3: Sentiment | N3: 버즈량 (%) | Q3: Sentiment | X3: 버즈량 (%) | AA3: Sentiment | AH3: 버즈량 (%) | AK3: Sentiment
F4: 전일比 | I4: 전일比 | P4: 전일比 | S4: 전일比 | Z4: 전일比 | AC4: 전일比 | AJ4: 전일比 | AM4: 전일比
G5: 긍정 | H5: 부정 | I5: 긍정 | J5: 부정 | Q5: 긍정 | R5: 부정 | S5: 긍정 | T5: 부정 | AA5: 긍정 | AB5: 부정 | AC5: 긍정 | AD5: 부정 | AK5: 긍정 | AL5: 부정 | AM5: 긍정 | AN5: 부정
B6: 1 | C6: AP/Memory | D6: 784 | E6: 0.14967545 | F6: 0.97149938 | G6: 0.14191419 | H6: 0.12541254 | I6: -0.029841534 | J6: -0.011992039 | L6: 1 | M6: Design | N6: 871 | O6: 0.15208661 | P6: 0.72704508 | Q6: 0.25666667 | R6: 0.086666667 | S6: -0.001954023 | T6: -0.018936782 | V6: 1 | W6: Design | X6: 1198 | Y6: 0.16662031 | Z6: 1.0754039 | AA6: 0.25862069 | AB6: 0.10560345 | AC6: -0.10786181 | AD6: -0.017785134 | AF6: 1 | AG6: Design | AH6: 1114 | AI6: 0.15932494 | AJ6: 1.3136792 | AK6: 0.3664825 | AL6: 0.12338858 | AM6: -0.040090265 | AN6: -0.040930667
B7: 2 | C7: Camera | D7: 758 | E7: 0.14471172 | F7: 0.96070976 | G7: 0.38082192 | H7: 0.14246575 | I7: 0.026467563 | J7: 0.040363651 | L7: 2 | M7: AP/Memory | N7: 807 | O7: 0.14091147 | P7: 0.93294798 | Q7: 0.17175573 | R7: 0.13740458 | S7: 0.016888469 | T7: 0.06660812 | V7: 2 | W7: AP/Memory | X7: 865 | Y7: 0.12030598 | Z7: 1.010514 | AA7: 0.15486726 | AB7: 0.07079646 | AC7: -0.08701 | AD7: -0.033896681 | AF7: 2 | AG7: Camera | AH7: 972 | AI7: 0.13901602 | AJ7: 1.1020408 | AK7: 0.23873874 | AL7: 0.15540541 | AM7: -0.17486817 | AN7: 0.01609655
B8: 3 | C8: Design | D8: 676 | E8: 0.12905689 | F8: 0.7761194 | G8: 0.17090909 | H8: 0.16727273 | I8: -0.085757576 | J8: 0.080606061 | L8: 3 | M8: Camera | N8: 789 | O8: 0.13776847 | P8: 0.96809816 | Q8: 0.35435435 | R8: 0.1021021 | S8: 0.15899012 | T8: -0.030348229 | V8: 3 | W8: Camera | X8: 815 | Y8: 0.11335188 | Z8: 0.83847737 | AA8: 0.19536424 | AB8: 0.13245033 | AC8: -0.0433745 | AD8: -0.022955074 | AF8: 3 | AG8: AP/Memory | AH8: 856 | AI8: 0.12242563 | AJ8: 1.2681481 | AK8: 0.24187726 | AL8: 0.10469314 | AM8: -0.038377521 | AN8: -0.052950171
B9: 4 | C9: Durability | D9: 560 | E9: 0.10691103 | F9: 1.7554859 | G9: 0.065714286 | H9: 0.27714286 | I9: -0.081572536 | J9: 0.19962348 | L9: 4 | M9: Display | N9: 669 | O9: 0.11681509 | P9: 0.82694685 | Q9: 0.38321168 | R9: 0.051094891 | S9: 0.1185058 | T9: -0.037140404 | V9: 4 | W9: Display | X9: 809 | Y9: 0.11251739 | Z9: 0.95739645 | AA9: 0.26470588 | AB9: 0.088235294 | AC9: -0.0085499316 | AD9: 0.012653899 | AF9: 4 | AG9: Display | AH9: 845 | AI9: 0.1208524 | AJ9: 1.2088698 | AK9: 0.27325581 | AL9: 0.075581395 | AM9: -0.10917662 | AN9: -0.020364551
B10: 5 | C10: Display | D10: 526 | E10: 0.10042001 | F10: 0.78624813 | G10: 0.45121951 | H10: 0.048780488 | I10: 0.068007833 | J10: -0.0023144027 | L10: 5 | M10: Price | N10: 530 | O10: 0.092544089 | P10: 0.95323741 | Q10: 0.10900474 | R10: 0.17061611 | S10: -0.020027519 | T10: 0.027758971 | V10: 5 | W10: Battery | X10: 683 | Y10: 0.094993046 | Z10: 0.92798913 | AA10: 0.22268908 | AB10: 0.20168067 | AC10: 0.040232935 | AD10: -0.064985994 | AF10: 5 | AG10: Battery | AH10: 736 | AI10: 0.10526316 | AJ10: 1.2667814 | AK10: 0.18245614 | AL10: 0.26666667 | AM10: -0.21631687 | AN10: 0.05807771
B11: 6 | C11: Price | D11: 446 | E11: 0.085147003 | F11: 0.84150943 | G11: 0.062761506 | H11: 0.26778243 | I11: -0.046243233 | J11: 0.097166313 | L11: 6 | M11: Battery | N11: 447 | O11: 0.078051336 | P11: 0.65446559 | Q11: 0.23837209 | R11: 0.19767442 | S11: 0.015683017 | T11: -0.0040062537 | V11: 6 | W11: S-Pen | X11: 677 | Y11: 0.094158554 | Z11: 1.7139241 | AA11: 0.14393939 | AB11: 0.10984848 | AC11: -0.071887944 | AD11: -0.0052594288 | AF11: 6 | AG11: Price | AH11: 508 | AI11: 0.072654462 | AJ11: 1.2330097 | AK11: 0.088105727 | AL11: 0.21585903 | AM11: -0.18389427 | AN11: -0.037474302
B12: 7 | C12: Battery | D12: 386 | E12: 0.073692249 | F12: 0.86353468 | G12: 0.11538462 | H12: 0.22435897 | I12: -0.12298748 | J12: 0.026684556 | L12: 7 | M12: Durability | N12: 319 | O12: 0.055701065 | P12: 0.75235849 | Q12: 0.14728682 | R12: 0.07751938 | S12: -0.088345362 | T12: -0.0029403903 | V12: 7 | W12: Price | X12: 556 | Y12: 0.077329624 | Z12: 1.0944882 | AA12: 0.12903226 | AB12: 0.14285714 | AC12: 0.040926531 | AD12: -0.073001888 | AF12: 7 | AG12: S-Pen | AH12: 395 | AI12: 0.056493135 | AJ12: 1.536965 | AK12: 0.21582734 | AL12: 0.11510791 | AM12: -0.18842798 | AN12: -0.083473647
B13: 8 | C13: AI | D13: 293 | E13: 0.055937381 | F13: 0.99659864 | G13: 0.24489796 | H13: 0.081632653 | I13: -0.019807923 | J13: 0.06202481 | L13: 8 | M13: AI | N13: 294 | O13: 0.051335778 | P13: 1.1574803 | Q13: 0.26470588 | R13: 0.019607843 | S13: 0.030939649 | T13: 0.019607843 | V13: 8 | W13: Durability | X13: 424 | Y13: 0.058970793 | Z13: 1.0927835 | AA13: 0.23563218 | AB13: 0.08045977 | AC13: 0.087060755 | AD13: 0.011888342 | AF13: 8 | AG13: Durability | AH13: 388 | AI13: 0.055491991 | AJ13: 1.2125 | AK13: 0.14857143 | AL13: 0.068571429 | AM13: -0.17417989 | AN13: -0.11661376
