Workbook
Name RawData: #REF!
Name RawData: #REF!
Name USP순서: [3]USP_RAW시트!$J$4:$BA$709

Sheet Summary
Q1: blog 점수 재계산
B2: LG.com Monitoring Report by Country
Q4: Crawling Date : 25.11.04
B5: REGION | C5: COUNTRY | D5: GP1 Status | E5: SKU | F5: SKU AUG | G5: GAP | H5: Total Score | I5: Total Score AUG | J5: GAP | K5: Monitoring Criteria
K6: SEO HTML Tag | P6: Category | Q6: Blog
K7: 1. Title | L7: 2. Description | M7: 3. H1 | N7: 4. Canonical Link | O7: 5. Alt text_ Feature Cards | P7: 6.Product Category | Q7: 7. Blog
K8: Score (out of 20) | M8: Score (out of 15) | Q8: Additional 10 points
C9: * | E9: 1834 | F9: 1830 | G9: 4 | H9: 94.914666 | I9: 89.386611 | J9: 5.5280551 | K9: =AVERAGEIF(K10:K59, "<>#N/A") -> 14.911224 | L9: =AVERAGEIF(L10:L59, "<>#N/A") -> 17.450312 | M9: =AVERAGEIF(M10:M59, "<>#N/A") -> 13.114907 | N9: =AVERAGEIF(N10:N59, "<>#N/A") -> 14.80959 | O9: =AVERAGEIF(O10:O59, "<>#N/A") -> 14.615264 | P9: =AVERAGEIF(P10:P59, "<>#N/A") -> 14.558824 | Q9: =AVERAGEIF(Q10:Q59, "<>#N/A") -> 5.4545455 | S9: BLOG
B10: NA | C10: Canada | D10: GP1 | E10: 48 | F10: 48 | G10: 0 | H10: 77.1875 | I10: 77.5 | J10: -0.3125 | K10: =IFERROR(AVERAGEIFS(PLP_BUSINESS!X:X, PLP_BUSINESS!$B:$B, Summary!$C10, PLP_BUSINESS!$H:$H, "Y"),0) -> 13.333333 | L10: =IFERROR(AVERAGEIFS(PLP_BUSINESS!Y:Y, PLP_BUSINESS!$B:$B, Summary!$C10, PLP_BUSINESS!$H:$H, "Y"),0) -> 17.916667 | M10: =IFERROR(AVERAGEIFS(PLP_BUSINESS!Z:Z, PLP_BUSINESS!$B:$B, Summary!$C10, PLP_BUSINESS!$H:$H, "Y"),0) -> 1.25 | N10: =IFERROR(AVERAGEIFS(PLP_BUSINESS!AA:AA, PLP_BUSINESS!$B:$B, Summary!$C10, PLP_BUSINESS!$H:$H, "Y"),0) -> 14.6875 | O10: =IFERROR(AVERAGEIFS(PLP_BUSINESS!AB:AB, PLP_BUSINESS!$B:$B, Summary!$C10, PLP_BUSINESS!$H:$H, "Y"),0) -> 15 | P10: =HLOOKUP($C10,'Product Category'!$E$7:$AS$68,62,0) -> 15 | Q10: =IF(ISNUMBER(MATCH(C10,S:S,0)), NA(), IF(ISNA(P10), NA(), _xlfn.XLOOKUP(C10,Blog!C:C,Blog!G:G,0))) -> 0 | R10: =IF(ISNA(P10), "예외", "") | S10: Algeria
B11: LATAM | C11: Colombia | D11: GP1 | E11: 33 | F11: 33 | G11: 0 | H11: 100 | I11: 100 | J11: 0 | K11: =IFERROR(AVERAGEIFS(PLP_BUSINESS!X:X, PLP_BUSINESS!$B:$B, Summary!$C11, PLP_BUSINESS!$H:$H, "Y"),0) -> 20 | L11: =IFERROR(AVERAGEIFS(PLP_BUSINESS!Y:Y, PLP_BUSINESS!$B:$B, Summary!$C11, PLP_BUSINESS!$H:$H, "Y"),0) -> 18.787879 | M11: =IFERROR(AVERAGEIFS(PLP_BUSINESS!Z:Z, PLP_BUSINESS!$B:$B, Summary!$C11, PLP_BUSINESS!$H:$H, "Y"),0) -> 15 | N11: =IFERROR(AVERAGEIFS(PLP_BUSINESS!AA:AA, PLP_BUSINESS!$B:$B, Summary!$C11, PLP_BUSINESS!$H:$H, "Y"),0) -> 15 | O11: =IFERROR(AVERAGEIFS(PLP_BUSINESS!AB:AB, PLP_BUSINESS!$B:$B, Summary!$C11, PLP_BUSINESS!$H:$H, "Y"),0) -> 15 | P11: =HLOOKUP($C11,'Product Category'!$E$7:$AS$68,62,0) -> 15 | Q11: =IF(ISNUMBER(MATCH(C11,S:S,0)), NA(), IF(ISNA(P11), NA(), _xlfn.XLOOKUP(C11,Blog!C:C,Blog!G:G,0))) -> 10 | R11: =IF(ISNA(P11), "예외", "")
B12: LATAM | C12: Ecuador | D12: 5.0 | E12: 36 | F12: 36 | G12: 0 | H12: 99.62963 | I12: 99.62963 | J12: 0 | K12: =IFERROR(AVERAGEIFS(PLP_BUSINESS!X:X, PLP_BUSINESS!$B:$B, Summary!$C12, PLP_BUSINESS!$H:$H, "Y"),0) -> 12.222222 | L12: =IFERROR(AVERAGEIFS(PLP_BUSINESS!Y:Y, PLP_BUSINESS!$B:$B, Summary!$C12, PLP_BUSINESS!$H:$H, "Y"),0) -> 20 | M12: =IFERROR(AVERAGEIFS(PLP_BUSINESS!Z:Z, PLP_BUSINESS!$B:$B, Summary!$C12, PLP_BUSINESS!$H:$H, "Y"),0) -> 12.916667 | N12: =IFERROR(AVERAGEIFS(PLP_BUSINESS!AA:AA, PLP_BUSINESS!$B:$B, Summary!$C12, PLP_BUSINESS!$H:$H, "Y"),0) -> 14.583333 | O12: =IFERROR(AVERAGEIFS(PLP_BUSINESS!AB:AB, PLP_BUSINESS!$B:$B, Summary!$C12, PLP_BUSINESS!$H:$H, "Y"),0) -> 15 | P12: =HLOOKUP($C12,'Product Category'!$E$7:$AS$68,62,0) -> #N/A | Q12: =IF(ISNUMBER(MATCH(C12,S:S,0)), NA(), IF(ISNA(P12), NA(), _xlfn.XLOOKUP(C12,Blog!C:C,Blog!G:G,0))) -> #N/A | R12: =IF(ISNA(P12), "예외", "") -> 예외
B13: LATAM | C13: Mexico | D13: GP1 | E13: 42 | F13: 42 | G13: 0 | H13: 100 | I13: 100 | J13: 0 | K13: =IFERROR(AVERAGEIFS(PLP_BUSINESS!X:X, PLP_BUSINESS!$B:$B, Summary!$C13, PLP_BUSINESS!$H:$H, "Y"),0) -> 20 | L13: =IFERROR(AVERAGEIFS(PLP_BUSINESS!Y:Y, PLP_BUSINESS!$B:$B, Summary!$C13, PLP_BUSINESS!$H:$H, "Y"),0) -> 20 | M13: =IFERROR(AVERAGEIFS(PLP_BUSINESS!Z:Z, PLP_BUSINESS!$B:$B, Summary!$C13, PLP_BUSINESS!$H:$H, "Y"),0) -> 15 | N13: =IFERROR(AVERAGEIFS(PLP_BUSINESS!AA:AA, PLP_BUSINESS!$B:$B, Summary!$C13, PLP_BUSINESS!$H:$H, "Y"),0) -> 14.642857 | O13: =IFERROR(AVERAGEIFS(PLP_BUSINESS!AB:AB, PLP_BUSINESS!$B:$B, Summary!$C13, PLP_BUSINESS!$H:$H, "Y"),0) -> 15 | P13: =HLOOKUP($C13,'Product Category'!$E$7:$AS$68,62,0) -> 15 | Q13: =IF(ISNUMBER(MATCH(C13,S:S,0)), NA(), IF(ISNA(P13), NA(), _xlfn.XLOOKUP(C13,Blog!C:C,Blog!G:G,0))) -> 10 | R13: =IF(ISNA(P13), "예외", "")
B14: LATAM | C14: Chile | D14: GP1 | E14: 31 | F14: 31 | G14: 0 | H14: 100 | I14: 100 | J14: 0 | K14: =IFERROR(AVERAGEIFS(PLP_BUSINESS!X:X, PLP_BUSINESS!$B:$B, Summary!$C14, PLP_BUSINESS!$H:$H, "Y"),0) -> 16.774194 | L14: =IFERROR(AVERAGEIFS(PLP_BUSINESS!Y:Y, PLP_BUSINESS!$B:$B, Summary!$C14, PLP_BUSINESS!$H:$H, "Y"),0) -> 19.354839 | M14: =IFERROR(AVERAGEIFS(PLP_BUSINESS!Z:Z, PLP_BUSINESS!$B:$B, Summary!$C14, PLP_BUSINESS!$H:$H, "Y"),0) -> 15 | N14: =IFERROR(AVERAGEIFS(PLP_BUSINESS!AA:AA, PLP_BUSINESS!$B:$B, Summary!$C14, PLP_BUSINESS!$H:$H, "Y"),0) -> 15 | O14: =IFERROR(AVERAGEIFS(PLP_BUSINESS!AB:AB, PLP_BUSINESS!$B:$B, Summary!$C14, PLP_BUSINESS!$H:$H, "Y"),0) -> 15 | P14: =HLOOKUP($C14,'Product Category'!$E$7:$AS$68,62,0) -> 15 | Q14: =IF(ISNUMBER(MATCH(C14,S:S,0)), NA(), IF(ISNA(P14), NA(), _xlfn.XLOOKUP(C14,Blog!C:C,Blog!G:G,0))) -> 10 | R14: =IF(ISNA(P14), "예외", "")
B15: LATAM | C15: Peru | D15: GP1 | E15: 38 | F15: 38 | G15: 0 | H15: 99.605263 | I15: 93.026316 | J15: 6.5789474 | K15: =IFERROR(AVERAGEIFS(PLP_BUSINESS!X:X, PLP_BUSINESS!$B:$B, Summary!$C15, PLP_BUSINESS!$H:$H, "Y"),0) -> 20 | L15: =IFERROR(AVERAGEIFS(PLP_BUSINESS!Y:Y, PLP_BUSINESS!$B:$B, Summary!$C15, PLP_BUSINESS!$H:$H, "Y"),0) -> 20 | M15: =IFERROR(AVERAGEIFS(PLP_BUSINESS!Z:Z, PLP_BUSINESS!$B:$B, Summary!$C15, PLP_BUSINESS!$H:$H, "Y"),0) -> 15 | N15: =IFERROR(AVERAGEIFS(PLP_BUSINESS!AA:AA, PLP_BUSINESS!$B:$B, Summary!$C15, PLP_BUSINESS!$H:$H, "Y"),0) -> 14.605263 | O15: =IFERROR(AVERAGEIFS(PLP_BUSINESS!AB:AB, PLP_BUSINESS!$B:$B, Summary!$C15, PLP_BUSINESS!$H:$H, "Y"),0) -> 15 | P15: =HLOOKUP($C15,'Product Category'!$E$7:$AS$68,62,0) -> 15 | Q15: =IF(ISNUMBER(MATCH(C15,S:S,0)), NA(), IF(ISNA(P15), NA(), _xlfn.XLOOKUP(C15,Blog!C:C,Blog!G:G,0))) -> 0 | R15: =IF(ISNA(P15), "예외", "")
B16: LATAM | C16: Panama | D16: GP1 | E16: 40 | F16: 40 | G16: 0 | H16: 100 | I16: 100 | J16: 0 | K16: =IFERROR(AVERAGEIFS(PLP_BUSINESS!X:X, PLP_BUSINESS!$B:$B, Summary!$C16, PLP_BUSINESS!$H:$H, "Y"),0) -> 19.5 | L16: =IFERROR(AVERAGEIFS(PLP_BUSINESS!Y:Y, PLP_BUSINESS!$B:$B, Summary!$C16, PLP_BUSINESS!$H:$H, "Y"),0) -> 19.5 | M16: =IFERROR(AVERAGEIFS(PLP_BUSINESS!Z:Z, PLP_BUSINESS!$B:$B, Summary!$C16, PLP_BUSINESS!$H:$H, "Y"),0) -> 14.25 | N16: =IFERROR(AVERAGEIFS(PLP_BUSINESS!AA:AA, PLP_BUSINESS!$B:$B, Summary!$C16, PLP_BUSINESS!$H:$H, "Y"),0) -> 15 | O16: =IFERROR(AVERAGEIFS(PLP_BUSINESS!AB:AB, PLP_BUSINESS!$B:$B, Summary!$C16, PLP_BUSINESS!$H:$H, "Y"),0) -> 15 | P16: =HLOOKUP($C16,'Product Category'!$E$7:$AS$68,62,0) -> 15 | Q16: =IF(ISNUMBER(MATCH(C16,S:S,0)), NA(), IF(ISNA(P16), NA(), _xlfn.XLOOKUP(C16,Blog!C:C,Blog!G:G,0))) -> 10 | R16: =IF(ISNA(P16), "예외", "")
B17: LATAM | C17: Brazil | D17: GP1 | E17: 31 | F17: 30 | G17: 1 | H17: 100 | I17: 97 | J17: 3 | K17: =IFERROR(AVERAGEIFS(PLP_BUSINESS!X:X, PLP_BUSINESS!$B:$B, Summary!$C17, PLP_BUSINESS!$H:$H, "Y"),0) -> 19.354839 | L17: =IFERROR(AVERAGEIFS(PLP_BUSINESS!Y:Y, PLP_BUSINESS!$B:$B, Summary!$C17, PLP_BUSINESS!$H:$H, "Y"),0) -> 18.064516 | M17: =IFERROR(AVERAGEIFS(PLP_BUSINESS!Z:Z, PLP_BUSINESS!$B:$B, Summary!$C17, PLP_BUSINESS!$H:$H, "Y"),0) -> 14.516129 | N17: =IFERROR(AVERAGEIFS(PLP_BUSINESS!AA:AA, PLP_BUSINESS!$B:$B, Summary!$C17, PLP_BUSINESS!$H:$H, "Y"),0) -> 15 | O17: =IFERROR(AVERAGEIFS(PLP_BUSINESS!AB:AB, PLP_BUSINESS!$B:$B, Summary!$C17, PLP_BUSINESS!$H:$H, "Y"),0) -> 15 | P17: =HLOOKUP($C17,'Product Category'!$E$7:$AS$68,62,0) -> 15 | Q17: =IF(ISNUMBER(MATCH(C17,S:S,0)), NA(), IF(ISNA(P17), NA(), _xlfn.XLOOKUP(C17,Blog!C:C,Blog!G:G,0))) -> 10 | R17: =IF(ISNA(P17), "예외", "")
B18: LATAM | C18: Argentina | D18: 5.0 | E18: 51 | F18: 51 | G18: 0 | H18: 89.411765 | I18: 99.411765 | J18: -10 | K18: =IFERROR(AVERAGEIFS(PLP_BUSINESS!X:X, PLP_BUSINESS!$B:$B, Summary!$C18, PLP_BUSINESS!$H:$H, "Y"),0) -> 15.686275 | L18: =IFERROR(AVERAGEIFS(PLP_BUSINESS!Y:Y, PLP_BUSINESS!$B:$B, Summary!$C18, PLP_BUSINESS!$H:$H, "Y"),0) -> 19.607843 | M18: =IFERROR(AVERAGEIFS(PLP_BUSINESS!Z:Z, PLP_BUSINESS!$B:$B, Summary!$C18, PLP_BUSINESS!$H:$H, "Y"),0) -> 11.176471 | N18: =IFERROR(AVERAGEIFS(PLP_BUSINESS!AA:AA, PLP_BUSINESS!$B:$B, Summary!$C18, PLP_BUSINESS!$H:$H, "Y"),0) -> 14.705882 | O18: =IFERROR(AVERAGEIFS(PLP_BUSINESS!AB:AB, PLP_BUSINESS!$B:$B, Summary!$C18, PLP_BUSINESS!$H:$H, "Y"),0) -> 13.235294 | P18: =HLOOKUP($C18,'Product Category'!$E$7:$AS$68,62,0) -> 15 | Q18: =IF(ISNUMBER(MATCH(C18,S:S,0)), NA(), IF(ISNA(P18), NA(), _xlfn.XLOOKUP(C18,Blog!C:C,Blog!G:G,0))) -> 0 | R18: =IF(ISNA(P18), "예외", "")
B19: EU | C19: Croatia | D19: 5.0 | E19: 38 | F19: 38 | G19: 0 | H19: 100 | I19: 100 | J19: 0 | K19: =IFERROR(AVERAGEIFS(PLP_BUSINESS!X:X, PLP_BUSINESS!$B:$B, Summary!$C19, PLP_BUSINESS!$H:$H, "Y"),0) -> 20 | L19: =IFERROR(AVERAGEIFS(PLP_BUSINESS!Y:Y, PLP_BUSINESS!$B:$B, Summary!$C19, PLP_BUSINESS!$H:$H, "Y"),0) -> 20 | M19: =IFERROR(AVERAGEIFS(PLP_BUSINESS!Z:Z, PLP_BUSINESS!$B:$B, Summary!$C19, PLP_BUSINESS!$H:$H, "Y"),0) -> 15 | N19: =IFERROR(AVERAGEIFS(PLP_BUSINESS!AA:AA, PLP_BUSINESS!$B:$B, Summary!$C19, PLP_BUSINESS!$H:$H, "Y"),0) -> 15 | O19: =IFERROR(AVERAGEIFS(PLP_BUSINESS!AB:AB, PLP_BUSINESS!$B:$B, Summary!$C19, PLP_BUSINESS!$H:$H, "Y"),0) -> 15 | P19: =HLOOKUP($C19,'Product Category'!$E$7:$AS$68,62,0) -> #N/A | Q19: =IF(ISNUMBER(MATCH(C19,S:S,0)), NA(), IF(ISNA(P19), NA(), _xlfn.XLOOKUP(C19,Blog!C:C,Blog!G:G,0))) -> #N/A | R19: =IF(ISNA(P19), "예외", "") -> 예외
B20: EU | C20: Germany | D20: GP1 | E20: 33 | F20: 32 | G20: 1 | H20: 84.242424 | I20: 85.9375 | J20: -1.6950758 | K20: =IFERROR(AVERAGEIFS(PLP_BUSINESS!X:X, PLP_BUSINESS!$B:$B, Summary!$C20, PLP_BUSINESS!$H:$H, "Y"),0) -> 13.333333 | L20: =IFERROR(AVERAGEIFS(PLP_BUSINESS!Y:Y, PLP_BUSINESS!$B:$B, Summary!$C20, PLP_BUSINESS!$H:$H, "Y"),0) -> 12.727273 | M20: =IFERROR(AVERAGEIFS(PLP_BUSINESS!Z:Z, PLP_BUSINESS!$B:$B, Summary!$C20, PLP_BUSINESS!$H:$H, "Y"),0) -> 13.636364 | N20: =IFERROR(AVERAGEIFS(PLP_BUSINESS!AA:AA, PLP_BUSINESS!$B:$B, Summary!$C20, PLP_BUSINESS!$H:$H, "Y"),0) -> 14.545455 | O20: =IFERROR(AVERAGEIFS(PLP_BUSINESS!AB:AB, PLP_BUSINESS!$B:$B, Summary!$C20, PLP_BUSINESS!$H:$H, "Y"),0) -> 15 | P20: =HLOOKUP($C20,'Product Category'!$E$7:$AS$68,62,0) -> 15 | Q20: =IF(ISNUMBER(MATCH(C20,S:S,0)), NA(), IF(ISNA(P20), NA(), _xlfn.XLOOKUP(C20,Blog!C:C,Blog!G:G,0))) -> 0 | R20: =IF(ISNA(P20), "예외", "")
B21: EU | C21: Slovakia | D21: 5.0 | E21: 50 | F21: 50 | G21: 0 | H21: 99.066667 | I21: 99.066667 | J21: 0 | K21: =IFERROR(AVERAGEIFS(PLP_BUSINESS!X:X, PLP_BUSINESS!$B:$B, Summary!$C21, PLP_BUSINESS!$H:$H, "Y"),0) -> 12.8 | L21: =IFERROR(AVERAGEIFS(PLP_BUSINESS!Y:Y, PLP_BUSINESS!$B:$B, Summary!$C21, PLP_BUSINESS!$H:$H, "Y"),0) -> 19.2 | M21: =IFERROR(AVERAGEIFS(PLP_BUSINESS!Z:Z, PLP_BUSINESS!$B:$B, Summary!$C21, PLP_BUSINESS!$H:$H, "Y"),0) -> 12.6 | N21: =IFERROR(AVERAGEIFS(PLP_BUSINESS!AA:AA, PLP_BUSINESS!$B:$B, Summary!$C21, PLP_BUSINESS!$H:$H, "Y"),0) -> 15 | O21: =IFERROR(AVERAGEIFS(PLP_BUSINESS!AB:AB, PLP_BUSINESS!$B:$B, Summary!$C21, PLP_BUSINESS!$H:$H, "Y"),0) -> 14.7 | P21: =HLOOKUP($C21,'Product Category'!$E$7:$AS$68,62,0) -> #N/A | Q21: =IF(ISNUMBER(MATCH(C21,S:S,0)), NA(), IF(ISNA(P21), NA(), _xlfn.XLOOKUP(C21,Blog!C:C,Blog!G:G,0))) -> #N/A | R21: =IF(ISNA(P21), "예외", "") -> 예외
B22: EU | C22: Hungary | D22: GP1 | E22: 34 | F22: 34 | G22: 0 | H22: 100 | I22: 87.794118 | J22: 12.205882 | K22: =IFERROR(AVERAGEIFS(PLP_BUSINESS!X:X, PLP_BUSINESS!$B:$B, Summary!$C22, PLP_BUSINESS!$H:$H, "Y"),0) -> 20 | L22: =IFERROR(AVERAGEIFS(PLP_BUSINESS!Y:Y, PLP_BUSINESS!$B:$B, Summary!$C22, PLP_BUSINESS!$H:$H, "Y"),0) -> 20 | M22: =IFERROR(AVERAGEIFS(PLP_BUSINESS!Z:Z, PLP_BUSINESS!$B:$B, Summary!$C22, PLP_BUSINESS!$H:$H, "Y"),0) -> 15 | N22: =IFERROR(AVERAGEIFS(PLP_BUSINESS!AA:AA, PLP_BUSINESS!$B:$B, Summary!$C22, PLP_BUSINESS!$H:$H, "Y"),0) -> 15 | O22: =IFERROR(AVERAGEIFS(PLP_BUSINESS!AB:AB, PLP_BUSINESS!$B:$B, Summary!$C22, PLP_BUSINESS!$H:$H, "Y"),0) -> 15 | P22: =HLOOKUP($C22,'Product Category'!$E$7:$AS$68,62,0) -> 15 | Q22: =IF(ISNUMBER(MATCH(C22,S:S,0)), NA(), IF(ISNA(P22), NA(), _xlfn.XLOOKUP(C22,Blog!C:C,Blog!G:G,0))) -> 10 | R22: =IF(ISNA(P22), "예외", "")
... B59: GLOBAL | C59: Global | D59: 5.0 | E59: 15 | F59: 15 | G59: 0 | H59: 100 | I59: 76 | J59: 24 | K59: =IFERROR(AVERAGEIFS(PLP_BUSINESS!X:X, PLP_BUSINESS!$B:$B, Summary!$C59, PLP_BUSINESS!$H:$H, "Y"),0) -> 20 | L59: =IFERROR(AVERAGEIFS(PLP_BUSINESS!Y:Y, PLP_BUSINESS!$B:$B, Summary!$C59, PLP_BUSINESS!$H:$H, "Y"),0) -> 20 | M59: =IFERROR(AVERAGEIFS(PLP_BUSINESS!Z:Z, PLP_BUSINESS!$B:$B, Summary!$C59, PLP_BUSINESS!$H:$H, "Y"),0) -> 14 | N59: =IFERROR(AVERAGEIFS(PLP_BUSINESS!AA:AA, PLP_BUSINESS!$B:$B, Summary!$C59, PLP_BUSINESS!$H:$H, "Y"),0) -> 13 | O59: =IFERROR(AVERAGEIFS(PLP_BUSINESS!AB:AB, PLP_BUSINESS!$B:$B, Summary!$C59, PLP_BUSINESS!$H:$H, "Y"),0) -> 10 | P59: =HLOOKUP($C59,'Product Category'!$E$7:$AS$68,62,0) -> #N/A | Q59: =IF(ISNUMBER(MATCH(C59,S:S,0)), NA(), IF(ISNA(P59), NA(), _xlfn.XLOOKUP(C59,Blog!C:C,Blog!G:G,0))) -> #N/A | R59: =IF(ISNA(P59), "예외", "") -> 예외

Sheet Summary (최종)
S1: product category 점수 추가(25점, 맨뒤의 탭) | T1: blog 점수(10점 additional)
B2: LG.com Monitoring Report by Country
T4: =Summary!Q4 -> Crawling Date : 25.11.04
B5: REGION | C5: COUNTRY | D5: GP1 Status | E5: SKU | F5: SKU AUG | G5: GAP | H5: Total Score | I5: Total Score AUG | J5: GAP
K6: SEO HTML Tag | P6: Category | Q6: Blog
K7: 1. Title | L7: 2. Description | M7: 3. H1 | N7: 4. Canonical Link | O7: 5. Alt text_ Feature Cards | P7: 6.Product Category | Q7: 7. Blog | R7: August Rank | S7: October Rank | T7: Change
K8: Score (out of 20) | M8: Score (out of 15) | Q8: Additional 10 points
C9: * | E9: 1468 | F9: 1464 | G9: 4 | H9: 97.471458 | I9: 91.862527 | J9: 5.6089317 | K9: {=AVERAGE(_xlfn._xlws.FILTER(K10:K43, ISNA(MATCH($C10:$C43, $V:$V, 0))))} -> 16.438378 | L9: {=AVERAGE(_xlfn._xlws.FILTER(L10:L43, ISNA(MATCH($C10:$C43, $V:$V, 0))))} -> 18.065083 | M9: {=AVERAGE(_xlfn._xlws.FILTER(M10:M43, ISNA(MATCH($C10:$C43, $V:$V, 0))))} -> 13.492513 | N9: {=AVERAGE(_xlfn._xlws.FILTER(N10:N43, ISNA(MATCH($C10:$C43, $V:$V, 0))))} -> 14.87202 | O9: {=AVERAGE(_xlfn._xlws.FILTER(O10:O43, ISNA(MATCH($C10:$C43, $V:$V, 0))))} -> 14.590095 | P9: {=AVERAGE(_xlfn._xlws.FILTER(P10:P43, ISNA(MATCH($C10:$C43, $V:$V, 0))))} -> 14.558824 | Q9: {=AVERAGE(_xlfn._xlws.FILTER(Q10:Q43,ISNA(MATCH($C10:$C43,$V:$V,0))*NOT(ISNA(Q10:Q43))))} -> 5.4545455 | V9: EXCEPTION | W9: BLOG
B10: ASIA | C10: Australia | D10: GP1 | E10: 25 | F10: 25 | G10: 0 | H10: 100 | I10: 100 | J10: 0 | K10: =IF(ISNUMBER(MATCH($C10, $V:$V, 0)), 0, IFERROR(AVERAGEIFS(PLP_BUSINESS!X:X, PLP_BUSINESS!$B:$B, 'Summary (최종)'!$C10, PLP_BUSINESS!$H:$H, "Y"),0)) -> 12.8 | L10: =IF(ISNUMBER(MATCH($C10, $V:$V, 0)), 0, IFERROR(AVERAGEIFS(PLP_BUSINESS!Y:Y, PLP_BUSINESS!$B:$B, 'Summary (최종)'!$C10, PLP_BUSINESS!$H:$H, "Y"),0)) -> 17.6 | M10: =IF(ISNUMBER(MATCH($C10, $V:$V, 0)), 0, IFERROR(AVERAGEIFS(PLP_BUSINESS!Z:Z, PLP_BUSINESS!$B:$B, 'Summary (최종)'!$C10, PLP_BUSINESS!$H:$H, "Y"),0)) -> 15 | N10: =IF(ISNUMBER(MATCH($C10, $V:$V, 0)), 0, IFERROR(AVERAGEIFS(PLP_BUSINESS!AA:AA, PLP_BUSINESS!$B:$B, 'Summary (최종)'!$C10, PLP_BUSINESS!$H:$H, "Y"),0)) -> 15 | O10: =IF(ISNUMBER(MATCH($C10, $V:$V, 0)), 0, IFERROR(AVERAGEIFS(PLP_BUSINESS!AB:AB, PLP_BUSINESS!$B:$B, 'Summary (최종)'!$C10, PLP_BUSINESS!$H:$H, "Y"),0)) -> 15 | P10: =IFERROR(HLOOKUP($C10,'Product Category'!$E$7:$AS$68,62,0), 0) -> 15 | Q10: =IF(ISNUMBER(MATCH(C10,W:W,0)), NA(),_xlfn.XLOOKUP(C10,Blog!C:C,Blog!G:G,0)) -> 10 | R10: {=SUMPRODUCT((ROUND($I$10:$I$43,8)>ROUND(I10,8))*1)+1} -> 1 | S10: {=SUMPRODUCT((ROUND($H$10:$H$43,8)>ROUND(H10,8))*1)+1} -> 1 | T10: =R10-S10 -> 0 | V10: Ecuador | W10: Algeria
B11: LATAM | C11: Brazil | D11: GP1 | E11: 31 | F11: 30 | G11: 1 | H11: 100 | I11: 97 | J11: 3 | K11: =IF(ISNUMBER(MATCH($C11, $V:$V, 0)), 0, IFERROR(AVERAGEIFS(PLP_BUSINESS!X:X, PLP_BUSINESS!$B:$B, 'Summary (최종)'!$C11, PLP_BUSINESS!$H:$H, "Y"),0)) -> 19.354839 | L11: =IF(ISNUMBER(MATCH($C11, $V:$V, 0)), 0, IFERROR(AVERAGEIFS(PLP_BUSINESS!Y:Y, PLP_BUSINESS!$B:$B, 'Summary (최종)'!$C11, PLP_BUSINESS!$H:$H, "Y"),0)) -> 18.064516 | M11: =IF(ISNUMBER(MATCH($C11, $V:$V, 0)), 0, IFERROR(AVERAGEIFS(PLP_BUSINESS!Z:Z, PLP_BUSINESS!$B:$B, 'Summary (최종)'!$C11, PLP_BUSINESS!$H:$H, "Y"),0)) -> 14.516129 | N11: =IF(ISNUMBER(MATCH($C11, $V:$V, 0)), 0, IFERROR(AVERAGEIFS(PLP_BUSINESS!AA:AA, PLP_BUSINESS!$B:$B, 'Summary (최종)'!$C11, PLP_BUSINESS!$H:$H, "Y"),0)) -> 15 | O11: =IF(ISNUMBER(MATCH($C11, $V:$V, 0)), 0, IFERROR(AVERAGEIFS(PLP_BUSINESS!AB:AB, PLP_BUSINESS!$B:$B, 'Summary (최종)'!$C11, PLP_BUSINESS!$H:$H, "Y"),0)) -> 15 | P11: =IFERROR(HLOOKUP($C11,'Product Category'!$E$7:$AS$68,62,0), 0) -> 15 | Q11: =IF(ISNUMBER(MATCH(C11,W:W,0)), NA(),_xlfn.XLOOKUP(C11,Blog!C:C,Blog!G:G,0)) -> 10 | R11: {=SUMPRODUCT((ROUND($I$10:$I$43,8)>ROUND(I11,8))*1)+1} -> 13 | S11: {=SUMPRODUCT((ROUND($H$10:$H$43,8)>ROUND(H11,8))*1)+1} -> 1 | T11: =R11-S11 -> 12 | V11: Croatia
B12: LATAM | C12: Chile | D12: GP1 | E12: 31 | F12: 31 | G12: 0 | H12: 100 | I12: 100 | J12: 0 | K12: =IF(ISNUMBER(MATCH($C12, $V:$V, 0)), 0, IFERROR(AVERAGEIFS(PLP_BUSINESS!X:X, PLP_BUSINESS!$B:$B, 'Summary (최종)'!$C12, PLP_BUSINESS!$H:$H, "Y"),0)) -> 16.774194 | L12: =IF(ISNUMBER(MATCH($C12, $V:$V, 0)), 0, IFERROR(AVERAGEIFS(PLP_BUSINESS!Y:Y, PLP_BUSINESS!$B:$B, 'Summary (최종)'!$C12, PLP_BUSINESS!$H:$H, "Y"),0)) -> 19.354839 | M12: =IF(ISNUMBER(MATCH($C12, $V:$V, 0)), 0, IFERROR(AVERAGEIFS(PLP_BUSINESS!Z:Z, PLP_BUSINESS!$B:$B, 'Summary (최종)'!$C12, PLP_BUSINESS!$H:$H, "Y"),0)) -> 15 | N12: =IF(ISNUMBER(MATCH($C12, $V:$V, 0)), 0, IFERROR(AVERAGEIFS(PLP_BUSINESS!AA:AA, PLP_BUSINESS!$B:$B, 'Summary (최종)'!$C12, PLP_BUSINESS!$H:$H, "Y"),0)) -> 15 | O12: =IF(ISNUMBER(MATCH($C12, $V:$V, 0)), 0, IFERROR(AVERAGEIFS(PLP_BUSINESS!AB:AB, PLP_BUSINESS!$B:$B, 'Summary (최종)'!$C12, PLP_BUSINESS!$H:$H, "Y"),0)) -> 15 | P12: =IFERROR(HLOOKUP($C12,'Product Category'!$E$7:$AS$68,62,0), 0) -> 15 | Q12: =IF(ISNUMBER(MATCH(C12,W:W,0)), NA(),_xlfn.XLOOKUP(C12,Blog!C:C,Blog!G:G,0)) -> 10 | R12: {=SUMPRODUCT((ROUND($I$10:$I$43,8)>ROUND(I12,8))*1)+1} -> 1 | S12: {=SUMPRODUCT((ROUND($H$10:$H$43,8)>ROUND(H12,8))*1)+1} -> 1 | T12: =R12-S12 -> 0 | V12: Slovakia
B13: LATAM | C13: Colombia | D13: GP1 | E13: 33 | F13: 33 | G13: 0 | H13: 100 | I13: 100 | J13: 0 | K13: =IF(ISNUMBER(MATCH($C13, $V:$V, 0)), 0, IFERROR(AVERAGEIFS(PLP_BUSINESS!X:X, PLP_BUSINESS!$B:$B, 'Summary (최종)'!$C13, PLP_BUSINESS!$H:$H, "Y"),0)) -> 20 | L13: =IF(ISNUMBER(MATCH($C13, $V:$V, 0)), 0, IFERROR(AVERAGEIFS(PLP_BUSINESS!Y:Y, PLP_BUSINESS!$B:$B, 'Summary (최종)'!$C13, PLP_BUSINESS!$H:$H, "Y"),0)) -> 18.787879 | M13: =IF(ISNUMBER(MATCH($C13, $V:$V, 0)), 0, IFERROR(AVERAGEIFS(PLP_BUSINESS!Z:Z, PLP_BUSINESS!$B:$B, 'Summary (최종)'!$C13, PLP_BUSINESS!$H:$H, "Y"),0)) -> 15 | N13: =IF(ISNUMBER(MATCH($C13, $V:$V, 0)), 0, IFERROR(AVERAGEIFS(PLP_BUSINESS!AA:AA, PLP_BUSINESS!$B:$B, 'Summary (최종)'!$C13, PLP_BUSINESS!$H:$H, "Y"),0)) -> 15 | O13: =IF(ISNUMBER(MATCH($C13, $V:$V, 0)), 0, IFERROR(AVERAGEIFS(PLP_BUSINESS!AB:AB, PLP_BUSINESS!$B:$B, 'Summary (최종)'!$C13, PLP_BUSINESS!$H:$H, "Y"),0)) -> 15 | P13: =IFERROR(HLOOKUP($C13,'Product Category'!$E$7:$AS$68,62,0), 0) -> 15 | Q13: =IF(ISNUMBER(MATCH(C13,W:W,0)), NA(),_xlfn.XLOOKUP(C13,Blog!C:C,Blog!G:G,0)) -> 10 | R13: {=SUMPRODUCT((ROUND($I$10:$I$43,8)>ROUND(I13,8))*1)+1} -> 1 | S13: {=SUMPRODUCT((ROUND($H$10:$H$43,8)>ROUND(H13,8))*1)+1} -> 1 | T13: =R13-S13 -> 0 | V13: Serbia
B14: EU | C14: Czech | D14: GP1 | E14: 41 | F14: 41 | G14: 0 | H14: 100 | I14: 97.682927 | J14: 2.3170732 | K14: =IF(ISNUMBER(MATCH($C14, $V:$V, 0)), 0, IFERROR(AVERAGEIFS(PLP_BUSINESS!X:X, PLP_BUSINESS!$B:$B, 'Summary (최종)'!$C14, PLP_BUSINESS!$H:$H, "Y"),0)) -> 18.536585 | L14: =IF(ISNUMBER(MATCH($C14, $V:$V, 0)), 0, IFERROR(AVERAGEIFS(PLP_BUSINESS!Y:Y, PLP_BUSINESS!$B:$B, 'Summary (최종)'!$C14, PLP_BUSINESS!$H:$H, "Y"),0)) -> 19.512195 | M14: =IF(ISNUMBER(MATCH($C14, $V:$V, 0)), 0, IFERROR(AVERAGEIFS(PLP_BUSINESS!Z:Z, PLP_BUSINESS!$B:$B, 'Summary (최종)'!$C14, PLP_BUSINESS!$H:$H, "Y"),0)) -> 14.634146 | N14: =IF(ISNUMBER(MATCH($C14, $V:$V, 0)), 0, IFERROR(AVERAGEIFS(PLP_BUSINESS!AA:AA, PLP_BUSINESS!$B:$B, 'Summary (최종)'!$C14, PLP_BUSINESS!$H:$H, "Y"),0)) -> 15 | O14: =IF(ISNUMBER(MATCH($C14, $V:$V, 0)), 0, IFERROR(AVERAGEIFS(PLP_BUSINESS!AB:AB, PLP_BUSINESS!$B:$B, 'Summary (최종)'!$C14, PLP_BUSINESS!$H:$H, "Y"),0)) -> 15 | P14: =IFERROR(HLOOKUP($C14,'Product Category'!$E$7:$AS$68,62,0), 0) -> 15 | Q14: =IF(ISNUMBER(MATCH(C14,W:W,0)), NA(),_xlfn.XLOOKUP(C14,Blog!C:C,Blog!G:G,0)) -> 10 | R14: {=SUMPRODUCT((ROUND($I$10:$I$43,8)>ROUND(I14,8))*1)+1} -> 11 | S14: {=SUMPRODUCT((ROUND($H$10:$H$43,8)>ROUND(H14,8))*1)+1} -> 1 | T14: =R14-S14 -> 10 | V14: Austria
B15: EU | C15: France | D15: GP1 | E15: 24 | F15: 24 | G15: 0 | H15: 100 | I15: 100 | J15: 0 | K15: =IF(ISNUMBER(MATCH($C15, $V:$V, 0)), 0, IFERROR(AVERAGEIFS(PLP_BUSINESS!X:X, PLP_BUSINESS!$B:$B, 'Summary (최종)'!$C15, PLP_BUSINESS!$H:$H, "Y"),0)) -> 20 | L15: =IF(ISNUMBER(MATCH($C15, $V:$V, 0)), 0, IFERROR(AVERAGEIFS(PLP_BUSINESS!Y:Y, PLP_BUSINESS!$B:$B, 'Summary (최종)'!$C15, PLP_BUSINESS!$H:$H, "Y"),0)) -> 20 | M15: =IF(ISNUMBER(MATCH($C15, $V:$V, 0)), 0, IFERROR(AVERAGEIFS(PLP_BUSINESS!Z:Z, PLP_BUSINESS!$B:$B, 'Summary (최종)'!$C15, PLP_BUSINESS!$H:$H, "Y"),0)) -> 15 | N15: =IF(ISNUMBER(MATCH($C15, $V:$V, 0)), 0, IFERROR(AVERAGEIFS(PLP_BUSINESS!AA:AA, PLP_BUSINESS!$B:$B, 'Summary (최종)'!$C15, PLP_BUSINESS!$H:$H, "Y"),0)) -> 15 | O15: =IF(ISNUMBER(MATCH($C15, $V:$V, 0)), 0, IFERROR(AVERAGEIFS(PLP_BUSINESS!AB:AB, PLP_BUSINESS!$B:$B, 'Summary (최종)'!$C15, PLP_BUSINESS!$H:$H, "Y"),0)) -> 15 | P15: =IFERROR(HLOOKUP($C15,'Product Category'!$E$7:$AS$68,62,0), 0) -> 15 | Q15: =IF(ISNUMBER(MATCH(C15,W:W,0)), NA(),_xlfn.XLOOKUP(C15,Blog!C:C,Blog!G:G,0)) -> 0 | R15: {=SUMPRODUCT((ROUND($I$10:$I$43,8)>ROUND(I15,8))*1)+1} -> 1 | S15: {=SUMPRODUCT((ROUND($H$10:$H$43,8)>ROUND(H15,8))*1)+1} -> 1 | T15: =R15-S15 -> 0 | V15: Bulgaria
B16: EU | C16: Hungary | D16: GP1 | E16: 34 | F16: 34 | G16: 0 | H16: 100 | I16: 87.794118 | J16: 12.205882 | K16: =IF(ISNUMBER(MATCH($C16, $V:$V, 0)), 0, IFERROR(AVERAGEIFS(PLP_BUSINESS!X:X, PLP_BUSINESS!$B:$B, 'Summary (최종)'!$C16, PLP_BUSINESS!$H:$H, "Y"),0)) -> 20 | L16: =IF(ISNUMBER(MATCH($C16, $V:$V, 0)), 0, IFERROR(AVERAGEIFS(PLP_BUSINESS!Y:Y, PLP_BUSINESS!$B:$B, 'Summary (최종)'!$C16, PLP_BUSINESS!$H:$H, "Y"),0)) -> 20 | M16: =IF(ISNUMBER(MATCH($C16, $V:$V, 0)), 0, IFERROR(AVERAGEIFS(PLP_BUSINESS!Z:Z, PLP_BUSINESS!$B:$B, 'Summary (최종)'!$C16, PLP_BUSINESS!$H:$H, "Y"),0)) -> 15 | N16: =IF(ISNUMBER(MATCH($C16, $V:$V, 0)), 0, IFERROR(AVERAGEIFS(PLP_BUSINESS!AA:AA, PLP_BUSINESS!$B:$B, 'Summary (최종)'!$C16, PLP_BUSINESS!$H:$H, "Y"),0)) -> 15 | O16: =IF(ISNUMBER(MATCH($C16, $V:$V, 0)), 0, IFERROR(AVERAGEIFS(PLP_BUSINESS!AB:AB, PLP_BUSINESS!$B:$B, 'Summary (최종)'!$C16, PLP_BUSINESS!$H:$H, "Y"),0)) -> 15 | P16: =IFERROR(HLOOKUP($C16,'Product Category'!$E$7:$AS$68,62,0), 0) -> 15 | Q16: =IF(ISNUMBER(MATCH(C16,W:W,0)), NA(),_xlfn.XLOOKUP(C16,Blog!C:C,Blog!G:G,0)) -> 10 | R16: {=SUMPRODUCT((ROUND($I$10:$I$43,8)>ROUND(I16,8))*1)+1} -> 24 | S16: {=SUMPRODUCT((ROUND($H$10:$H$43,8)>ROUND(H16,8))*1)+1} -> 1 | T16: =R16-S16 -> 23 | V16: Netherlands
B17: INDIA | C17: India | D17: GP1 | E17: 35 | F17: 35 | G17: 0 | H17: 100 | I17: 91.714286 | J17: 8.2857143 | K17: =IF(ISNUMBER(MATCH($C17, $V:$V, 0)), 0, IFERROR(AVERAGEIFS(PLP_BUSINESS!X:X, PLP_BUSINESS!$B:$B, 'Summary (최종)'!$C17, PLP_BUSINESS!$H:$H, "Y"),0)) -> 16 | L17: =IF(ISNUMBER(MATCH($C17, $V:$V, 0)), 0, IFERROR(AVERAGEIFS(PLP_BUSINESS!Y:Y, PLP_BUSINESS!$B:$B, 'Summary (최종)'!$C17, PLP_BUSINESS!$H:$H, "Y"),0)) -> 20 | M17: =IF(ISNUMBER(MATCH($C17, $V:$V, 0)), 0, IFERROR(AVERAGEIFS(PLP_BUSINESS!Z:Z, PLP_BUSINESS!$B:$B, 'Summary (최종)'!$C17, PLP_BUSINESS!$H:$H, "Y"),0)) -> 15 | N17: =IF(ISNUMBER(MATCH($C17, $V:$V, 0)), 0, IFERROR(AVERAGEIFS(PLP_BUSINESS!AA:AA, PLP_BUSINESS!$B:$B, 'Summary (최종)'!$C17, PLP_BUSINESS!$H:$H, "Y"),0)) -> 15 | O17: =IF(ISNUMBER(MATCH($C17, $V:$V, 0)), 0, IFERROR(AVERAGEIFS(PLP_BUSINESS!AB:AB, PLP_BUSINESS!$B:$B, 'Summary (최종)'!$C17, PLP_BUSINESS!$H:$H, "Y"),0)) -> 15 | P17: =IFERROR(HLOOKUP($C17,'Product Category'!$E$7:$AS$68,62,0), 0) -> 15 | Q17: =IF(ISNUMBER(MATCH(C17,W:W,0)), NA(),_xlfn.XLOOKUP(C17,Blog!C:C,Blog!G:G,0)) -> 10 | R17: {=SUMPRODUCT((ROUND($I$10:$I$43,8)>ROUND(I17,8))*1)+1} -> 19 | S17: {=SUMPRODUCT((ROUND($H$10:$H$43,8)>ROUND(H17,8))*1)+1} -> 1 | T17: =R17-S17 -> 18 | V17: Portugal
B18: ASIA | C18: Indonesia | D18: GP1 | E18: 41 | F18: 41 | G18: 0 | H18: 100 | I18: 100 | J18: 0 | K18: =IF(ISNUMBER(MATCH($C18, $V:$V, 0)), 0, IFERROR(AVERAGEIFS(PLP_BUSINESS!X:X, PLP_BUSINESS!$B:$B, 'Summary (최종)'!$C18, PLP_BUSINESS!$H:$H, "Y"),0)) -> 19.512195 | L18: =IF(ISNUMBER(MATCH($C18, $V:$V, 0)), 0, IFERROR(AVERAGEIFS(PLP_BUSINESS!Y:Y, PLP_BUSINESS!$B:$B, 'Summary (최종)'!$C18, PLP_BUSINESS!$H:$H, "Y"),0)) -> 18.04878 | M18: =IF(ISNUMBER(MATCH($C18, $V:$V, 0)), 0, IFERROR(AVERAGEIFS(PLP_BUSINESS!Z:Z, PLP_BUSINESS!$B:$B, 'Summary (최종)'!$C18, PLP_BUSINESS!$H:$H, "Y"),0)) -> 13.170732 | N18: =IF(ISNUMBER(MATCH($C18, $V:$V, 0)), 0, IFERROR(AVERAGEIFS(PLP_BUSINESS!AA:AA, PLP_BUSINESS!$B:$B, 'Summary (최종)'!$C18, PLP_BUSINESS!$H:$H, "Y"),0)) -> 15 | O18: =IF(ISNUMBER(MATCH($C18, $V:$V, 0)), 0, IFERROR(AVERAGEIFS(PLP_BUSINESS!AB:AB, PLP_BUSINESS!$B:$B, 'Summary (최종)'!$C18, PLP_BUSINESS!$H:$H, "Y"),0)) -> 15 | P18: =IFERROR(HLOOKUP($C18,'Product Category'!$E$7:$AS$68,62,0), 0) -> 15 | Q18: =IF(ISNUMBER(MATCH(C18,W:W,0)), NA(),_xlfn.XLOOKUP(C18,Blog!C:C,Blog!G:G,0)) -> 10 | R18: {=SUMPRODUCT((ROUND($I$10:$I$43,8)>ROUND(I18,8))*1)+1} -> 1 | S18: {=SUMPRODUCT((ROUND($H$10:$H$43,8)>ROUND(H18,8))*1)+1} -> 1 | T18: =R18-S18 -> 0 | V18: Uzbekistan
B19: MEA | C19: Kenya | D19: 5.0 | E19: 39 | F19: 39 | G19: 0 | H19: 100 | I19: 85.512821 | J19: 14.487179 | K19: =IF(ISNUMBER(MATCH($C19, $V:$V, 0)), 0, IFERROR(AVERAGEIFS(PLP_BUSINESS!X:X, PLP_BUSINESS!$B:$B, 'Summary (최종)'!$C19, PLP_BUSINESS!$H:$H, "Y"),0)) -> 18.974359 | L19: =IF(ISNUMBER(MATCH($C19, $V:$V, 0)), 0, IFERROR(AVERAGEIFS(PLP_BUSINESS!Y:Y, PLP_BUSINESS!$B:$B, 'Summary (최종)'!$C19, PLP_BUSINESS!$H:$H, "Y"),0)) -> 19.487179 | M19: =IF(ISNUMBER(MATCH($C19, $V:$V, 0)), 0, IFERROR(AVERAGEIFS(PLP_BUSINESS!Z:Z, PLP_BUSINESS!$B:$B, 'Summary (최종)'!$C19, PLP_BUSINESS!$H:$H, "Y"),0)) -> 15 | N19: =IF(ISNUMBER(MATCH($C19, $V:$V, 0)), 0, IFERROR(AVERAGEIFS(PLP_BUSINESS!AA:AA, PLP_BUSINESS!$B:$B, 'Summary (최종)'!$C19, PLP_BUSINESS!$H:$H, "Y"),0)) -> 15 | O19: =IF(ISNUMBER(MATCH($C19, $V:$V, 0)), 0, IFERROR(AVERAGEIFS(PLP_BUSINESS!AB:AB, PLP_BUSINESS!$B:$B, 'Summary (최종)'!$C19, PLP_BUSINESS!$H:$H, "Y"),0)) -> 13.846154 | P19: =IFERROR(HLOOKUP($C19,'Product Category'!$E$7:$AS$68,62,0), 0) -> 15 | Q19: =IF(ISNUMBER(MATCH(C19,W:W,0)), NA(),_xlfn.XLOOKUP(C19,Blog!C:C,Blog!G:G,0)) -> 10 | R19: {=SUMPRODUCT((ROUND($I$10:$I$43,8)>ROUND(I19,8))*1)+1} -> 27 | S19: {=SUMPRODUCT((ROUND($H$10:$H$43,8)>ROUND(H19,8))*1)+1} -> 1 | T19: =R19-S19 -> 26 | V19: Kazakhstan
B20: LATAM | C20: Mexico | D20: GP1 | E20: 42 | F20: 42 | G20: 0 | H20: 100 | I20: 100 | J20: 0 | K20: =IF(ISNUMBER(MATCH($C20, $V:$V, 0)), 0, IFERROR(AVERAGEIFS(PLP_BUSINESS!X:X, PLP_BUSINESS!$B:$B, 'Summary (최종)'!$C20, PLP_BUSINESS!$H:$H, "Y"),0)) -> 20 | L20: =IF(ISNUMBER(MATCH($C20, $V:$V, 0)), 0, IFERROR(AVERAGEIFS(PLP_BUSINESS!Y:Y, PLP_BUSINESS!$B:$B, 'Summary (최종)'!$C20, PLP_BUSINESS!$H:$H, "Y"),0)) -> 20 | M20: =IF(ISNUMBER(MATCH($C20, $V:$V, 0)), 0, IFERROR(AVERAGEIFS(PLP_BUSINESS!Z:Z, PLP_BUSINESS!$B:$B, 'Summary (최종)'!$C20, PLP_BUSINESS!$H:$H, "Y"),0)) -> 15 | N20: =IF(ISNUMBER(MATCH($C20, $V:$V, 0)), 0, IFERROR(AVERAGEIFS(PLP_BUSINESS!AA:AA, PLP_BUSINESS!$B:$B, 'Summary (최종)'!$C20, PLP_BUSINESS!$H:$H, "Y"),0)) -> 14.642857 | O20: =IF(ISNUMBER(MATCH($C20, $V:$V, 0)), 0, IFERROR(AVERAGEIFS(PLP_BUSINESS!AB:AB, PLP_BUSINESS!$B:$B, 'Summary (최종)'!$C20, PLP_BUSINESS!$H:$H, "Y"),0)) -> 15 | P20: =IFERROR(HLOOKUP($C20,'Product Category'!$E$7:$AS$68,62,0), 0) -> 15 | Q20: =IF(ISNUMBER(MATCH(C20,W:W,0)), NA(),_xlfn.XLOOKUP(C20,Blog!C:C,Blog!G:G,0)) -> 10 | R20: {=SUMPRODUCT((ROUND($I$10:$I$43,8)>ROUND(I20,8))*1)+1} -> 1 | S20: {=SUMPRODUCT((ROUND($H$10:$H$43,8)>ROUND(H20,8))*1)+1} -> 1 | T20: =R20-S20 -> 0 | V20: Morocco
B21: LATAM | C21: Panama | D21: GP1 | E21: 40 | F21: 40 | G21: 0 | H21: 100 | I21: 100 | J21: 0 | K21: =IF(ISNUMBER(MATCH($C21, $V:$V, 0)), 0, IFERROR(AVERAGEIFS(PLP_BUSINESS!X:X, PLP_BUSINESS!$B:$B, 'Summary (최종)'!$C21, PLP_BUSINESS!$H:$H, "Y"),0)) -> 19.5 | L21: =IF(ISNUMBER(MATCH($C21, $V:$V, 0)), 0, IFERROR(AVERAGEIFS(PLP_BUSINESS!Y:Y, PLP_BUSINESS!$B:$B, 'Summary (최종)'!$C21, PLP_BUSINESS!$H:$H, "Y"),0)) -> 19.5 | M21: =IF(ISNUMBER(MATCH($C21, $V:$V, 0)), 0, IFERROR(AVERAGEIFS(PLP_BUSINESS!Z:Z, PLP_BUSINESS!$B:$B, 'Summary (최종)'!$C21, PLP_BUSINESS!$H:$H, "Y"),0)) -> 14.25 | N21: =IF(ISNUMBER(MATCH($C21, $V:$V, 0)), 0, IFERROR(AVERAGEIFS(PLP_BUSINESS!AA:AA, PLP_BUSINESS!$B:$B, 'Summary (최종)'!$C21, PLP_BUSINESS!$H:$H, "Y"),0)) -> 15 | O21: =IF(ISNUMBER(MATCH($C21, $V:$V, 0)), 0, IFERROR(AVERAGEIFS(PLP_BUSINESS!AB:AB, PLP_BUSINESS!$B:$B, 'Summary (최종)'!$C21, PLP_BUSINESS!$H:$H, "Y"),0)) -> 15 | P21: =IFERROR(HLOOKUP($C21,'Product Category'!$E$7:$AS$68,62,0), 0) -> 15 | Q21: =IF(ISNUMBER(MATCH(C21,W:W,0)), NA(),_xlfn.XLOOKUP(C21,Blog!C:C,Blog!G:G,0)) -> 10 | R21: {=SUMPRODUCT((ROUND($I$10:$I$43,8)>ROUND(I21,8))*1)+1} -> 1 | S21: {=SUMPRODUCT((ROUND($H$10:$H$43,8)>ROUND(H21,8))*1)+1} -> 1 | T21: =R21-S21 -> 0 | V21: Iran
B22: ASIA | C22: Singapore | D22: GP1 | E22: 40 | F22: 40 | G22: 0 | H22: 100 | I22: 76.875 | J22: 23.125 | K22: =IF(ISNUMBER(MATCH($C22, $V:$V, 0)), 0, IFERROR(AVERAGEIFS(PLP_BUSINESS!X:X, PLP_BUSINESS!$B:$B, 'Summary (최종)'!$C22, PLP_BUSINESS!$H:$H, "Y"),0)) -> 19.5 | L22: =IF(ISNUMBER(MATCH($C22, $V:$V, 0)), 0, IFERROR(AVERAGEIFS(PLP_BUSINESS!Y:Y, PLP_BUSINESS!$B:$B, 'Summary (최종)'!$C22, PLP_BUSINESS!$H:$H, "Y"),0)) -> 20 | M22: =IF(ISNUMBER(MATCH($C22, $V:$V, 0)), 0, IFERROR(AVERAGEIFS(PLP_BUSINESS!Z:Z, PLP_BUSINESS!$B:$B, 'Summary (최종)'!$C22, PLP_BUSINESS!$H:$H, "Y"),0)) -> 15 | N22: =IF(ISNUMBER(MATCH($C22, $V:$V, 0)), 0, IFERROR(AVERAGEIFS(PLP_BUSINESS!AA:AA, PLP_BUSINESS!$B:$B, 'Summary (최종)'!$C22, PLP_BUSINESS!$H:$H, "Y"),0)) -> 15 | O22: =IF(ISNUMBER(MATCH($C22, $V:$V, 0)), 0, IFERROR(AVERAGEIFS(PLP_BUSINESS!AB:AB, PLP_BUSINESS!$B:$B, 'Summary (최종)'!$C22, PLP_BUSINESS!$H:$H, "Y"),0)) -> 15 | P22: =IFERROR(HLOOKUP($C22,'Product Category'!$E$7:$AS$68,62,0), 0) -> 15 | Q22: =IF(ISNUMBER(MATCH(C22,W:W,0)), NA(),_xlfn.XLOOKUP(C22,Blog!C:C,Blog!G:G,0)) -> 10 | R22: {=SUMPRODUCT((ROUND($I$10:$I$43,8)>ROUND(I22,8))*1)+1} -> 31 | S22: {=SUMPRODUCT((ROUND($H$10:$H$43,8)>ROUND(H22,8))*1)+1} -> 1 | T22: =R22-S22 -> 30 | V22: Bangladesh
... B25: MEA | C25: UAE | D25: 5.0 | E25: 85 | F25: 84 | G25: 1 | H25: 100 | I25: 78.511905 | J25: 21.488095 | K25: =IF(ISNUMBER(MATCH($C25, $V:$V, 0)), 0, IFERROR(AVERAGEIFS(PLP_BUSINESS!X:X, PLP_BUSINESS!$B:$B, 'Summary (최종)'!$C25, PLP_BUSINESS!$H:$H, "Y"),0)) -> 19.529412 | L25: =IF(ISNUMBER(MATCH($C25, $V:$V, 0)), 0, IFERROR(AVERAGEIFS(PLP_BUSINESS!Y:Y, PLP_BUSINESS!$B:$B, 'Summary (최종)'!$C25, PLP_BUSINESS!$H:$H, "Y"),0)) -> 19.764706 | M25: =IF(ISNUMBER(MATCH($C25, $V:$V, 0)), 0, IFERROR(AVERAGEIFS(PLP_BUSINESS!Z:Z, PLP_BUSINESS!$B:$B, 'Summary (최종)'!$C25, PLP_BUSINESS!$H:$H, "Y"),0)) -> 15 | N25: =IF(ISNUMBER(MATCH($C25, $V:$V, 0)), 0, IFERROR(AVERAGEIFS(PLP_BUSINESS!AA:AA, PLP_BUSINESS!$B:$B, 'Summary (최종)'!$C25, PLP_BUSINESS!$H:$H, "Y"),0)) -> 14.470588 | O25: =IF(ISNUMBER(MATCH($C25, $V:$V, 0)), 0, IFERROR(AVERAGEIFS(PLP_BUSINESS!AB:AB, PLP_BUSINESS!$B:$B, 'Summary (최종)'!$C25, PLP_BUSINESS!$H:$H, "Y"),0)) -> 14.470588 | P25: =IFERROR(HLOOKUP($C25,'Product Category'!$E$7:$AS$68,62,0), 0) -> 10 | Q25: =IF(ISNUMBER(MATCH(C25,W:W,0)), NA(),_xlfn.XLOOKUP(C25,Blog!C:C,Blog!G:G,0)) -> 10 | R25: {=SUMPRODUCT((ROUND($I$10:$I$43,8)>ROUND(I25,8))*1)+1} -> 28 | S25: {=SUMPRODUCT((ROUND($H$10:$H$43,8)>ROUND(H25,8))*1)+1} -> 1 | T25: =R25-S25 -> 27 | V25: Taiwan
B26: ASIA | C26: Vietnam | D26: GP1 | E26: 44 | F26: 43 | G26: 1 | H26: 100 | I26: 99.883721 | J26: 0.11627907 | K26: =IF(ISNUMBER(MATCH($C26, $V:$V, 0)), 0, IFERROR(AVERAGEIFS(PLP_BUSINESS!X:X, PLP_BUSINESS!$B:$B, 'Summary (최종)'!$C26, PLP_BUSINESS!$H:$H, "Y"),0)) -> 19.545455 | L26: =IF(ISNUMBER(MATCH($C26, $V:$V, 0)), 0, IFERROR(AVERAGEIFS(PLP_BUSINESS!Y:Y, PLP_BUSINESS!$B:$B, 'Summary (최종)'!$C26, PLP_BUSINESS!$H:$H, "Y"),0)) -> 19.545455 | M26: =IF(ISNUMBER(MATCH($C26, $V:$V, 0)), 0, IFERROR(AVERAGEIFS(PLP_BUSINESS!Z:Z, PLP_BUSINESS!$B:$B, 'Summary (최종)'!$C26, PLP_BUSINESS!$H:$H, "Y"),0)) -> 15 | N26: =IF(ISNUMBER(MATCH($C26, $V:$V, 0)), 0, IFERROR(AVERAGEIFS(PLP_BUSINESS!AA:AA, PLP_BUSINESS!$B:$B, 'Summary (최종)'!$C26, PLP_BUSINESS!$H:$H, "Y"),0)) -> 15 | O26: =IF(ISNUMBER(MATCH($C26, $V:$V, 0)), 0, IFERROR(AVERAGEIFS(PLP_BUSINESS!AB:AB, PLP_BUSINESS!$B:$B, 'Summary (최종)'!$C26, PLP_BUSINESS!$H:$H, "Y"),0)) -> 15 | P26: =IFERROR(HLOOKUP($C26,'Product Category'!$E$7:$AS$68,62,0), 0) -> 15 | Q26: =IF(ISNUMBER(MATCH(C26,W:W,0)), NA(),_xlfn.XLOOKUP(C26,Blog!C:C,Blog!G:G,0)) -> 10 | R26: {=SUMPRODUCT((ROUND($I$10:$I$43,8)>ROUND(I26,8))*1)+1} -> 8 | S26: {=SUMPRODUCT((ROUND($H$10:$H$43,8)>ROUND(H26,8))*1)+1} -> 1 | T26: =R26-S26 -> 7
B27: LATAM | C27: Peru | D27: GP1 | E27: 38 | F27: 38 | G27: 0 | H27: 99.605263 | I27: 93.026316 | J27: 6.5789474 | K27: =IF(ISNUMBER(MATCH($C27, $V:$V, 0)), 0, IFERROR(AVERAGEIFS(PLP_BUSINESS!X:X, PLP_BUSINESS!$B:$B, 'Summary (최종)'!$C27, PLP_BUSINESS!$H:$H, "Y"),0)) -> 20 | L27: =IF(ISNUMBER(MATCH($C27, $V:$V, 0)), 0, IFERROR(AVERAGEIFS(PLP_BUSINESS!Y:Y, PLP_BUSINESS!$B:$B, 'Summary (최종)'!$C27, PLP_BUSINESS!$H:$H, "Y"),0)) -> 20 | M27: =IF(ISNUMBER(MATCH($C27, $V:$V, 0)), 0, IFERROR(AVERAGEIFS(PLP_BUSINESS!Z:Z, PLP_BUSINESS!$B:$B, 'Summary (최종)'!$C27, PLP_BUSINESS!$H:$H, "Y"),0)) -> 15 | N27: =IF(ISNUMBER(MATCH($C27, $V:$V, 0)), 0, IFERROR(AVERAGEIFS(PLP_BUSINESS!AA:AA, PLP_BUSINESS!$B:$B, 'Summary (최종)'!$C27, PLP_BUSINESS!$H:$H, "Y"),0)) -> 14.605263 | O27: =IF(ISNUMBER(MATCH($C27, $V:$V, 0)), 0, IFERROR(AVERAGEIFS(PLP_BUSINESS!AB:AB, PLP_BUSINESS!$B:$B, 'Summary (최종)'!$C27, PLP_BUSINESS!$H:$H, "Y"),0)) -> 15 | P27: =IFERROR(HLOOKUP($C27,'Product Category'!$E$7:$AS$68,62,0), 0) -> 15 | Q27: =IF(ISNUMBER(MATCH(C27,W:W,0)), NA(),_xlfn.XLOOKUP(C27,Blog!C:C,Blog!G:G,0)) -> 0 | R27: {=SUMPRODUCT((ROUND($I$10:$I$43,8)>ROUND(I27,8))*1)+1} -> 17 | S27: {=SUMPRODUCT((ROUND($H$10:$H$43,8)>ROUND(H27,8))*1)+1} -> 18 | T27: =R27-S27 -> -1
B28: MEA | C28: Jordan | D28: 5.0 | E28: 73 | F28: 73 | G28: 0 | H28: 98.493151 | I28: 77.671233 | J28: 20.821918 | K28: =IF(ISNUMBER(MATCH($C28, $V:$V, 0)), 0, IFERROR(AVERAGEIFS(PLP_BUSINESS!X:X, PLP_BUSINESS!$B:$B, 'Summary (최종)'!$C28, PLP_BUSINESS!$H:$H, "Y"),0)) -> 19.726027 | L28: =IF(ISNUMBER(MATCH($C28, $V:$V, 0)), 0, IFERROR(AVERAGEIFS(PLP_BUSINESS!Y:Y, PLP_BUSINESS!$B:$B, 'Summary (최종)'!$C28, PLP_BUSINESS!$H:$H, "Y"),0)) -> 20 | M28: =IF(ISNUMBER(MATCH($C28, $V:$V, 0)), 0, IFERROR(AVERAGEIFS(PLP_BUSINESS!Z:Z, PLP_BUSINESS!$B:$B, 'Summary (최종)'!$C28, PLP_BUSINESS!$H:$H, "Y"),0)) -> 14.794521 | N28: =IF(ISNUMBER(MATCH($C28, $V:$V, 0)), 0, IFERROR(AVERAGEIFS(PLP_BUSINESS!AA:AA, PLP_BUSINESS!$B:$B, 'Summary (최종)'!$C28, PLP_BUSINESS!$H:$H, "Y"),0)) -> 14.383562 | O28: =IF(ISNUMBER(MATCH($C28, $V:$V, 0)), 0, IFERROR(AVERAGEIFS(PLP_BUSINESS!AB:AB, PLP_BUSINESS!$B:$B, 'Summary (최종)'!$C28, PLP_BUSINESS!$H:$H, "Y"),0)) -> 14.589041 | P28: =IFERROR(HLOOKUP($C28,'Product Category'!$E$7:$AS$68,62,0), 0) -> 15 | Q28: =IF(ISNUMBER(MATCH(C28,W:W,0)), NA(),_xlfn.XLOOKUP(C28,Blog!C:C,Blog!G:G,0)) -> 0 | R28: {=SUMPRODUCT((ROUND($I$10:$I$43,8)>ROUND(I28,8))*1)+1} -> 29 | S28: {=SUMPRODUCT((ROUND($H$10:$H$43,8)>ROUND(H28,8))*1)+1} -> 19 | T28: =R28-S28 -> 10
B29: MEA | C29: SaudiArabia | D29: GP1 | E29: 60 | F29: 60 | G29: 0 | H29: 98.166667 | I29: 98.166667 | J29: 0 | K29: =IF(ISNUMBER(MATCH($C29, $V:$V, 0)), 0, IFERROR(AVERAGEIFS(PLP_BUSINESS!X:X, PLP_BUSINESS!$B:$B, 'Summary (최종)'!$C29, PLP_BUSINESS!$H:$H, "Y"),0)) -> 19 | L29: =IF(ISNUMBER(MATCH($C29, $V:$V, 0)), 0, IFERROR(AVERAGEIFS(PLP_BUSINESS!Y:Y, PLP_BUSINESS!$B:$B, 'Summary (최종)'!$C29, PLP_BUSINESS!$H:$H, "Y"),0)) -> 19.666667 | M29: =IF(ISNUMBER(MATCH($C29, $V:$V, 0)), 0, IFERROR(AVERAGEIFS(PLP_BUSINESS!Z:Z, PLP_BUSINESS!$B:$B, 'Summary (최종)'!$C29, PLP_BUSINESS!$H:$H, "Y"),0)) -> 14.5 | N29: =IF(ISNUMBER(MATCH($C29, $V:$V, 0)), 0, IFERROR(AVERAGEIFS(PLP_BUSINESS!AA:AA, PLP_BUSINESS!$B:$B, 'Summary (최종)'!$C29, PLP_BUSINESS!$H:$H, "Y"),0)) -> 15 | O29: =IF(ISNUMBER(MATCH($C29, $V:$V, 0)), 0, IFERROR(AVERAGEIFS(PLP_BUSINESS!AB:AB, PLP_BUSINESS!$B:$B, 'Summary (최종)'!$C29, PLP_BUSINESS!$H:$H, "Y"),0)) -> 15 | P29: =IFERROR(HLOOKUP($C29,'Product Category'!$E$7:$AS$68,62,0), 0) -> 15 | Q29: =IF(ISNUMBER(MATCH(C29,W:W,0)), NA(),_xlfn.XLOOKUP(C29,Blog!C:C,Blog!G:G,0)) -> 0 | R29: {=SUMPRODUCT((ROUND($I$10:$I$43,8)>ROUND(I29,8))*1)+1} -> 10 | S29: {=SUMPRODUCT((ROUND($H$10:$H$43,8)>ROUND(H29,8))*1)+1} -> 20 | T29: =R29-S29 -> -10
B30: EU | C30: UK | D30: GP1 | E30: 28 | F30: 28 | G30: 0 | H30: 96.785714 | I30: 96.785714 | J30: 0 | K30: =IF(ISNUMBER(MATCH($C30, $V:$V, 0)), 0, IFERROR(AVERAGEIFS(PLP_BUSINESS!X:X, PLP_BUSINESS!$B:$B, 'Summary (최종)'!$C30, PLP_BUSINESS!$H:$H, "Y"),0)) -> 13.571429 | L30: =IF(ISNUMBER(MATCH($C30, $V:$V, 0)), 0, IFERROR(AVERAGEIFS(PLP_BUSINESS!Y:Y, PLP_BUSINESS!$B:$B, 'Summary (최종)'!$C30, PLP_BUSINESS!$H:$H, "Y"),0)) -> 16.428571 | M30: =IF(ISNUMBER(MATCH($C30, $V:$V, 0)), 0, IFERROR(AVERAGEIFS(PLP_BUSINESS!Z:Z, PLP_BUSINESS!$B:$B, 'Summary (최종)'!$C30, PLP_BUSINESS!$H:$H, "Y"),0)) -> 11.785714 | N30: =IF(ISNUMBER(MATCH($C30, $V:$V, 0)), 0, IFERROR(AVERAGEIFS(PLP_BUSINESS!AA:AA, PLP_BUSINESS!$B:$B, 'Summary (최종)'!$C30, PLP_BUSINESS!$H:$H, "Y"),0)) -> 15 | O30: =IF(ISNUMBER(MATCH($C30, $V:$V, 0)), 0, IFERROR(AVERAGEIFS(PLP_BUSINESS!AB:AB, PLP_BUSINESS!$B:$B, 'Summary (최종)'!$C30, PLP_BUSINESS!$H:$H, "Y"),0)) -> 15 | P30: =IFERROR(HLOOKUP($C30,'Product Category'!$E$7:$AS$68,62,0), 0) -> 15 | Q30: =IF(ISNUMBER(MATCH(C30,W:W,0)), NA(),_xlfn.XLOOKUP(C30,Blog!C:C,Blog!G:G,0)) -> 10 | R30: {=SUMPRODUCT((ROUND($I$10:$I$43,8)>ROUND(I30,8))*1)+1} -> 14 | S30: {=SUMPRODUCT((ROUND($H$10:$H$43,8)>ROUND(H30,8))*1)+1} -> 21 | T30: =R30-S30 -> -7
B31: ASIA | C31: China | D31: 5.0 | E31: 39 | F31: 39 | G31: 0 | H31: 95 | I31: 95 | J31: 0 | K31: =IF(ISNUMBER(MATCH($C31, $V:$V, 0)), 0, IFERROR(AVERAGEIFS(PLP_BUSINESS!X:X, PLP_BUSINESS!$B:$B, 'Summary (최종)'!$C31, PLP_BUSINESS!$H:$H, "Y"),0)) -> 15.384615 | L31: =IF(ISNUMBER(MATCH($C31, $V:$V, 0)), 0, IFERROR(AVERAGEIFS(PLP_BUSINESS!Y:Y, PLP_BUSINESS!$B:$B, 'Summary (최종)'!$C31, PLP_BUSINESS!$H:$H, "Y"),0)) -> 20 | M31: =IF(ISNUMBER(MATCH($C31, $V:$V, 0)), 0, IFERROR(AVERAGEIFS(PLP_BUSINESS!Z:Z, PLP_BUSINESS!$B:$B, 'Summary (최종)'!$C31, PLP_BUSINESS!$H:$H, "Y"),0)) -> 14.615385 | N31: =IF(ISNUMBER(MATCH($C31, $V:$V, 0)), 0, IFERROR(AVERAGEIFS(PLP_BUSINESS!AA:AA, PLP_BUSINESS!$B:$B, 'Summary (최종)'!$C31, PLP_BUSINESS!$H:$H, "Y"),0)) -> 15 | O31: =IF(ISNUMBER(MATCH($C31, $V:$V, 0)), 0, IFERROR(AVERAGEIFS(PLP_BUSINESS!AB:AB, PLP_BUSINESS!$B:$B, 'Summary (최종)'!$C31, PLP_BUSINESS!$H:$H, "Y"),0)) -> 15 | P31: =IFERROR(HLOOKUP($C31,'Product Category'!$E$7:$AS$68,62,0), 0) -> 15 | Q31: =IF(ISNUMBER(MATCH(C31,W:W,0)), NA(),_xlfn.XLOOKUP(C31,Blog!C:C,Blog!G:G,0)) -> 0 | R31: {=SUMPRODUCT((ROUND($I$10:$I$43,8)>ROUND(I31,8))*1)+1} -> 15 | S31: {=SUMPRODUCT((ROUND($H$10:$H$43,8)>ROUND(H31,8))*1)+1} -> 22 | T31: =R31-S31 -> -7
B32: MEA | C32: Nigeria | D32: 5.0 | E32: 74 | F32: 74 | G32: 0 | H32: 93.851351 | I32: 93.851351 | J32: 0 | K32: =IF(ISNUMBER(MATCH($C32, $V:$V, 0)), 0, IFERROR(AVERAGEIFS(PLP_BUSINESS!X:X, PLP_BUSINESS!$B:$B, 'Summary (최종)'!$C32, PLP_BUSINESS!$H:$H, "Y"),0)) -> 12.162162 | L32: =IF(ISNUMBER(MATCH($C32, $V:$V, 0)), 0, IFERROR(AVERAGEIFS(PLP_BUSINESS!Y:Y, PLP_BUSINESS!$B:$B, 'Summary (최종)'!$C32, PLP_BUSINESS!$H:$H, "Y"),0)) -> 18.918919 | M32: =IF(ISNUMBER(MATCH($C32, $V:$V, 0)), 0, IFERROR(AVERAGEIFS(PLP_BUSINESS!Z:Z, PLP_BUSINESS!$B:$B, 'Summary (최종)'!$C32, PLP_BUSINESS!$H:$H, "Y"),0)) -> 14.189189 | N32: =IF(ISNUMBER(MATCH($C32, $V:$V, 0)), 0, IFERROR(AVERAGEIFS(PLP_BUSINESS!AA:AA, PLP_BUSINESS!$B:$B, 'Summary (최종)'!$C32, PLP_BUSINESS!$H:$H, "Y"),0)) -> 14.797297 | O32: =IF(ISNUMBER(MATCH($C32, $V:$V, 0)), 0, IFERROR(AVERAGEIFS(PLP_BUSINESS!AB:AB, PLP_BUSINESS!$B:$B, 'Summary (최종)'!$C32, PLP_BUSINESS!$H:$H, "Y"),0)) -> 13.783784 | P32: =IFERROR(HLOOKUP($C32,'Product Category'!$E$7:$AS$68,62,0), 0) -> 10 | Q32: =IF(ISNUMBER(MATCH(C32,W:W,0)), NA(),_xlfn.XLOOKUP(C32,Blog!C:C,Blog!G:G,0)) -> 10 | R32: {=SUMPRODUCT((ROUND($I$10:$I$43,8)>ROUND(I32,8))*1)+1} -> 16 | S32: {=SUMPRODUCT((ROUND($H$10:$H$43,8)>ROUND(H32,8))*1)+1} -> 23 | T32: =R32-S32 -> -7
B33: ASIA | C33: Philippines | D33: GP1 | E33: 43 | F33: 43 | G33: 0 | H33: 93.023256 | I33: 89.767442 | J33: 3.255814 | K33: =IF(ISNUMBER(MATCH($C33, $V:$V, 0)), 0, IFERROR(AVERAGEIFS(PLP_BUSINESS!X:X, PLP_BUSINESS!$B:$B, 'Summary (최종)'!$C33, PLP_BUSINESS!$H:$H, "Y"),0)) -> 14.883721 | L33: =IF(ISNUMBER(MATCH($C33, $V:$V, 0)), 0, IFERROR(AVERAGEIFS(PLP_BUSINESS!Y:Y, PLP_BUSINESS!$B:$B, 'Summary (최종)'!$C33, PLP_BUSINESS!$H:$H, "Y"),0)) -> 18.139535 | M33: =IF(ISNUMBER(MATCH($C33, $V:$V, 0)), 0, IFERROR(AVERAGEIFS(PLP_BUSINESS!Z:Z, PLP_BUSINESS!$B:$B, 'Summary (최종)'!$C33, PLP_BUSINESS!$H:$H, "Y"),0)) -> 15 | N33: =IF(ISNUMBER(MATCH($C33, $V:$V, 0)), 0, IFERROR(AVERAGEIFS(PLP_BUSINESS!AA:AA, PLP_BUSINESS!$B:$B, 'Summary (최종)'!$C33, PLP_BUSINESS!$H:$H, "Y"),0)) -> 15 | O33: =IF(ISNUMBER(MATCH($C33, $V:$V, 0)), 0, IFERROR(AVERAGEIFS(PLP_BUSINESS!AB:AB, PLP_BUSINESS!$B:$B, 'Summary (최종)'!$C33, PLP_BUSINESS!$H:$H, "Y"),0)) -> 15 | P33: =IFERROR(HLOOKUP($C33,'Product Category'!$E$7:$AS$68,62,0), 0) -> 15 | Q33: =IF(ISNUMBER(MATCH(C33,W:W,0)), NA(),_xlfn.XLOOKUP(C33,Blog!C:C,Blog!G:G,0)) -> 0 | R33: {=SUMPRODUCT((ROUND($I$10:$I$43,8)>ROUND(I33,8))*1)+1} -> 21 | S33: {=SUMPRODUCT((ROUND($H$10:$H$43,8)>ROUND(H33,8))*1)+1} -> 24 | T33: =R33-S33 -> -3
B34: LATAM | C34: Argentina | D34: 5.0 | E34: 51 | F34: 51 | G34: 0 | H34: 89.411765 | I34: 99.411765 | J34: -10 | K34: =IF(ISNUMBER(MATCH($C34, $V:$V, 0)), 0, IFERROR(AVERAGEIFS(PLP_BUSINESS!X:X, PLP_BUSINESS!$B:$B, 'Summary (최종)'!$C34, PLP_BUSINESS!$H:$H, "Y"),0)) -> 15.686275 | L34: =IF(ISNUMBER(MATCH($C34, $V:$V, 0)), 0, IFERROR(AVERAGEIFS(PLP_BUSINESS!Y:Y, PLP_BUSINESS!$B:$B, 'Summary (최종)'!$C34, PLP_BUSINESS!$H:$H, "Y"),0)) -> 19.607843 | M34: =IF(ISNUMBER(MATCH($C34, $V:$V, 0)), 0, IFERROR(AVERAGEIFS(PLP_BUSINESS!Z:Z, PLP_BUSINESS!$B:$B, 'Summary (최종)'!$C34, PLP_BUSINESS!$H:$H, "Y"),0)) -> 11.176471 | N34: =IF(ISNUMBER(MATCH($C34, $V:$V, 0)), 0, IFERROR(AVERAGEIFS(PLP_BUSINESS!AA:AA, PLP_BUSINESS!$B:$B, 'Summary (최종)'!$C34, PLP_BUSINESS!$H:$H, "Y"),0)) -> 14.705882 | O34: =IF(ISNUMBER(MATCH($C34, $V:$V, 0)), 0, IFERROR(AVERAGEIFS(PLP_BUSINESS!AB:AB, PLP_BUSINESS!$B:$B, 'Summary (최종)'!$C34, PLP_BUSINESS!$H:$H, "Y"),0)) -> 13.235294 | P34: =IFERROR(HLOOKUP($C34,'Product Category'!$E$7:$AS$68,62,0), 0) -> 15 | Q34: =IF(ISNUMBER(MATCH(C34,W:W,0)), NA(),_xlfn.XLOOKUP(C34,Blog!C:C,Blog!G:G,0)) -> 0 | R34: {=SUMPRODUCT((ROUND($I$10:$I$43,8)>ROUND(I34,8))*1)+1} -> 9 | S34: {=SUMPRODUCT((ROUND($H$10:$H$43,8)>ROUND(H34,8))*1)+1} -> 25 | T34: =R34-S34 -> -16
B35: MEA | C35: SouthAfrica | D35: GP1 | E35: 33 | F35: 33 | G35: 0 | H35: 88.939394 | I35: 88.939394 | J35: 0 | K35: =IF(ISNUMBER(MATCH($C35, $V:$V, 0)), 0, IFERROR(AVERAGEIFS(PLP_BUSINESS!X:X, PLP_BUSINESS!$B:$B, 'Summary (최종)'!$C35, PLP_BUSINESS!$H:$H, "Y"),0)) -> 13.939394 | L35: =IF(ISNUMBER(MATCH($C35, $V:$V, 0)), 0, IFERROR(AVERAGEIFS(PLP_BUSINESS!Y:Y, PLP_BUSINESS!$B:$B, 'Summary (최종)'!$C35, PLP_BUSINESS!$H:$H, "Y"),0)) -> 16.363636 | M35: =IF(ISNUMBER(MATCH($C35, $V:$V, 0)), 0, IFERROR(AVERAGEIFS(PLP_BUSINESS!Z:Z, PLP_BUSINESS!$B:$B, 'Summary (최종)'!$C35, PLP_BUSINESS!$H:$H, "Y"),0)) -> 13.636364 | N35: =IF(ISNUMBER(MATCH($C35, $V:$V, 0)), 0, IFERROR(AVERAGEIFS(PLP_BUSINESS!AA:AA, PLP_BUSINESS!$B:$B, 'Summary (최종)'!$C35, PLP_BUSINESS!$H:$H, "Y"),0)) -> 15 | O35: =IF(ISNUMBER(MATCH($C35, $V:$V, 0)), 0, IFERROR(AVERAGEIFS(PLP_BUSINESS!AB:AB, PLP_BUSINESS!$B:$B, 'Summary (최종)'!$C35, PLP_BUSINESS!$H:$H, "Y"),0)) -> 15 | P35: =IFERROR(HLOOKUP($C35,'Product Category'!$E$7:$AS$68,62,0), 0) -> 15 | Q35: =IF(ISNUMBER(MATCH(C35,W:W,0)), NA(),_xlfn.XLOOKUP(C35,Blog!C:C,Blog!G:G,0)) -> 0 | R35: {=SUMPRODUCT((ROUND($I$10:$I$43,8)>ROUND(I35,8))*1)+1} -> 22 | S35: {=SUMPRODUCT((ROUND($H$10:$H$43,8)>ROUND(H35,8))*1)+1} -> 26 | T35: =R35-S35 -> -4
B36: MEA | C36: Algeria | D36: 5.0 | E36: 32 | F36: 32 | G36: 0 | H36: 87.8125 | I36: 87.8125 | J36: 0 | K36: =IF(ISNUMBER(MATCH($C36, $V:$V, 0)), 0, IFERROR(AVERAGEIFS(PLP_BUSINESS!X:X, PLP_BUSINESS!$B:$B, 'Summary (최종)'!$C36, PLP_BUSINESS!$H:$H, "Y"),0)) -> 18.125 | L36: =IF(ISNUMBER(MATCH($C36, $V:$V, 0)), 0, IFERROR(AVERAGEIFS(PLP_BUSINESS!Y:Y, PLP_BUSINESS!$B:$B, 'Summary (최종)'!$C36, PLP_BUSINESS!$H:$H, "Y"),0)) -> 17.5 | M36: =IF(ISNUMBER(MATCH($C36, $V:$V, 0)), 0, IFERROR(AVERAGEIFS(PLP_BUSINESS!Z:Z, PLP_BUSINESS!$B:$B, 'Summary (최종)'!$C36, PLP_BUSINESS!$H:$H, "Y"),0)) -> 13.59375 | N36: =IF(ISNUMBER(MATCH($C36, $V:$V, 0)), 0, IFERROR(AVERAGEIFS(PLP_BUSINESS!AA:AA, PLP_BUSINESS!$B:$B, 'Summary (최종)'!$C36, PLP_BUSINESS!$H:$H, "Y"),0)) -> 14.53125 | O36: =IF(ISNUMBER(MATCH($C36, $V:$V, 0)), 0, IFERROR(AVERAGEIFS(PLP_BUSINESS!AB:AB, PLP_BUSINESS!$B:$B, 'Summary (최종)'!$C36, PLP_BUSINESS!$H:$H, "Y"),0)) -> 14.0625 | P36: =IFERROR(HLOOKUP($C36,'Product Category'!$E$7:$AS$68,62,0), 0) -> 10 | Q36: =IF(ISNUMBER(MATCH(C36,W:W,0)), NA(),_xlfn.XLOOKUP(C36,Blog!C:C,Blog!G:G,0)) -> #N/A | R36: {=SUMPRODUCT((ROUND($I$10:$I$43,8)>ROUND(I36,8))*1)+1} -> 23 | S36: {=SUMPRODUCT((ROUND($H$10:$H$43,8)>ROUND(H36,8))*1)+1} -> 27 | T36: =R36-S36 -> -4
B37: MEA | C37: Egypt | D37: GP1 | E37: 124 | F37: 124 | G37: 0 | H37: 85.846774 | I37: 85.725806 | J37: 0.12096774 | K37: =IF(ISNUMBER(MATCH($C37, $V:$V, 0)), 0, IFERROR(AVERAGEIFS(PLP_BUSINESS!X:X, PLP_BUSINESS!$B:$B, 'Summary (최종)'!$C37, PLP_BUSINESS!$H:$H, "Y"),0)) -> 13.387097 | L37: =IF(ISNUMBER(MATCH($C37, $V:$V, 0)), 0, IFERROR(AVERAGEIFS(PLP_BUSINESS!Y:Y, PLP_BUSINESS!$B:$B, 'Summary (최종)'!$C37, PLP_BUSINESS!$H:$H, "Y"),0)) -> 13.548387 | M37: =IF(ISNUMBER(MATCH($C37, $V:$V, 0)), 0, IFERROR(AVERAGEIFS(PLP_BUSINESS!Z:Z, PLP_BUSINESS!$B:$B, 'Summary (최종)'!$C37, PLP_BUSINESS!$H:$H, "Y"),0)) -> 14.032258 | N37: =IF(ISNUMBER(MATCH($C37, $V:$V, 0)), 0, IFERROR(AVERAGEIFS(PLP_BUSINESS!AA:AA, PLP_BUSINESS!$B:$B, 'Summary (최종)'!$C37, PLP_BUSINESS!$H:$H, "Y"),0)) -> 14.879032 | O37: =IF(ISNUMBER(MATCH($C37, $V:$V, 0)), 0, IFERROR(AVERAGEIFS(PLP_BUSINESS!AB:AB, PLP_BUSINESS!$B:$B, 'Summary (최종)'!$C37, PLP_BUSINESS!$H:$H, "Y"),0)) -> 15 | P37: =IFERROR(HLOOKUP($C37,'Product Category'!$E$7:$AS$68,62,0), 0) -> 15 | Q37: =IF(ISNUMBER(MATCH(C37,W:W,0)), NA(),_xlfn.XLOOKUP(C37,Blog!C:C,Blog!G:G,0)) -> 0 | R37: {=SUMPRODUCT((ROUND($I$10:$I$43,8)>ROUND(I37,8))*1)+1} -> 26 | S37: {=SUMPRODUCT((ROUND($H$10:$H$43,8)>ROUND(H37,8))*1)+1} -> 28 | T37: =R37-S37 -> -2
... B43: EU | C43: Greece | D43: 5.0 | E43: 29 | F43: 29 | G43: 0 | H43: 70.517241 | I43: 70.517241 | J43: 0 | K43: =IF(ISNUMBER(MATCH($C43, $V:$V, 0)), 0, IFERROR(AVERAGEIFS(PLP_BUSINESS!X:X, PLP_BUSINESS!$B:$B, 'Summary (최종)'!$C43, PLP_BUSINESS!$H:$H, "Y"),0)) -> 8.2758621 | L43: =IF(ISNUMBER(MATCH($C43, $V:$V, 0)), 0, IFERROR(AVERAGEIFS(PLP_BUSINESS!Y:Y, PLP_BUSINESS!$B:$B, 'Summary (최종)'!$C43, PLP_BUSINESS!$H:$H, "Y"),0)) -> 13.103448 | M43: =IF(ISNUMBER(MATCH($C43, $V:$V, 0)), 0, IFERROR(AVERAGEIFS(PLP_BUSINESS!Z:Z, PLP_BUSINESS!$B:$B, 'Summary (최종)'!$C43, PLP_BUSINESS!$H:$H, "Y"),0)) -> 10.862069 | N43: =IF(ISNUMBER(MATCH($C43, $V:$V, 0)), 0, IFERROR(AVERAGEIFS(PLP_BUSINESS!AA:AA, PLP_BUSINESS!$B:$B, 'Summary (최종)'!$C43, PLP_BUSINESS!$H:$H, "Y"),0)) -> 15 | O43: =IF(ISNUMBER(MATCH($C43, $V:$V, 0)), 0, IFERROR(AVERAGEIFS(PLP_BUSINESS!AB:AB, PLP_BUSINESS!$B:$B, 'Summary (최종)'!$C43, PLP_BUSINESS!$H:$H, "Y"),0)) -> 8.2758621 | P43: =IFERROR(HLOOKUP($C43,'Product Category'!$E$7:$AS$68,62,0), 0) -> 15 | Q43: =IF(ISNUMBER(MATCH(C43,W:W,0)), NA(),_xlfn.XLOOKUP(C43,Blog!C:C,Blog!G:G,0)) -> 0 | R43: {=SUMPRODUCT((ROUND($I$10:$I$43,8)>ROUND(I43,8))*1)+1} -> 33 | S43: {=SUMPRODUCT((ROUND($H$10:$H$43,8)>ROUND(H43,8))*1)+1} -> 34 | T43: =R43-S43 -> -1

Sheet Monitoring Detail

Sheet Checklist & Criteria
B2: LG.com Contents Monitoring Detail Information
L3: 2025.10.16
B4: Category | C4: Checklist | D4: Scoring Criteria | J4: Improvement Guide
D5: Criteria | E5: Score Table | J5: Criteria Area | L5: Improvement Guide
E6: All conditions must be met to receive Full Points
B7: SEO Tag | C7: 1) Check <Title> | D7: 1) Follow Character Limit * Character Limit - Title Tag length is 40 ~ 60 characters : 20 Points - Less than 40 or over 60 characters : 0 Points *Character limit for 2byte character countries is 5 ~ 40 characters : HongKong(zh), Japan, Taiwan | E7: Type | F7: 1) Character Limit | I7: Total Score | K7: [Pass Case] | L7: - Follow Character Limit - Refer to the 'Meta tag guideline' shared by HQ
E8: Basic | F8: Pass | I8: 20
F9: Fail | I9: 0
E10: 2bytes | F10: Pass | I10: 20
F11: Fail | I11: 0
C12: 2) Check <Description> | D12: 1) Follow Character Limit * Character Limit - Description Tag length is 60 ~ 160 characters : 20 Points - Less than 60 or over 160 characters : 0 Points *Character limit for 2byte character countries is 40 ~ 90 characters : HongKong(zh), Japan, Taiwan | E12: Type | F12: 1) Character Limit | I12: Total Score | K12: [Pass Case] | L12: - Follow Character Limit - Refer to the 'Meta tag guideline' shared by HQ
E13: basic | F13: Pass | I13: 20
F14: Fail | I14: 0
E15: 2bytes | F15: Pass | I15: 20
F16: Fail | I16: 0
C17: 3) Check <H1> | D17: 1) Use H1 tag only for PLP titles | E17: Type | F17: 1) Should only be used for PLP title | I17: Total Score | K17: [Pass Case] | L17: - Avoid using multiple H1 Tags and use only for PLP title Refer to the 'Meta tag guideline' shared by HQ
D18: * There should only be one H1 tag in a page | E18: All | F18: Pass | I18: 15
F19: Fail | I19: 0
C20: 4) Check <Canonical Link> | D20: 1) Canonical Link or Redirect Link have the same URL or main tags Information as PDP | E20: Type | F20: 1) 'Canonical Link' or 'Redirect Link' and 'PDP' have the same URL | I20: Total Score | K20: [Pass Case] | L20: - Fill the same information as the current PLP URL
D21: * If the main tags of the 'canonical link' or 'redirect link page' and 'PDP' are same, it is pass even if the URLs are different | E21: All | F21: Pass | I21: 15
D22: - main tag : <title>, <description>, <UFN> | F22: Fail | I22: 0
C23: 5) Check <Alt Text> of Feature Cards | D23: 1) Follow Character Limit * Character Limit - Alt Text length is 1 ~ 125 characters : 15 Points - Alt Text is not set (length is 0) : 0 Points - Alt Text length over 125 characters : 0 Points * Feature Cards with alt text character limit errors are listed in "PLP_BUSINESS" Sheet - only fail case are listed. Pass case are not listed - If there is more than two fail cases, the alt texts are listed with comma * In the S column, the number of feature cards that needs to be fixied among all feature cards is displayed in the format of [Number of feature cards requiring modification]/[Total number of feature cards] | E23: Type | F23: 1) Character Limit | I23: Total Score | K23: [Pass Case] | L23: - Follow Character Limit Refer to the 'Meta tag guideline' shared by HQ
E24: All | F24: Pass | I24: 15
F25: Fail | I25: 0
B26: Category | C26: 6) Check Product Category Page Upload Status | D26: 1) Product Category Page is uploaded * Refer to the 'Product Category' sheet | E26: Type | F26: 1) Product Category Page is uploaded | I26: Total Score
E27: All | F27: Uploaded | I27: 15
F28: Uploaded more than 90% | I28: 10
F29: Not Uploaded | I29: 0
B30: Blog | C30: 7) Latest Blog Update (Additional 10 points) | D30: 1) 10 points if article is uploaded during 3 months prior to the reporting month * Scores exceeding 100 (including Blog score) will be adjusted to 100 | E30: Type | F30: 1) Article is uploaded during 3 months prior to the reporting month | I30: Total Score
E31: All | F31: Uploaded | I31: 10
F32: Not Uploaded | I32: 0

Sheet PLP_BUSINESS
J1: Tag <Title> | L1: Tag <Description> | N1: Tag <H1> | Q1: Tag <Canonical Link> | T1: Tag <Alt text>_(Front Image) | W1: Scoring
A2: Region | B2: Country | C2: Locale | D2: Page Type | E2: CAT/PLP | F2: GNB | G2: GNB ENG Trans | H2: Scoring Y/N | I2: URL | J2: Title Tag Text | K2: Length of title tag | L2: Description Tag | M2: Length of Description tag | N2: All H1 | O2: # of H1 tag | P2: H1 tag P/F | Q2: Canonical Link Tag | R2: Redirect Link | S2: Redirect Link P/F | T2: Issue / TTL * of Feature Cards | U2: Fail case of Alt text | V2: Length of Alt text | W2: Total Score | X2: Title Tag Score | Y2: Description Tag Score | Z2: H1 Tag Score | AA2: Canonical Link Score | AB2: Feature Alt Score
A3: MEA | B3: UAE | C3: AE : AE (en) | D3: 5.0 | E3: PLP | F3: Absorption Chiller Direct Fired Type | G3: Absorption Chiller Direct Fired Type | H3: Y | I3: https://www.lg.com/ae/business/hvac/commercial-solutions/chiller/absorption-chiller-direct-fired-type | J3: Absorption Chiller Direct Fired - HVAC | Business | LG UAE | K3: 58 | L3: LG Absorption Chiller Direct Fired Type employs water as a refrigerant, optimizing energy use and maximizing installation convenience with its parts partition. | M3: 159 | N3: ['Absorption Chiller Direct Fired Type'] | O3: 1 | P3: Pass | Q3: https://www.lg.com/ae/business/hvac/commercial-solutions/chiller/absorption-chiller-direct-fired-type | S3: Pass | T3: 0% | U3: ['pass'] | V3: [] | W3: 85 | X3: 20 | Y3: 20 | Z3: 15 | AA3: 15 | AB3: 15
A4: MEA | B4: UAE | C4: AE : AE (en) | D4: 5.0 | E4: PLP | F4: Absorption Chiller Hot Water Type | G4: Absorption Chiller Hot Water Type | H4: Y | I4: https://www.lg.com/ae/business/hvac/commercial-solutions/chiller/absorption-chiller-hot-water-type | J4: Absorption Chiller Hot Water - HVAC | Business | LG UAE | K4: 55 | L4: LG Absorption Chiller Hot Water Type offers an eco-friendly cooling and heating solution by utilizing wastewater from nearby factories or power plants. | M4: 151 | N4: ['Absorption Chiller Hot Water Type'] | O4: 1 | P4: Pass | Q4: https://www.lg.com/ae/business/hvac/commercial-solutions/chiller/absorption-chiller-hot-water-type | S4: Pass | T4: 0% | U4: ['pass'] | V4: [] | W4: 85 | X4: 20 | Y4: 20 | Z4: 15 | AA4: 15 | AB4: 15
A5: MEA | B5: UAE | C5: AE : AE (en) | D5: 5.0 | E5: PLP | F5: Absorption Chiller Steam Type | G5: Absorption Chiller Steam Type | H5: Y | I5: https://www.lg.com/ae/business/hvac/commercial-solutions/chiller/absorption-chiller-steam-type | J5: Absorption Chiller Steam - HVAC | Business | LG UAE | K5: 51 | L5: LG Absorption Chiller Steam Type maintains steady, eco-friendly performance in power-short areas by leveraging various thermal heat sources. | M5: 140 | N5: ['Absorption Chiller Steam Type'] | O5: 1 | P5: Pass | Q5: https://www.lg.com/ae/business/hvac/commercial-solutions/chiller/absorption-chiller-steam-type | S5: Pass | T5: 0% | U5: ['pass'] | V5: [] | W5: 85 | X5: 20 | Y5: 20 | Z5: 15 | AA5: 15 | AB5: 15
A6: MEA | B6: UAE | C6: AE : AE (en) | D6: 5.0 | E6: PLP | F6: Air Cooled Inverter Scroll Chiller | G6: Air Cooled Inverter Scroll Chiller | H6: Y | I6: https://www.lg.com/ae/business/hvac/commercial-solutions/chiller/air-cooled-inverter-scroll-chiller | J6: Air Cooled Inverter Scroll Chiller - HVAC| Business | LG UAE | K6: 60 | L6: LG Inverter Scroll Chiller delivers efficient heating, a wide operational range, and optimal refrigerant control via its twin inverter compressor. | M6: 146 | N6: ['Inverter Scroll Chiller'] | O6: 1 | P6: Pass | Q6: https://www.lg.com/ae/business/hvac/commercial-solutions/chiller/air-cooled-inverter-scroll-chiller | S6: Pass | T6: 0% | U6: ['pass'] | V6: [] | W6: 85 | X6: 20 | Y6: 20 | Z6: 15 | AA6: 15 | AB6: 15
A7: MEA | B7: UAE | C7: AE : AE (en) | D7: 5.0 | E7: PLP | F7: Air Cooled Screw Chiller | G7: Air Cooled Screw Chiller | H7: Y | I7: https://www.lg.com/ae/business/hvac/commercial-solutions/chiller/air-cooled-screw-chiller | J7: Air Cooled Screw Chiller - HVAC | Business | LG UAE | K7: 51 | L7: LG Air-cooled Screw Chiller maximizes heat transfer with its corrosion-resistant heat exchanger, accentuated by a gold-colored coated fin. | M7: 138 | N7: ['Air-cooled Screw Chiller'] | O7: 1 | P7: Pass | Q7: https://www.lg.com/ae/business/hvac/commercial-solutions/chiller/air-cooled-screw-chiller | S7: Pass | T7: 0% | U7: ['pass'] | V7: [] | W7: 85 | X7: 20 | Y7: 20 | Z7: 15 | AA7: 15 | AB7: 15
A8: MEA | B8: UAE | C8: AE : AE (en) | D8: 5.0 | E8: PLP | F8: Air Handling Unit | G8: Air Handling Unit | H8: Y | I8: https://www.lg.com/ae/business/hvac/commercial-solutions/vrf-system/integrated-unit/air-handling-unit | J8: Air Handling Unit - VRF System - HVAC | Business | LG UAE | K8: 57 | L8: LG Air Handling Unit (AHU) ensures efficient, comfortable air solutions all year round, courtesy of its high expandability. | M8: 123 | N8: ['Air Handling Unit (AHU)'] | O8: 1 | P8: Pass | Q8: https://www.lg.com/ae/business/hvac/commercial-solutions/vrf-system/integrated-unit/air-handling-unit | S8: Pass | T8: 0% | U8: ['pass'] | V8: [] | W8: 85 | X8: 20 | Y8: 20 | Z8: 15 | AA8: 15 | AB8: 15
A9: MEA | B9: UAE | C9: AE : AE (en) | D9: 5.0 | E9: PLP | F9: Air to Water Heat Pumps | G9: Air to Water Heat Pumps | H9: Y | I9: https://www.lg.com/ae/business/hvac/residential-solutions/air-to-water-heat-pumps | J9: Heating Solution (AWHP) - HVAC | Business | LG UAE | K9: 50 | L9: LG Air to Water Heat Pump, THERMA V, Sustainable solution providing heating, cooling & hot water for comfort, replacing gas boilers with renewable technology. | M9: 158 | N9: ['Heating Solution (AWHP)'] | O9: 1 | P9: Pass | Q9: https://www.lg.com/ae/business/hvac/residential-solutions/air-to-water-heat-pumps | S9: Pass | T9: 0% | U9: ['pass'] | V9: [] | W9: 85 | X9: 20 | Y9: 20 | Z9: 15 | AA9: 15 | AB9: 15
A10: MEA | B10: UAE | C10: AE : AE (en) | D10: 5.0 | E10: PLP | F10: Application Controller | G10: Application Controller | H10: Y | I10: https://www.lg.com/ae/business/hvac/control-solutions/application-controller | J10: Application Controller - HVAC | Business | LG UAE | K10: 49 | L10: The LG HVAC Application Controller manages building systems for enhanced comfort, featuring flexible integration, energy monitoring, and AHU control. | M10: 149 | N10: ['Application Controller'] | O10: 1 | P10: Pass | Q10: https://www.lg.com/ae/business/hvac/control-solutions/application-controller | S10: Pass | T10: 0% | U10: ['pass'] | V10: [] | W10: 85 | X10: 20 | Y10: 20 | Z10: 15 | AA10: 15 | AB10: 15
